Workbook
Name _dpx2: '[2]DHL City to Zone OB Vol'!$AF$7:$AO$45
Name _dpx2: '[4]DHL City to Zone OB Vol'!$AF$7:$AO$45

Sheet 2025年应收汇总表
A1: 对账单汇总
A2: 客户名称： | B2: 哈贝尔（HUPPER TEK)
A3: 序号 | B3: 账单日期 | C3: 充值日期 | D3: 充值金额 | E3: 账单金额 | F3: 应收总额 | G3: 备注
A4: 1 | B4: 8月账单 | E4: 1632 | F4: =D4-E4 -> -1632
A5: 2 | B5: 9月账单 | C5: 45928 | D5: =4000+2700 -> 6700 | E5: 5868.692 | F5: =F4+D5-E5 -> -800.69196
A6: 3 | B6: 10月账单 | C6: 45959 | D6: =2500+3000 -> 5500 | E6: ='对账单-汇总页'!F18 -> 5902.5777 | F6: =F5+D6-E6 -> -1203.2696
A7: 4 | F7: =F6+D7-E7 -> -1203.2696
A8: 5 | F8: =F7+D8-E8 -> -1203.2696
A9: 6 | F9: =F8+D9-E9 -> -1203.2696
A10: 7 | F10: =F9+D10-E10 -> -1203.2696
A11: 8 | F11: =F10+D11-E11 -> -1203.2696
A12: 9 | F12: =F11+D12-E12 -> -1203.2696
A13: 10 | F13: =F12+D13-E13 -> -1203.2696
A14: 11 | F14: =F13+D14-E14 -> -1203.2696
A15: 12 | F15: =F14+D15-E15 -> -1203.2696
A16: 13 | F16: =F15+D16-E16 -> -1203.2696
A17: 14 | F17: =F16+D17-E17 -> -1203.2696
A18: 15 | F18: =F17+D18-E18 -> -1203.2696
... A22: 19 | F22: =F21+D22-E22 -> -1203.2696
A23: 应收汇总： | F23: =F22+D23-E23 -> -1203.2696 | G23: 负数为欠费

Sheet 对账单-汇总页
D1: MIC Logistik GmbH对账单
A3: 客户 | B3: 哈贝尔（HUPPER TEK) | D3: 海外仓地点 | E3: 德国北威州门兴格拉德巴赫
A4: 报价生效日期 | D4: 公司邮箱 | E4: info@miclogistik.de
A5: 对账期 | B5: 2025.10.01~2025.10.31 | D5: 公司网页 | E5: www.miclogistik.de
A7: 一、服务内容及对账明细 | G7: 计费币种：欧元/Euro
A8: 业务场景 | B8: 费用项 | C8: 库内基础费用 A | D8: 运输基础费用 B | E8: 附加费 C | F8: 开票费用合计 A-B+C | G8: 备注
A9: 1. 正向 | B9: 1.1 入库 | C9: ='1.1 正向-入库'!V1 -> 70 | D9: 0 | E9: 0 | F9: =C9+D9+E9 -> 70
B10: 2.1 2B | C10: 0 | D10: 0 | E10: ='2.1 正向-2B'!BX1+'2.1 正向-2B'!CA1 -> 0 | F10: =C10+D10+E10 -> 0 | G10: 10月无2B
B11: 2.2 2C订单-GEL | C11: ='2.2 正向-2C-GEL'!AZ1 -> 573.05 | D11: ='2.2 正向-2C-GEL'!BI1 -> 3296.5742 | E11: ='2.2 正向-2C-GEL'!BR1-'2.2 正向-2C-GEL'!BI1 -> 462.8 | F11: =C11+D11+E11 -> 4332.4242
B12: 2.3 2C订单-DHL | C12: ='2.3 正向-2C-DHL'!AZ1 -> 4.8 | D12: ='2.3 正向-2C-DHL'!BF1 -> 33.14115 | E12: ='2.3 正向-2C-DHL'!BJ1 -> 123.06851 | F12: =C12+D12+E12 -> 161.00966
B13: 2.4 2C订单-PlanB | C13: 0 | D13: ='2.4 正向-2C-PlanB '!AY1 -> 264 | E13: ='2.4 正向-2C-PlanB '!BH1-'2.4 正向-2C-PlanB '!AY1 -> 0 | F13: =C13+D13+E13 -> 264
A14: 2. 仓储费 | B14: 3.1 正向仓储费(10月） | C14: ='3.1 正向-普货-仓储费 '!AP1 -> 829.10948 | D14: 0 | E14: 0 | F14: =C14+D14+E14 -> 829.10948 | G14: 每月月底统一核算
A15: 3. 逆向退货 | B15: 4.1 逆向退货费 | C15: ='4.1 逆向退货&仓租费'!AJ1 -> 19.4 | D15: ='4.1 逆向退货&仓租费'!AQ1 -> 186.2343 | E15: ='4.1 逆向退货&仓租费'!BH1 -> 40.4 | F15: =C15+D15+E15 -> 246.0343 | G15: 每月月底统一核算
B16: 4.1 逆向退货仓租费 | C16: ='4.1 逆向退货&仓租费'!BW1 -> 0 | D16: 0 | E16: ='4.1 逆向退货&仓租费'!BW1 -> 0 | F16: =C16+D16+E16 -> 0 | G16: 每月月底统一核算
A17: 4. 其他 | C17: 0 | D17: 0 | E17: 0 | F17: =C17+D17+E17 -> 0
A18: 合计 | C18: =SUM(C9:C17) -> 1496.3595 | D18: =SUM(D9:D17) -> 3779.9497 | E18: =SUM(E9:E17) -> 626.26851 | F18: =SUM(F9:F17) -> 5902.5777
A19: 截止到9月30日余额 | C19: ='2025年应收汇总表'!F5 -> -800.69196
A20: 10.9日充值 | C20: 2500
A21: 10.29日充值 | C21: 3000
A22: 截止到10月31日余额 | C22: =C21+C20+C19-F18 -> -1203.2696 | G22: 10月已欠费（建议充值）
A24: 关键说明
A25: 1. 报价： | B25: 不含德国VAT，相关的附加费具体详见每项报价说明。
A26: 2. 账号使用前提： | B26: 采用预充值+保证金的方式： 预充值：根据未来2周或1个月预测消费额提前充值，按照不同重量段及对应报价，出单时进行预扣（含退货），充值余额不足则暂停出单； 保证金：主要是应对相关异常费用，不含常规的出单基础费、附加费，具体额度按月度预充值*15%来收取。
A27: 3. 结算： | B27: 结算币种为欧元，月结，开票与预充值核销。
A28: 4. 运输保险： | B28: 建议购买，发送丢失或损毁，按商业发票金额（需含运费）赔偿；若不购买，只能按照德国道理运输法则，货物实际重量*8.33欧/kg进行赔偿，运费也不赔偿。
A29: 5. 服务时间： | B29: 若遇当地国法定节假日，导致服务商不收货，我司会提前知会客户。
A30: 6. 报价申明： | B30: 卡派运输市场价格波动大，若变化浮动超过10%，MIC提前一个月书面/邮件通知确认。
A32: 客户签章 | F32: MIC Logistik GmbH
A37: 日期： | B37: 45965 | F37: 日期： | G37: =B37 -> 45965

Sheet 1.1 正向-入库
A1: MIC德国海外仓到货&收货&入库明细表 | U1: =SUM(U4:U4) -> 70 | V1: =SUM(V4:V4) -> 70
A2: 退货信息 | R2: 卸货&收货费 | V2: 合计
A3: 任务号 | B3: 入库月份 | C3: Carrier | D3: 收货日期 | E3: 入库状态 | F3: 客户 | G3: 批次号 | H3: 批次号行数 | I3: 批次数 | J3: 类型 | K3: 物品SKU | L3: 物品描述 | M3: 物品 总数 | N3: 货位 | O3: 箱数 | P3: 托盘数 | Q3: Remark | R3: 托盘数 | S3: 箱数 | T3: 单价 | U3: 金额
A4: MI202510300003 | B4: 202510 | C4: Truck | D4: 2025-10-30 12:57:02 | E4: Inbound Completed | F4: YCD-EX:HUPPER TEK | G4: 易仓入库单号：RVABM0009-251021-0001 | K4: ABM0009-B07GSF11XX | L4: 白板 | M4: 87 | N4: M » Vir1 | O4: 87 | P4: 5 | R4: =P4 -> 5 | T4: 14 | U4: =T4*R4 -> 70 | V4: =U4+Q4 -> 70

Sheet 2.1 正向-2B
A1: MIC德国海外仓一件代发明细表 | AP1: =SUM(AP5:AP8) -> 0 | AS1: =SUM(AS5:AS8) -> 0 | AV1: =SUM(AV5:AV8) -> 0 | AY1: =SUM(AY5:AY8) -> 0 | BB1: =SUM(BB5:BB8) -> 0 | BE1: =SUM(BE5:BE8) -> 0 | BF1: =SUM(BF5:BF8) -> 0 | BO1: =SUM(BO5:BO8) -> 0 | BQ1: =SUM(BQ5:BQ8) -> 0 | BX1: =SUM(BX5:BX8) -> 0 | CA1: =SUM(CA5:CA8) -> 0 | CB1: =SUM(CB5:CB8) -> 0 | CC1: 0
A2: ,1m, | BG2: 尾程运输费 | CC2: 费用合计
A3: 出库指令 | Z3: 物品-拣料及最小包装 | AN3: 拣货&包装费 | AQ3: 拣货续件费 | AT3: 贴标费 | AW3: 包材费-包裹 | AZ3: 装车费 | BC3: 自提附加费 | BF3: 合计 | BG3: 基础费 | BP3: 续重费（超300公斤） | BR3: 附加费 | BY3: 3件包裹以上运输续件费 | CB3: 合计
A4: Order No. | B4: 订单 行数 | C4: 订单数 | D4: 对账 | E4: Warehouse | F4: 月份 | G4: Order Created At | H4: Shipped At | I4: Status | J4: Customer | K4: Original Reference | L4: Business Type | M4: Channel | N4: Creator | O4: 运单数 | P4: Priority | Q4: weight | R4: Carrier | S4: Carrier Return | T4: Shipments No1 | U4: Shipments No2 | V4: Retour No | W4: Postal Code | X4: 城市 | Y4: Country | Z4: Item ID | AA4: 物品描述 | AB4: 物品尺寸 长宽高cm | AC4: 单个物品 重量kg | AD4: Item Batch | AE4: Item Qty | AF4: 订单重量 kg | AG4: PltQty | AH4: PltDim | AI4: PltWeight | AJ4: BoxQty | AK4: BoxDim | AL4: BoxWeight | AM4: 备注 | AN4: 数量 套 | AO4: 单价 Euro | AP4: 金额 Euro | AQ4: 数量 pcs | AR4: 单价 Euro | AS4: 金额 Euro | AT4: 标签/张 | AU4: 单价 | AV4: 金额 | AW4: 数量 pcs | AX4: 单价 Euro | AY4: 金额 Euro | AZ4: 数量 /托 | BA4: 单价 Euro | BB4: 金额 Euro | BC4: 数量 /托 | BD4: 单价 Euro | BE4: 金额 Euro | BF4: 库内小计 | BG4: 数量 票 | BH4: 实际重kg | BI4: 体积重KG | BJ4: 计费 重量 kg | BK4: 邮编所属区域 | BL4: 城市 | BM4: 国家 | BN4: 单价 Euro | BO4: 金额 Euro | BP4: 单价 Euro | BQ4: 金额 Euro | BR4: 运输 订单 管理 * | BS4: 燃油 附加费 * | BT4: 过路 过桥 * | BU4: 运输 保险 | BV4: 预约 通知 * | BW4: 其它 | BX4: 附加费小计 | BY4: 包裹数 个 | BZ4: 单价 Euro | CA4: 金额 Euro | CD4: MIC回复
A9: 10月无2B订单

Sheet 2.2 正向-2C-GEL
A1: MIC德国海外仓一件代发明细表 | AM1: =SUM(AM5:AM71) -> 354.05 | AP1: =SUM(AP5:AP71) -> 0 | AS1: =SUM(AS5:AS71) -> 0 | AV1: =SUM(AV5:AV71) -> 0 | AY1: =SUM(AY5:AY71) -> 219 | AZ1: =SUM(AZ5:AZ71) -> 573.05 | BI1: =SUM(BI5:BI71) -> 3296.5742 | BN1: =SUM(BN5:BN71) -> 462.8 | BQ1: =SUM(BQ5:BQ71) -> 0 | BR1: =SUM(BR5:BR71) -> 3759.3742 | BS1: =SUM(BS5:BS71) -> 4332.7716
A2: ,1m, | BA2: 尾程运输费 | BS2: 总费用合计
A3: 出库指令 | AD3: 物品-拣料及最小包装 | AK3: 拣货&包装费 | AN3: 拣货续件费 | AQ3: 贴标费 | AT3: 包材费-包裹 | AW3: 装车费/搬运到卡车 | AZ3: 库内小计 | BA3: 基础费 | BJ3: 附加费 | BO3: 3件包裹以上运输续件费 | BR3: 尾程费用合计
A4: Order No. | B4: 订单 行数 | C4: 订单数 | D4: 对账 | E4: Warehouse | F4: 月份 | G4: Order Created At | H4: Shipped At | I4: Status | J4: Customer | K4: Original Reference | L4: Business Type | M4: Channel | N4: Creator | O4: 运单数 | P4: Priority | Q4: weight | R4: Carrier | S4: Carrier Return | T4: Shipments No1 | U4: Shipments No2 | V4: Retour No | W4: Postal Code | X4: 城市 | Y4: Country | Z4: sndZip | AA4: sndCity | AB4: sndCountry | AC4: RefOnLabel | AD4: Item ID | AE4: 物品描述 | AF4: 物品尺寸 长宽高cm | AG4: 单个物品 重量kg | AH4: Item Batch | AI4: Item Qty | AJ4: 订单重量 kg | AK4: 数量 套 | AL4: 单价 Euro | AM4: 金额 Euro | AN4: 数量 pcs | AO4: 单价 Euro | AP4: 金额 Euro | AQ4: 标签/张 | AR4: 单价 | AS4: 金额 | AT4: 数量 pcs | AU4: 单价 Euro | AV4: 金额 Euro | AW4: 托盘或散件 | AX4: 单价 Euro | AY4: 金额 Euro | BA4: 数量 票 | BB4: 实际重kg | BC4: 体积重KG | BD4: 计费 重量 kg | BE4: 邮编所属区域 | BF4: 城市 | BG4: 国家 | BH4: 单价 Euro | BI4: 金额 Euro | BJ4: 运输 订单 管理 * | BK4: 过路 过桥 * | BL4: 预约 通知 * | BM4: 其它 | BN4: 附加费小计 | BO4: 包裹数 个 | BP4: 单价 Euro | BQ4: 金额 Euro | BR4: 尾程费用合计 | BS4: 总费用合计
A5: ABM0009-251001-0002 | B5: =COUNTIF(A:A,A5) -> 1 | C5: 1 | E5: M | F5: 202510 | G5: 2025-10-01 | H5: 2025-10-01 | I5: Delivered | J5: YCD-EX:HUPPER TEK | K5: ABM0009-251001-0002 | L5: B2C | N5: qianhui.xu@miclogistik.de | O5: 1 | P5: NORMAL | Q5: 47.4 | R5: GELF-EML_HUPPERTEK | S5: RetourHermes_M | T5: 4618276352 | U5: =VLOOKUP(T5,[5]semitemu_order_export_251110144!$R:$S,2,0) -> PO-076-15674187067513743 | W5: 45699 | X5: Herten | Y5: DE | AC5: ABM0009-251001-0002 | AD5: B07BK8W5MF | AE5: 金属储物柜71英寸银色 | AF5: 188x49x14 | AG5: 47.4 | AI5: 1 | AJ5: =AI5*AG5 -> 47.4 | AK5: =AI5 -> 1 | AL5: 4.85 | AM5: =AL5*AK5 -> 4.85 | AP5: =AO5*AN5 -> 0 | AS5: =AR5*AQ5 -> 0 | AV5: =AU5*AT5 -> 0 | AW5: =O5 -> 1 | AX5: 3 | AY5: =AX5*AW5 -> 3 | AZ5: =AM5+AP5+AS5+AV5+AY5 -> 7.85 | BA5: 1 | BB5: =AJ5 -> 47.4 | BD5: 50 | BE5: =W5 -> 45699 | BF5: =X5 -> Herten | BG5: =Y5 -> DE | BH5: 46.558575 | BI5: =BH5 -> 46.558575 | BJ5: 2.5 | BK5: =0.024*BD5 -> 1.2 | BL5: 2.5 | BN5: =SUM(BJ5:BM5) -> 6.2 | BQ5: =BO5*BP5 -> 0 | BR5: =BI5+BN5+BQ5 -> 52.758575 | BS5: =AZ5+BR5 -> 60.608575
A6: ABM0009-251001-0001 | B6: =COUNTIF(A:A,A6) -> 1 | C6: 1 | E6: M | F6: 202510 | G6: 2025-10-01 | H6: 2025-10-01 | I6: Delivered | J6: YCD-EX:HUPPER TEK | K6: ABM0009-251001-0001 | L6: B2C | N6: qianhui.xu@miclogistik.de | O6: 1 | P6: NORMAL | Q6: 47.4 | R6: GELF-EML_HUPPERTEK | S6: RetourHermes_M | T6: 4618276345 | U6: =VLOOKUP(T6,[5]semitemu_order_export_251110144!$R:$S,2,0) -> PO-076-15674190083193743 | W6: 45699 | X6: Herten | Y6: DE | AC6: ABM0009-251001-0001 | AD6: B077RVYZRF | AE6: 德国联邦快递金属储物柜 | AF6: 188x49x14 | AG6: 47.4 | AI6: 1 | AJ6: =AI6*AG6 -> 47.4 | AK6: =AI6 -> 1 | AL6: 4.85 | AM6: =AL6*AK6 -> 4.85 | AP6: =AO6*AN6 -> 0 | AS6: =AR6*AQ6 -> 0 | AV6: =AU6*AT6 -> 0 | AW6: =O6 -> 1 | AX6: 3 | AY6: =AX6*AW6 -> 3 | AZ6: =AM6+AP6+AS6+AV6+AY6 -> 7.85 | BA6: 1 | BB6: =AJ6 -> 47.4 | BD6: 50 | BE6: =W6 -> 45699 | BF6: =X6 -> Herten | BG6: =Y6 -> DE | BH6: 46.558575 | BI6: =BH6 -> 46.558575 | BJ6: 2.5 | BK6: =0.024*BD6 -> 1.2 | BL6: 2.5 | BN6: =SUM(BJ6:BM6) -> 6.2 | BQ6: =BO6*BP6 -> 0 | BR6: =BI6+BN6+BQ6 -> 52.758575 | BS6: =AZ6+BR6 -> 60.608575
A7: ABM0009-251006-0003 | B7: =COUNTIF(A:A,A7) -> 1 | C7: 1 | E7: M | F7: 202510 | G7: 2025-10-06 | H7: 2025-10-06 | I7: Delivered | J7: YCD-EX:HUPPER TEK | K7: ABM0009-251006-0003 | L7: B2C | N7: qianhui.xu@miclogistik.de | O7: 1 | P7: NORMAL | Q7: 47.4 | R7: GELF-EML_HUPPERTEK | S7: RetourHermes_M | T7: 4618295421 | U7: =VLOOKUP(T7,[5]semitemu_order_export_251110144!$R:$S,2,0) -> PO-076-07335299241592215 | W7: 17033 | X7: Neubrandenburg | Y7: DE | AC7: ABM0009-251006-0003 | AD7: B07Q3SQT6C | AE7: 金属储物柜71英寸高 | AF7: 188x49x14 | AG7: 47.4 | AI7: 1 | AJ7: =AI7*AG7 -> 47.4 | AK7: =AI7 -> 1 | AL7: 4.85 | AM7: =AL7*AK7 -> 4.85 | AP7: =AO7*AN7 -> 0 | AS7: =AR7*AQ7 -> 0 | AV7: =AU7*AT7 -> 0 | AW7: =O7 -> 1 | AX7: 3 | AY7: =AX7*AW7 -> 3 | AZ7: =AM7+AP7+AS7+AV7+AY7 -> 7.85 | BA7: 1 | BB7: =AJ7 -> 47.4 | BD7: 50 | BE7: =W7 -> 17033 | BF7: =X7 -> Neubrandenburg | BG7: =Y7 -> DE | BH7: 46.558575 | BI7: =BH7 -> 46.558575 | BJ7: 2.5 | BK7: =0.024*BD7 -> 1.2 | BL7: 2.5 | BM7: 9 | BN7: =SUM(BJ7:BM7) -> 15.2 | BQ7: =BO7*BP7 -> 0 | BR7: =BI7+BN7+BQ7 -> 61.758575 | BS7: =AZ7+BR7 -> 69.608575
A8: ABM0009-251006-0002 | B8: =COUNTIF(A:A,A8) -> 1 | C8: 1 | E8: M | F8: 202510 | G8: 2025-10-06 | H8: 2025-10-06 | I8: Delivered | J8: YCD-EX:HUPPER TEK | K8: ABM0009-251006-0002 | L8: B2C | N8: qianhui.xu@miclogistik.de | O8: 1 | P8: NORMAL | Q8: 47.4 | R8: GELF-EML_HUPPERTEK | S8: RetourHermes_M | T8: 4618295414 | U8: =VLOOKUP(T8,[5]semitemu_order_export_251110144!$R:$S,2,0) -> PO-076-07375657288312516 | W8: 86169 | X8: Augsburg | Y8: DE | AC8: ABM0009-251006-0002 | AD8: B07Q3SQT6C | AE8: 金属储物柜71英寸高 | AF8: 188x49x14 | AG8: 47.4 | AI8: 1 | AJ8: =AI8*AG8 -> 47.4 | AK8: =AI8 -> 1 | AL8: 4.85 | AM8: =AL8*AK8 -> 4.85 | AP8: =AO8*AN8 -> 0 | AS8: =AR8*AQ8 -> 0 | AV8: =AU8*AT8 -> 0 | AW8: =O8 -> 1 | AX8: 3 | AY8: =AX8*AW8 -> 3 | AZ8: =AM8+AP8+AS8+AV8+AY8 -> 7.85 | BA8: 1 | BB8: =AJ8 -> 47.4 | BD8: 50 | BE8: =W8 -> 86169 | BF8: =X8 -> Augsburg | BG8: =Y8 -> DE | BH8: 46.558575 | BI8: =BH8 -> 46.558575 | BJ8: 2.5 | BK8: =0.024*BD8 -> 1.2 | BL8: 2.5 | BN8: =SUM(BJ8:BM8) -> 6.2 | BQ8: =BO8*BP8 -> 0 | BR8: =BI8+BN8+BQ8 -> 52.758575 | BS8: =AZ8+BR8 -> 60.608575
A9: ABM0009-251006-0001 | B9: =COUNTIF(A:A,A9) -> 1 | C9: 1 | E9: M | F9: 202510 | G9: 2025-10-06 | H9: 2025-10-06 | I9: Delivered | J9: YCD-EX:HUPPER TEK | K9: ABM0009-251006-0001 | L9: B2C | N9: qianhui.xu@miclogistik.de | O9: 1 | P9: NORMAL | Q9: 47.4 | R9: GELF-EML_HUPPERTEK | S9: RetourHermes_M | T9: 4618295407 | U9: =VLOOKUP(T9,[5]semitemu_order_export_251110144!$R:$S,2,0) -> PO-076-07324324385912278 | W9: 8626 | X9: Adorf/Vogtl. | Y9: DE | AC9: ABM0009-251006-0001 | AD9: B07Q3SQT6C | AE9: 金属储物柜71英寸高 | AF9: 188x49x14 | AG9: 47.4 | AI9: 1 | AJ9: =AI9*AG9 -> 47.4 | AK9: =AI9 -> 1 | AL9: 4.85 | AM9: =AL9*AK9 -> 4.85 | AP9: =AO9*AN9 -> 0 | AS9: =AR9*AQ9 -> 0 | AV9: =AU9*AT9 -> 0 | AW9: =O9 -> 1 | AX9: 3 | AY9: =AX9*AW9 -> 3 | AZ9: =AM9+AP9+AS9+AV9+AY9 -> 7.85 | BA9: 1 | BB9: =AJ9 -> 47.4 | BD9: 50 | BE9: =W9 -> 8626 | BF9: =X9 -> Adorf/Vogtl. | BG9: =Y9 -> DE | BH9: 46.558575 | BI9: =BH9 -> 46.558575 | BJ9: 2.5 | BK9: =0.024*BD9 -> 1.2 | BL9: 2.5 | BN9: =SUM(BJ9:BM9) -> 6.2 | BQ9: =BO9*BP9 -> 0 | BR9: =BI9+BN9+BQ9 -> 52.758575 | BS9: =AZ9+BR9 -> 60.608575
A10: ABM0009-251005-0005 | B10: =COUNTIF(A:A,A10) -> 1 | C10: 1 | E10: M | F10: 202510 | G10: 2025-10-06 | H10: 2025-10-06 | I10: Delivered | J10: YCD-EX:HUPPER TEK | K10: ABM0009-251005-0005 | L10: B2C | N10: qianhui.xu@miclogistik.de | O10: 1 | P10: NORMAL | Q10: 47.4 | R10: GELF-EML_HUPPERTEK | S10: RetourHermes_M | T10: 4618295391 | U10: =VLOOKUP(T10,[5]semitemu_order_export_251110144!$R:$S,2,0) -> PO-076-12849033505912372 | W10: 65618 | X10: Selters (taunus) | Y10: DE | AC10: ABM0009-251005-0005 | AD10: B07BK8W5MF | AE10: 金属储物柜71英寸银色 | AF10: 188x49x14 | AG10: 47.4 | AI10: 1 | AJ10: =AI10*AG10 -> 47.4 | AK10: =AI10 -> 1 | AL10: 4.85 | AM10: =AL10*AK10 -> 4.85 | AP10: =AO10*AN10 -> 0 | AS10: =AR10*AQ10 -> 0 | AV10: =AU10*AT10 -> 0 | AW10: =O10 -> 1 | AX10: 3 | AY10: =AX10*AW10 -> 3 | AZ10: =AM10+AP10+AS10+AV10+AY10 -> 7.85 | BA10: 1 | BB10: =AJ10 -> 47.4 | BD10: 50 | BE10: =W10 -> 65618 | BF10: =X10 -> Selters (taunus) | BG10: =Y10 -> DE | BH10: 46.558575 | BI10: =BH10 -> 46.558575 | BJ10: 2.5 | BK10: =0.024*BD10 -> 1.2 | BL10: 2.5 | BN10: =SUM(BJ10:BM10) -> 6.2 | BQ10: =BO10*BP10 -> 0 | BR10: =BI10+BN10+BQ10 -> 52.758575 | BS10: =AZ10+BR10 -> 60.608575
A11: ABM0009-251005-0004 | B11: =COUNTIF(A:A,A11) -> 1 | C11: 1 | E11: M | F11: 202510 | G11: 2025-10-06 | H11: 2025-10-06 | I11: Delivered | J11: YCD-EX:HUPPER TEK | K11: ABM0009-251005-0004 | L11: B2C | N11: qianhui.xu@miclogistik.de | O11: 1 | P11: NORMAL | Q11: 47.4 | R11: GELF-EML_HUPPERTEK | S11: RetourHermes_M | T11: 4618295384 | U11: =VLOOKUP(T11,[5]semitemu_order_export_251110144!$R:$S,2,0) -> PO-076-13025640325753368 | W11: 47226 | X11: Duisburg | Y11: DE | AC11: ABM0009-251005-0004 | AD11: B07Q3SQT6C | AE11: 金属储物柜71英寸高 | AF11: 188x49x14 | AG11: 47.4 | AI11: 1 | AJ11: =AI11*AG11 -> 47.4 | AK11: =AI11 -> 1 | AL11: 4.85 | AM11: =AL11*AK11 -> 4.85 | AP11: =AO11*AN11 -> 0 | AS11: =AR11*AQ11 -> 0 | AV11: =AU11*AT11 -> 0 | AW11: =O11 -> 1 | AX11: 3 | AY11: =AX11*AW11 -> 3 | AZ11: =AM11+AP11+AS11+AV11+AY11 -> 7.85 | BA11: 1 | BB11: =AJ11 -> 47.4 | BD11: 50 | BE11: =W11 -> 47226 | BF11: =X11 -> Duisburg | BG11: =Y11 -> DE | BH11: 46.558575 | BI11: =BH11 -> 46.558575 | BJ11: 2.5 | BK11: =0.024*BD11 -> 1.2 | BL11: 2.5 | BN11: =SUM(BJ11:BM11) -> 6.2 | BQ11: =BO11*BP11 -> 0 | BR11: =BI11+BN11+BQ11 -> 52.758575 | BS11: =AZ11+BR11 -> 60.608575
A12: ABM0009-251005-0003 | B12: =COUNTIF(A:A,A12) -> 1 | C12: 1 | E12: M | F12: 202510 | G12: 2025-10-06 | H12: 2025-10-06 | I12: Delivery Notify | J12: YCD-EX:HUPPER TEK | K12: ABM0009-251005-0003 | L12: B2C | N12: qianhui.xu@miclogistik.de | O12: 1 | P12: NORMAL | Q12: 47.4 | R12: GELF-EML_HUPPERTEK | S12: RetourHermes_M | T12: 4618295377 | U12: =VLOOKUP(T12,[5]semitemu_order_export_251110144!$R:$S,2,0) -> PO-076-12663615570551207 | W12: 10997 | X12: Berlin | Y12: DE | AC12: ABM0009-251005-0003 | AD12: B077RVYZRF | AE12: 德国联邦快递金属储物柜 | AF12: 188x49x14 | AG12: 47.4 | AI12: 1 | AJ12: =AI12*AG12 -> 47.4 | AK12: =AI12 -> 1 | AL12: 4.85 | AM12: =AL12*AK12 -> 4.85 | AP12: =AO12*AN12 -> 0 | AS12: =AR12*AQ12 -> 0 | AV12: =AU12*AT12 -> 0 | AW12: =O12 -> 1 | AX12: 3 | AY12: =AX12*AW12 -> 3 | AZ12: =AM12+AP12+AS12+AV12+AY12 -> 7.85 | BA12: 1 | BB12: =AJ12 -> 47.4 | BD12: 50 | BE12: =W12 -> 10997 | BF12: =X12 -> Berlin | BG12: =Y12 -> DE | BH12: 46.558575 | BI12: =BH12 -> 46.558575 | BJ12: 2.5 | BK12: =0.024*BD12 -> 1.2 | BL12: 2.5 | BM12: 7.8 | BN12: =SUM(BJ12:BM12) -> 14 | BQ12: =BO12*BP12 -> 0 | BR12: =BI12+BN12+BQ12 -> 60.558575 | BS12: =AZ12+BR12 -> 68.408575
A13: ABM0009-251005-0002 | B13: =COUNTIF(A:A,A13) -> 1 | C13: 1 | E13: M | F13: 202510 | G13: 2025-10-06 | H13: 2025-10-06 | I13: Delivered | J13: YCD-EX:HUPPER TEK | K13: ABM0009-251005-0002 | L13: B2C | N13: qianhui.xu@miclogistik.de | O13: 1 | P13: NORMAL | Q13: 47.4 | R13: GELF-EML_HUPPERTEK | S13: RetourHermes_M | T13: 4618295360 | U13: =VLOOKUP(T13,[5]semitemu_order_export_251110144!$R:$S,2,0) -> PO-076-12550580616311625 | W13: 78073 | X13: Bad Dürrheim | Y13: DE | AC13: ABM0009-251005-0002 | AD13: B07Q3SQT6C | AE13: 金属储物柜71英寸高 | AF13: 188x49x14 | AG13: 47.4 | AI13: 1 | AJ13: =AI13*AG13 -> 47.4 | AK13: =AI13 -> 1 | AL13: 4.85 | AM13: =AL13*AK13 -> 4.85 | AP13: =AO13*AN13 -> 0 | AS13: =AR13*AQ13 -> 0 | AV13: =AU13*AT13 -> 0 | AW13: =O13 -> 1 | AX13: 3 | AY13: =AX13*AW13 -> 3 | AZ13: =AM13+AP13+AS13+AV13+AY13 -> 7.85 | BA13: 1 | BB13: =AJ13 -> 47.4 | BD13: 50 | BE13: =W13 -> 78073 | BF13: =X13 -> Bad Dürrheim | BG13: =Y13 -> DE | BH13: 46.558575 | BI13: =BH13 -> 46.558575 | BJ13: 2.5 | BK13: =0.024*BD13 -> 1.2 | BL13: 2.5 | BN13: =SUM(BJ13:BM13) -> 6.2 | BQ13: =BO13*BP13 -> 0 | BR13: =BI13+BN13+BQ13 -> 52.758575 | BS13: =AZ13+BR13 -> 60.608575
A14: ABM0009-251005-0001 | B14: =COUNTIF(A:A,A14) -> 1 | C14: 1 | E14: M | F14: 202510 | G14: 2025-10-06 | H14: 2025-10-06 | I14: Delivered | J14: YCD-EX:HUPPER TEK | K14: ABM0009-251005-0001 | L14: B2C | N14: qianhui.xu@miclogistik.de | O14: 1 | P14: NORMAL | Q14: 47.4 | R14: GELF-EML_HUPPERTEK | S14: RetourHermes_M | T14: 4618295353 | U14: =VLOOKUP(T14,[5]semitemu_order_export_251110144!$R:$S,2,0) -> PO-076-13035591900793564 | W14: 52399 | X14: Merzenich | Y14: DE | AC14: ABM0009-251005-0001 | AD14: B076THQBHX | AE14: 金属储物柜71英寸灰色 | AF14: 188x49x14 | AG14: 47.4 | AI14: 1 | AJ14: =AI14*AG14 -> 47.4 | AK14: =AI14 -> 1 | AL14: 4.85 | AM14: =AL14*AK14 -> 4.85 | AP14: =AO14*AN14 -> 0 | AS14: =AR14*AQ14 -> 0 | AV14: =AU14*AT14 -> 0 | AW14: =O14 -> 1 | AX14: 3 | AY14: =AX14*AW14 -> 3 | AZ14: =AM14+AP14+AS14+AV14+AY14 -> 7.85 | BA14: 1 | BB14: =AJ14 -> 47.4 | BD14: 50 | BE14: =W14 -> 52399 | BF14: =X14 -> Merzenich | BG14: =Y14 -> DE | BH14: 46.558575 | BI14: =BH14 -> 46.558575 | BJ14: 2.5 | BK14: =0.024*BD14 -> 1.2 | BL14: 2.5 | BN14: =SUM(BJ14:BM14) -> 6.2 | BQ14: =BO14*BP14 -> 0 | BR14: =BI14+BN14+BQ14 -> 52.758575 | BS14: =AZ14+BR14 -> 60.608575
A15: ABM0009-251004-0002 | B15: =COUNTIF(A:A,A15) -> 1 | C15: 1 | E15: M | F15: 202510 | G15: 2025-10-06 | H15: 2025-10-06 | I15: Delivered | J15: YCD-EX:HUPPER TEK | K15: ABM0009-251004-0002 | L15: B2C | N15: qianhui.xu@miclogistik.de | O15: 1 | P15: NORMAL | Q15: 47.4 | R15: GELF-EML_HUPPERTEK | S15: RetourHermes_M | T15: 4618295346 | U15: =VLOOKUP(T15,[5]semitemu_order_export_251110144!$R:$S,2,0) -> PO-076-01386897395830548 | W15: 21073 | X15: Hamburg | Y15: DE | AC15: ABM0009-251004-0002 | AD15: B076THQBHX | AE15: 金属储物柜71英寸灰色 | AF15: 188x49x14 | AG15: 47.4 | AI15: 1 | AJ15: =AI15*AG15 -> 47.4 | AK15: =AI15 -> 1 | AL15: 4.85 | AM15: =AL15*AK15 -> 4.85 | AP15: =AO15*AN15 -> 0 | AS15: =AR15*AQ15 -> 0 | AV15: =AU15*AT15 -> 0 | AW15: =O15 -> 1 | AX15: 3 | AY15: =AX15*AW15 -> 3 | AZ15: =AM15+AP15+AS15+AV15+AY15 -> 7.85 | BA15: 1 | BB15: =AJ15 -> 47.4 | BD15: 50 | BE15: =W15 -> 21073 | BF15: =X15 -> Hamburg | BG15: =Y15 -> DE | BH15: 46.558575 | BI15: =BH15 -> 46.558575 | BJ15: 2.5 | BK15: =0.024*BD15 -> 1.2 | BL15: 2.5 | BM15: 7.8 | BN15: =SUM(BJ15:BM15) -> 14 | BQ15: =BO15*BP15 -> 0 | BR15: =BI15+BN15+BQ15 -> 60.558575 | BS15: =AZ15+BR15 -> 68.408575
A16: ABM0009-251004-0001 | B16: =COUNTIF(A:A,A16) -> 1 | C16: 1 | E16: M | F16: 202510 | G16: 2025-10-06 | H16: 2025-10-06 | I16: Delivered | J16: YCD-EX:HUPPER TEK | K16: ABM0009-251004-0001 | L16: B2C | N16: qianhui.xu@miclogistik.de | O16: 1 | P16: NORMAL | Q16: 47.4 | R16: GELF-EML_HUPPERTEK | S16: RetourHermes_M | T16: 4618295339 | U16: =VLOOKUP(T16,[5]semitemu_order_export_251110144!$R:$S,2,0) -> PO-076-01536533002870424 | W16: 37120 | X16: Bovenden | Y16: DE | AC16: ABM0009-251004-0001 | AD16: B07BK8W5MF | AE16: 金属储物柜71英寸银色 | AF16: 188x49x14 | AG16: 47.4 | AI16: 1 | AJ16: =AI16*AG16 -> 47.4 | AK16: =AI16 -> 1 | AL16: 4.85 | AM16: =AL16*AK16 -> 4.85 | AP16: =AO16*AN16 -> 0 | AS16: =AR16*AQ16 -> 0 | AV16: =AU16*AT16 -> 0 | AW16: =O16 -> 1 | AX16: 3 | AY16: =AX16*AW16 -> 3 | AZ16: =AM16+AP16+AS16+AV16+AY16 -> 7.85 | BA16: 1 | BB16: =AJ16 -> 47.4 | BD16: 50 | BE16: =W16 -> 37120 | BF16: =X16 -> Bovenden | BG16: =Y16 -> DE | BH16: 46.558575 | BI16: =BH16 -> 46.558575 | BJ16: 2.5 | BK16: =0.024*BD16 -> 1.2 | BL16: 2.5 | BN16: =SUM(BJ16:BM16) -> 6.2 | BQ16: =BO16*BP16 -> 0 | BR16: =BI16+BN16+BQ16 -> 52.758575 | BS16: =AZ16+BR16 -> 60.608575
A17: ABM0009-251002-0007 | B17: =COUNTIF(A:A,A17) -> 1 | C17: 1 | E17: M | F17: 202510 | G17: 2025-10-06 | H17: 2025-10-06 | I17: Delivered | J17: YCD-EX:HUPPER TEK | K17: ABM0009-251002-0007 | L17: B2C | N17: qianhui.xu@miclogistik.de | O17: 1 | P17: NORMAL | Q17: 47.4 | R17: GELF-EML_HUPPERTEK | S17: RetourHermes_M | T17: 4618295322 | U17: =VLOOKUP(T17,[5]semitemu_order_export_251110144!$R:$S,2,0) -> PO-076-10112202624632335 | W17: 23758 | X17: Oldenburg in Holstein | Y17: DE | AC17: ABM0009-251002-0007 | AD17: B07Q3SQT6C | AE17: 金属储物柜71英寸高 | AF17: 188x49x14 | AG17: 47.4 | AI17: 1 | AJ17: =AI17*AG17 -> 47.4 | AK17: =AI17 -> 1 | AL17: 4.85 | AM17: =AL17*AK17 -> 4.85 | AP17: =AO17*AN17 -> 0 | AS17: =AR17*AQ17 -> 0 | AV17: =AU17*AT17 -> 0 | AW17: =O17 -> 1 | AX17: 3 | AY17: =AX17*AW17 -> 3 | AZ17: =AM17+AP17+AS17+AV17+AY17 -> 7.85 | BA17: 1 | BB17: =AJ17 -> 47.4 | BD17: 50 | BE17: =W17 -> 23758 | BF17: =X17 -> Oldenburg in Holstein | BG17: =Y17 -> DE | BH17: 46.558575 | BI17: =BH17 -> 46.558575 | BJ17: 2.5 | BK17: =0.024*BD17 -> 1.2 | BL17: 2.5 | BN17: =SUM(BJ17:BM17) -> 6.2 | BQ17: =BO17*BP17 -> 0 | BR17: =BI17+BN17+BQ17 -> 52.758575 | BS17: =AZ17+BR17 -> 60.608575
A18: ABM0009-251002-0006 | B18: =COUNTIF(A:A,A18) -> 1 | C18: 1 | E18: M | F18: 202510 | G18: 2025-10-06 | H18: 2025-10-06 | I18: Delivered | J18: YCD-EX:HUPPER TEK | K18: ABM0009-251002-0006 | L18: B2C | N18: qianhui.xu@miclogistik.de | O18: 1 | P18: NORMAL | Q18: 47.4 | R18: GELF-EML_HUPPERTEK | S18: RetourHermes_M | T18: 4618295315 | U18: =VLOOKUP(T18,[5]semitemu_order_export_251110144!$R:$S,2,0) -> PO-076-10112202624632335 | W18: 23758 | X18: Oldenburg in Holstein | Y18: DE | AC18: ABM0009-251002-0006 | AD18: B07Q3SQT6C | AE18: 金属储物柜71英寸高 | AF18: 188x49x14 | AG18: 47.4 | AI18: 1 | AJ18: =AI18*AG18 -> 47.4 | AK18: =AI18 -> 1 | AL18: 4.85 | AM18: =AL18*AK18 -> 4.85 | AP18: =AO18*AN18 -> 0 | AS18: =AR18*AQ18 -> 0 | AV18: =AU18*AT18 -> 0 | AW18: =O18 -> 1 | AX18: 3 | AY18: =AX18*AW18 -> 3 | AZ18: =AM18+AP18+AS18+AV18+AY18 -> 7.85 | BA18: 1 | BB18: =AJ18 -> 47.4 | BD18: 50 | BE18: =W18 -> 23758 | BF18: =X18 -> Oldenburg in Holstein | BG18: =Y18 -> DE | BH18: 46.558575 | BI18: =BH18 -> 46.558575 | BJ18: 2.5 | BK18: =0.024*BD18 -> 1.2 | BL18: 2.5 | BN18: =SUM(BJ18:BM18) -> 6.2 | BQ18: =BO18*BP18 -> 0 | BR18: =BI18+BN18+BQ18 -> 52.758575 | BS18: =AZ18+BR18 -> 60.608575
A19: ABM0009-251002-0005 | B19: =COUNTIF(A:A,A19) -> 1 | C19: 1 | E19: M | F19: 202510 | G19: 2025-10-06 | H19: 2025-10-06 | I19: Delivered | J19: YCD-EX:HUPPER TEK | K19: ABM0009-251002-0005 | L19: B2C | N19: qianhui.xu@miclogistik.de | O19: 1 | P19: NORMAL | Q19: 47.4 | R19: GELF-EML_HUPPERTEK | S19: RetourHermes_M | T19: 4618295308 | U19: =VLOOKUP(T19,[5]semitemu_order_export_251110144!$R:$S,2,0) -> PO-076-10197391601273843 | W19: 93170 | X19: Bernhardswald | Y19: DE | AC19: ABM0009-251002-0005 | AD19: B07Q3SQT6C | AE19: 金属储物柜71英寸高 | AF19: 188x49x14 | AG19: 47.4 | AI19: 1 | AJ19: =AI19*AG19 -> 47.4 | AK19: =AI19 -> 1 | AL19: 4.85 | AM19: =AL19*AK19 -> 4.85 | AP19: =AO19*AN19 -> 0 | AS19: =AR19*AQ19 -> 0 | AV19: =AU19*AT19 -> 0 | AW19: =O19 -> 1 | AX19: 3 | AY19: =AX19*AW19 -> 3 | AZ19: =AM19+AP19+AS19+AV19+AY19 -> 7.85 | BA19: 1 | BB19: =AJ19 -> 47.4 | BD19: 50 | BE19: =W19 -> 93170 | BF19: =X19 -> Bernhardswald | BG19: =Y19 -> DE | BH19: 46.558575 | BI19: =BH19 -> 46.558575 | BJ19: 2.5 | BK19: =0.024*BD19 -> 1.2 | BL19: 2.5 | BN19: =SUM(BJ19:BM19) -> 6.2 | BQ19: =BO19*BP19 -> 0 | BR19: =BI19+BN19+BQ19 -> 52.758575 | BS19: =AZ19+BR19 -> 60.608575
A20: ABM0009-251002-0004 | B20: =COUNTIF(A:A,A20) -> 1 | C20: 1 | E20: M | F20: 202510 | G20: 2025-10-06 | H20: 2025-10-06 | I20: Delivered | J20: YCD-EX:HUPPER TEK | K20: ABM0009-251002-0004 | L20: B2C | N20: qianhui.xu@miclogistik.de | O20: 1 | P20: NORMAL | Q20: 47.4 | R20: GELF-EML_HUPPERTEK | S20: RetourHermes_M | T20: 4618295292 | U20: =VLOOKUP(T20,[5]semitemu_order_export_251110144!$R:$S,2,0) -> PO-076-10100283011192372 | W20: 65618 | X20: Selters (taunus) | Y20: DE | AC20: ABM0009-251002-0004 | AD20: B07Q3SQT6C | AE20: 金属储物柜71英寸高 | AF20: 188x49x14 | AG20: 47.4 | AI20: 1 | AJ20: =AI20*AG20 -> 47.4 | AK20: =AI20 -> 1 | AL20: 4.85 | AM20: =AL20*AK20 -> 4.85 | AP20: =AO20*AN20 -> 0 | AS20: =AR20*AQ20 -> 0 | AV20: =AU20*AT20 -> 0 | AW20: =O20 -> 1 | AX20: 3 | AY20: =AX20*AW20 -> 3 | AZ20: =AM20+AP20+AS20+AV20+AY20 -> 7.85 | BA20: 1 | BB20: =AJ20 -> 47.4 | BD20: 50 | BE20: =W20 -> 65618 | BF20: =X20 -> Selters (taunus) | BG20: =Y20 -> DE | BH20: 46.558575 | BI20: =BH20 -> 46.558575 | BJ20: 2.5 | BK20: =0.024*BD20 -> 1.2 | BL20: 2.5 | BN20: =SUM(BJ20:BM20) -> 6.2 | BQ20: =BO20*BP20 -> 0 | BR20: =BI20+BN20+BQ20 -> 52.758575 | BS20: =AZ20+BR20 -> 60.608575
A21: ABM0009-251002-0003 | B21: =COUNTIF(A:A,A21) -> 1 | C21: 1 | E21: M | F21: 202510 | G21: 2025-10-06 | H21: 2025-10-06 | I21: Delivered | J21: YCD-EX:HUPPER TEK | K21: ABM0009-251002-0003 | L21: B2C | N21: qianhui.xu@miclogistik.de | O21: 1 | P21: NORMAL | Q21: 47.4 | R21: GELF-EML_HUPPERTEK | S21: RetourHermes_M | T21: 4618295285 | U21: =VLOOKUP(T21,[5]semitemu_order_export_251110144!$R:$S,2,0) -> PO-076-09867602550392001 | W21: 37308 | X21: Bodenrode-Westhausen | Y21: DE | AC21: ABM0009-251002-0003 | AD21: B07BK8W5MF | AE21: 金属储物柜71英寸银色 | AF21: 188x49x14 | AG21: 47.4 | AI21: 1 | AJ21: =AI21*AG21 -> 47.4 | AK21: =AI21 -> 1 | AL21: 4.85 | AM21: =AL21*AK21 -> 4.85 | AP21: =AO21*AN21 -> 0 | AS21: =AR21*AQ21 -> 0 | AV21: =AU21*AT21 -> 0 | AW21: =O21 -> 1 | AX21: 3 | AY21: =AX21*AW21 -> 3 | AZ21: =AM21+AP21+AS21+AV21+AY21 -> 7.85 | BA21: 1 | BB21: =AJ21 -> 47.4 | BD21: 50 | BE21: =W21 -> 37308 | BF21: =X21 -> Bodenrode-Westhausen | BG21: =Y21 -> DE | BH21: 46.558575 | BI21: =BH21 -> 46.558575 | BJ21: 2.5 | BK21: =0.024*BD21 -> 1.2 | BL21: 2.5 | BN21: =SUM(BJ21:BM21) -> 6.2 | BQ21: =BO21*BP21 -> 0 | BR21: =BI21+BN21+BQ21 -> 52.758575 | BS21: =AZ21+BR21 -> 60.608575
A22: ABM0009-251002-0002 | B22: =COUNTIF(A:A,A22) -> 1 | C22: 1 | E22: M | F22: 202510 | G22: 2025-10-06 | H22: 2025-10-06 | I22: Delivered | J22: YCD-EX:HUPPER TEK | K22: ABM0009-251002-0002 | L22: B2C | N22: qianhui.xu@miclogistik.de | O22: 1 | P22: NORMAL | Q22: 47.4 | R22: GELF-EML_HUPPERTEK | S22: RetourHermes_M | T22: 4618295278 | U22: =VLOOKUP(T22,[5]semitemu_order_export_251110144!$R:$S,2,0) -> PO-076-10301733824633509 | W22: 97494 | X22: Bundorf | Y22: DE | AC22: ABM0009-251002-0002 | AD22: B07Q3SQT6C | AE22: 金属储物柜71英寸高 | AF22: 188x49x14 | AG22: 47.4 | AI22: 1 | AJ22: =AI22*AG22 -> 47.4 | AK22: =AI22 -> 1 | AL22: 4.85 | AM22: =AL22*AK22 -> 4.85 | AP22: =AO22*AN22 -> 0 | AS22: =AR22*AQ22 -> 0 | AV22: =AU22*AT22 -> 0 | AW22: =O22 -> 1 | AX22: 3 | AY22: =AX22*AW22 -> 3 | AZ22: =AM22+AP22+AS22+AV22+AY22 -> 7.85 | BA22: 1 | BB22: =AJ22 -> 47.4 | BD22: 50 | BE22: =W22 -> 97494 | BF22: =X22 -> Bundorf | BG22: =Y22 -> DE | BH22: 46.558575 | BI22: =BH22 -> 46.558575 | BJ22: 2.5 | BK22: =0.024*BD22 -> 1.2 | BL22: 2.5 | BN22: =SUM(BJ22:BM22) -> 6.2 | BQ22: =BO22*BP22 -> 0 | BR22: =BI22+BN22+BQ22 -> 52.758575 | BS22: =AZ22+BR22 -> 60.608575
A23: ABM0009-251002-0001 | B23: =COUNTIF(A:A,A23) -> 1 | C23: 1 | E23: M | F23: 202510 | G23: 2025-10-06 | H23: 2025-10-06 | I23: Delivered | J23: YCD-EX:HUPPER TEK | K23: ABM0009-251002-0001 | L23: B2C | N23: qianhui.xu@miclogistik.de | O23: 1 | P23: NORMAL | Q23: 47.4 | R23: GELF-EML_HUPPERTEK | S23: RetourHermes_M | T23: 4618295247 | U23: =VLOOKUP(T23,[5]semitemu_order_export_251110144!$R:$S,2,0) -> PO-076-20903654042231245 | W23: 83620 | X23: Feldkirchen-westerham | Y23: DE | AC23: ABM0009-251002-0001 | AD23: B076THQBHX | AE23: 金属储物柜71英寸灰色 | AF23: 188x49x14 | AG23: 47.4 | AI23: 1 | AJ23: =AI23*AG23 -> 47.4 | AK23: =AI23 -> 1 | AL23: 4.85 | AM23: =AL23*AK23 -> 4.85 | AP23: =AO23*AN23 -> 0 | AS23: =AR23*AQ23 -> 0 | AV23: =AU23*AT23 -> 0 | AW23: =O23 -> 1 | AX23: 3 | AY23: =AX23*AW23 -> 3 | AZ23: =AM23+AP23+AS23+AV23+AY23 -> 7.85 | BA23: 1 | BB23: =AJ23 -> 47.4 | BD23: 50 | BE23: =W23 -> 83620 | BF23: =X23 -> Feldkirchen-westerham | BG23: =Y23 -> DE | BH23: 46.558575 | BI23: =BH23 -> 46.558575 | BJ23: 2.5 | BK23: =0.024*BD23 -> 1.2 | BL23: 2.5 | BN23: =SUM(BJ23:BM23) -> 6.2 | BQ23: =BO23*BP23 -> 0 | BR23: =BI23+BN23+BQ23 -> 52.758575 | BS23: =AZ23+BR23 -> 60.608575
A24: ABM0009-251007-0002 | B24: =COUNTIF(A:A,A24) -> 1 | C24: 1 | E24: M | F24: 202510 | G24: 2025-10-07 | H24: 2025-10-07 | I24: Delivered | J24: YCD-EX:HUPPER TEK | K24: ABM0009-251007-0002 | L24: B2C | N24: qianhui.xu@miclogistik.de | O24: 1 | P24: NORMAL | Q24: 47.4 | R24: GELF-EML_HUPPERTEK | S24: RetourHermes_M | T24: 4618302853 | U24: =VLOOKUP(T24,[5]semitemu_order_export_251110144!$R:$S,2,0) -> PO-076-18114922916471963 | W24: 26871 | X24: Aschendorf | Y24: DE | AC24: ABM0009-251007-0002 | AD24: B076THQBHX | AE24: 金属储物柜71英寸灰色 | AF24: 188x49x14 | AG24: 47.4 | AI24: 1 | AJ24: =AI24*AG24 -> 47.4 | AK24: =AI24 -> 1 | AL24: 4.85 | AM24: =AL24*AK24 -> 4.85 | AP24: =AO24*AN24 -> 0 | AS24: =AR24*AQ24 -> 0 | AV24: =AU24*AT24 -> 0 | AW24: =O24 -> 1 | AX24: 3 | AY24: =AX24*AW24 -> 3 | AZ24: =AM24+AP24+AS24+AV24+AY24 -> 7.85 | BA24: 1 | BB24: =AJ24 -> 47.4 | BD24: 50 | BE24: =W24 -> 26871 | BF24: =X24 -> Aschendorf | BG24: =Y24 -> DE | BH24: 46.558575 | BI24: =BH24 -> 46.558575 | BJ24: 2.5 | BK24: =0.024*BD24 -> 1.2 | BL24: 2.5 | BN24: =SUM(BJ24:BM24) -> 6.2 | BQ24: =BO24*BP24 -> 0 | BR24: =BI24+BN24+BQ24 -> 52.758575 | BS24: =AZ24+BR24 -> 60.608575
A25: ABM0009-251007-0001 | B25: =COUNTIF(A:A,A25) -> 1 | C25: 1 | E25: M | F25: 202510 | G25: 2025-10-07 | H25: 2025-10-07 | I25: Delivered | J25: YCD-EX:HUPPER TEK | K25: ABM0009-251007-0001 | L25: B2C | N25: qianhui.xu@miclogistik.de | O25: 1 | P25: NORMAL | Q25: 47.4 | R25: GELF-EML_HUPPERTEK | S25: RetourHermes_M | T25: 4618302846 | U25: =VLOOKUP(T25,[5]semitemu_order_export_251110144!$R:$S,2,0) -> PO-076-18438716672633873 | W25: 85375 | X25: Neufahrn b. Freising | Y25: DE | AC25: ABM0009-251007-0001 | AD25: B07Q3SQT6C | AE25: 金属储物柜71英寸高 | AF25: 188x49x14 | AG25: 47.4 | AI25: 1 | AJ25: =AI25*AG25 -> 47.4 | AK25: =AI25 -> 1 | AL25: 4.85 | AM25: =AL25*AK25 -> 4.85 | AP25: =AO25*AN25 -> 0 | AS25: =AR25*AQ25 -> 0 | AV25: =AU25*AT25 -> 0 | AW25: =O25 -> 1 | AX25: 3 | AY25: =AX25*AW25 -> 3 | AZ25: =AM25+AP25+AS25+AV25+AY25 -> 7.85 | BA25: 1 | BB25: =AJ25 -> 47.4 | BD25: 50 | BE25: =W25 -> 85375 | BF25: =X25 -> Neufahrn b. Freising | BG25: =Y25 -> DE | BH25: 46.558575 | BI25: =BH25 -> 46.558575 | BJ25: 2.5 | BK25: =0.024*BD25 -> 1.2 | BL25: 2.5 | BN25: =SUM(BJ25:BM25) -> 6.2 | BQ25: =BO25*BP25 -> 0 | BR25: =BI25+BN25+BQ25 -> 52.758575 | BS25: =AZ25+BR25 -> 60.608575
A26: ABM0009-251008-0003 | B26: =COUNTIF(A:A,A26) -> 1 | C26: 1 | E26: M | F26: 202510 | G26: 2025-10-08 | H26: 2025-10-08 | I26: Delivered | J26: YCD-EX:HUPPER TEK | K26: ABM0009-251008-0003 | L26: B2C | N26: qianhui.xu@miclogistik.de | O26: 1 | P26: NORMAL | Q26: 47.4 | R26: GELF-EML_HUPPERTEK | S26: RetourHermes_M | T26: 4618317444 | U26: =VLOOKUP(T26,[5]semitemu_order_export_251110144!$R:$S,2,0) -> PO-076-03898465820792218 | W26: 45145 | X26: Essen | Y26: DE | AC26: ABM0009-251008-0003 | AD26: B07Q3SQT6C | AE26: 金属储物柜71英寸高 | AF26: 188x49x14 | AG26: 47.4 | AI26: 1 | AJ26: =AI26*AG26 -> 47.4 | AK26: =AI26 -> 1 | AL26: 4.85 | AM26: =AL26*AK26 -> 4.85 | AP26: =AO26*AN26 -> 0 | AS26: =AR26*AQ26 -> 0 | AV26: =AU26*AT26 -> 0 | AW26: =O26 -> 1 | AX26: 3 | AY26: =AX26*AW26 -> 3 | AZ26: =AM26+AP26+AS26+AV26+AY26 -> 7.85 | BA26: 1 | BB26: =AJ26 -> 47.4 | BD26: 50 | BE26: =W26 -> 45145 | BF26: =X26 -> Essen | BG26: =Y26 -> DE | BH26: 46.558575 | BI26: =BH26 -> 46.558575 | BJ26: 2.5 | BK26: =0.024*BD26 -> 1.2 | BL26: 2.5 | BN26: =SUM(BJ26:BM26) -> 6.2 | BQ26: =BO26*BP26 -> 0 | BR26: =BI26+BN26+BQ26 -> 52.758575 | BS26: =AZ26+BR26 -> 60.608575
A27: ABM0009-251008-0002 | B27: =COUNTIF(A:A,A27) -> 1 | C27: 1 | E27: M | F27: 202510 | G27: 2025-10-08 | H27: 2025-10-08 | I27: Delivered | J27: YCD-EX:HUPPER TEK | K27: ABM0009-251008-0002 | L27: B2C | N27: qianhui.xu@miclogistik.de | O27: 1 | P27: NORMAL | Q27: 47.4 | R27: GELF-EML_HUPPERTEK | S27: RetourHermes_M | T27: 4618317437 | U27: =VLOOKUP(T27,[5]semitemu_order_export_251110144!$R:$S,2,0) -> PO-076-03898465820792218 | W27: 45145 | X27: Essen | Y27: DE | AC27: ABM0009-251008-0002 | AD27: B07Q3SQT6C | AE27: 金属储物柜71英寸高 | AF27: 188x49x14 | AG27: 47.4 | AI27: 1 | AJ27: =AI27*AG27 -> 47.4 | AK27: =AI27 -> 1 | AL27: 4.85 | AM27: =AL27*AK27 -> 4.85 | AP27: =AO27*AN27 -> 0 | AS27: =AR27*AQ27 -> 0 | AV27: =AU27*AT27 -> 0 | AW27: =O27 -> 1 | AX27: 3 | AY27: =AX27*AW27 -> 3 | AZ27: =AM27+AP27+AS27+AV27+AY27 -> 7.85 | BA27: 1 | BB27: =AJ27 -> 47.4 | BD27: 50 | BE27: =W27 -> 45145 | BF27: =X27 -> Essen | BG27: =Y27 -> DE | BH27: 46.558575 | BI27: =BH27 -> 46.558575 | BJ27: 2.5 | BK27: =0.024*BD27 -> 1.2 | BL27: 2.5 | BN27: =SUM(BJ27:BM27) -> 6.2 | BQ27: =BO27*BP27 -> 0 | BR27: =BI27+BN27+BQ27 -> 52.758575 | BS27: =AZ27+BR27 -> 60.608575
... A35: ABM0009-251013-0002 | B35: =COUNTIF(A:A,A35) -> 1 | C35: 1 | E35: M | F35: 202510 | G35: 2025-10-13 | H35: 2025-10-13 | I35: Delivered | J35: YCD-EX:HUPPER TEK | K35: ABM0009-251013-0002 | L35: B2C | N35: qianhui.xu@miclogistik.de | O35: 1 | P35: NORMAL | Q35: 47.4 | R35: GELF-EML_HUPPERTEK | S35: RetourHermes_M | T35: 4618357204 | U35: =VLOOKUP(T35,[5]semitemu_order_export_251110144!$R:$S,2,0) -> PO-076-11763896474230904 | W35: 61130 | X35: Nidderau | Y35: DE | AC35: ABM0009-251013-0002 | AD35: B07Q3SQT6C | AE35: 金属储物柜71英寸高 | AF35: 188x49x14 | AG35: 47.4 | AI35: 1 | AJ35: =AI35*AG35 -> 47.4 | AK35: =AI35 -> 1 | AL35: 4.85 | AM35: =AL35*AK35 -> 4.85 | AP35: =AO35*AN35 -> 0 | AS35: =AR35*AQ35 -> 0 | AV35: =AU35*AT35 -> 0 | AW35: =O35 -> 1 | AX35: 3 | AY35: =AX35*AW35 -> 3 | AZ35: =AM35+AP35+AS35+AV35+AY35 -> 7.85 | BA35: 1 | BB35: =AJ35 -> 47.4 | BD35: 50 | BE35: =W35 -> 61130 | BF35: =X35 -> Nidderau | BG35: =Y35 -> DE | BH35: 46.558575 | BI35: =BH35 -> 46.558575 | BJ35: 2.5 | BK35: =0.024*BD35 -> 1.2 | BL35: 2.5 | BN35: =SUM(BJ35:BM35) -> 6.2 | BQ35: =BO35*BP35 -> 0 | BR35: =BI35+BN35+BQ35 -> 52.758575 | BS35: =AZ35+BR35 -> 60.608575
A36: ABM0009-251013-0001 | B36: =COUNTIF(A:A,A36) -> 1 | C36: 1 | E36: M | F36: 202510 | G36: 2025-10-13 | H36: 2025-10-13 | I36: Delivered | J36: YCD-EX:HUPPER TEK | K36: ABM0009-251013-0001 | L36: B2C | N36: qianhui.xu@miclogistik.de | O36: 1 | P36: NORMAL | Q36: 47.4 | R36: GELF-EML_HUPPERTEK | S36: RetourHermes_M | T36: 4618357198 | U36: =VLOOKUP(T36,[6]ebay_order_export_251110145132!$S:$T,2,0) -> 14-13687-11781 | W36: 23569 | X36: Lübeck | Y36: DE | AC36: ABM0009-251013-0001 | AD36: B07Q3SQT6C | AE36: 金属储物柜71英寸高 | AF36: 188x49x14 | AG36: 47.4 | AI36: 1 | AJ36: =AI36*AG36 -> 47.4 | AK36: =AI36 -> 1 | AL36: 4.85 | AM36: =AL36*AK36 -> 4.85 | AP36: =AO36*AN36 -> 0 | AS36: =AR36*AQ36 -> 0 | AV36: =AU36*AT36 -> 0 | AW36: =O36 -> 1 | AX36: 3 | AY36: =AX36*AW36 -> 3 | AZ36: =AM36+AP36+AS36+AV36+AY36 -> 7.85 | BA36: 1 | BB36: =AJ36 -> 47.4 | BD36: 50 | BE36: =W36 -> 23569 | BF36: =X36 -> Lübeck | BG36: =Y36 -> DE | BH36: 46.558575 | BI36: =BH36 -> 46.558575 | BJ36: 2.5 | BK36: =0.024*BD36 -> 1.2 | BL36: 2.5 | BN36: =SUM(BJ36:BM36) -> 6.2 | BQ36: =BO36*BP36 -> 0 | BR36: =BI36+BN36+BQ36 -> 52.758575 | BS36: =AZ36+BR36 -> 60.608575
A37: ABM0009-251011-0002 | B37: =COUNTIF(A:A,A37) -> 1 | C37: 1 | E37: M | F37: 202510 | G37: 2025-10-13 | H37: 2025-10-13 | I37: Delivered | J37: YCD-EX:HUPPER TEK | K37: ABM0009-251011-0002 | L37: B2C | N37: qianhui.xu@miclogistik.de | O37: 1 | P37: NORMAL | Q37: 47.4 | R37: GELF-EML_HUPPERTEK | S37: RetourHermes_M | T37: 4618357181 | U37: =VLOOKUP(T37,[5]semitemu_order_export_251110144!$R:$S,2,0) -> PO-076-20612291739513460 | W37: 23843 | X37: Bad Oldesloe | Y37: DE | AC37: ABM0009-251011-0002 | AD37: B07Q3SQT6C | AE37: 金属储物柜71英寸高 | AF37: 188x49x14 | AG37: 47.4 | AI37: 1 | AJ37: =AI37*AG37 -> 47.4 | AK37: =AI37 -> 1 | AL37: 4.85 | AM37: =AL37*AK37 -> 4.85 | AP37: =AO37*AN37 -> 0 | AS37: =AR37*AQ37 -> 0 | AV37: =AU37*AT37 -> 0 | AW37: =O37 -> 1 | AX37: 3 | AY37: =AX37*AW37 -> 3 | AZ37: =AM37+AP37+AS37+AV37+AY37 -> 7.85 | BA37: 1 | BB37: =AJ37 -> 47.4 | BD37: 50 | BE37: =W37 -> 23843 | BF37: =X37 -> Bad Oldesloe | BG37: =Y37 -> DE | BH37: 46.558575 | BI37: =BH37 -> 46.558575 | BJ37: 2.5 | BK37: =0.024*BD37 -> 1.2 | BL37: 2.5 | BN37: =SUM(BJ37:BM37) -> 6.2 | BQ37: =BO37*BP37 -> 0 | BR37: =BI37+BN37+BQ37 -> 52.758575 | BS37: =AZ37+BR37 -> 60.608575
A38: ABM0009-251011-0001 | B38: =COUNTIF(A:A,A38) -> 1 | C38: 1 | E38: M | F38: 202510 | G38: 2025-10-13 | H38: 2025-10-13 | I38: Delivered | J38: YCD-EX:HUPPER TEK | K38: ABM0009-251011-0001 | L38: B2C | N38: qianhui.xu@miclogistik.de | O38: 1 | P38: NORMAL | Q38: 47.4 | R38: GELF-EML_HUPPERTEK | S38: RetourHermes_M | T38: 4618357174 | U38: =VLOOKUP(T38,[5]semitemu_order_export_251110144!$R:$S,2,0) -> PO-076-20612291739513460 | W38: 23843 | X38: Bad Oldesloe | Y38: DE | AC38: ABM0009-251011-0001 | AD38: B07Q3SQT6C | AE38: 金属储物柜71英寸高 | AF38: 188x49x14 | AG38: 47.4 | AI38: 1 | AJ38: =AI38*AG38 -> 47.4 | AK38: =AI38 -> 1 | AL38: 4.85 | AM38: =AL38*AK38 -> 4.85 | AP38: =AO38*AN38 -> 0 | AS38: =AR38*AQ38 -> 0 | AV38: =AU38*AT38 -> 0 | AW38: =O38 -> 1 | AX38: 3 | AY38: =AX38*AW38 -> 3 | AZ38: =AM38+AP38+AS38+AV38+AY38 -> 7.85 | BA38: 1 | BB38: =AJ38 -> 47.4 | BD38: 50 | BE38: =W38 -> 23843 | BF38: =X38 -> Bad Oldesloe | BG38: =Y38 -> DE | BH38: 46.558575 | BI38: =BH38 -> 46.558575 | BJ38: 2.5 | BK38: =0.024*BD38 -> 1.2 | BL38: 2.5 | BN38: =SUM(BJ38:BM38) -> 6.2 | BQ38: =BO38*BP38 -> 0 | BR38: =BI38+BN38+BQ38 -> 52.758575 | BS38: =AZ38+BR38 -> 60.608575
A39: ABM0009-251014-0002 | B39: =COUNTIF(A:A,A39) -> 1 | C39: 1 | E39: M | F39: 202510 | G39: 2025-10-14 | H39: 2025-10-14 | I39: Delivered | J39: YCD-EX:HUPPER TEK | K39: ABM0009-251014-0002 | L39: B2C | N39: qianhui.xu@miclogistik.de | O39: 1 | P39: NORMAL | Q39: 47.4 | R39: GELF-EML_HUPPERTEK | S39: RetourHermes_M | T39: 4618363328 | U39: =VLOOKUP(T39,[5]semitemu_order_export_251110144!$R:$S,2,0) -> PO-076-06372173758071587 | W39: 73079 | X39: Süßen | Y39: DE | AC39: ABM0009-251014-0002 | AD39: B07Q3SQT6C | AE39: 金属储物柜71英寸高 | AF39: 188x49x14 | AG39: 47.4 | AI39: 1 | AJ39: =AI39*AG39 -> 47.4 | AK39: =AI39 -> 1 | AL39: 4.85 | AM39: =AL39*AK39 -> 4.85 | AP39: =AO39*AN39 -> 0 | AS39: =AR39*AQ39 -> 0 | AV39: =AU39*AT39 -> 0 | AW39: =O39 -> 1 | AX39: 3 | AY39: =AX39*AW39 -> 3 | AZ39: =AM39+AP39+AS39+AV39+AY39 -> 7.85 | BA39: 1 | BB39: =AJ39 -> 47.4 | BD39: 50 | BE39: =W39 -> 73079 | BF39: =X39 -> Süßen | BG39: =Y39 -> DE | BH39: 46.558575 | BI39: =BH39 -> 46.558575 | BJ39: 2.5 | BK39: =0.024*BD39 -> 1.2 | BL39: 2.5 | BN39: =SUM(BJ39:BM39) -> 6.2 | BQ39: =BO39*BP39 -> 0 | BR39: =BI39+BN39+BQ39 -> 52.758575 | BS39: =AZ39+BR39 -> 60.608575
A40: ABM0009-251014-0001 | B40: =COUNTIF(A:A,A40) -> 1 | C40: 1 | E40: M | F40: 202510 | G40: 2025-10-14 | H40: 2025-10-14 | I40: Delivered | J40: YCD-EX:HUPPER TEK | K40: ABM0009-251014-0001 | L40: B2C | N40: qianhui.xu@miclogistik.de | O40: 1 | P40: NORMAL | Q40: 47.4 | R40: GELF-EML_HUPPERTEK | S40: RetourHermes_M | T40: 4618363311 | U40: =VLOOKUP(T40,[5]semitemu_order_export_251110144!$R:$S,2,0) -> PO-076-06750099461753911 | W40: 78054 | X40: Villingen-Schwenningen | Y40: DE | AC40: ABM0009-251014-0001 | AD40: B076THQBHX | AE40: 金属储物柜71英寸灰色 | AF40: 188x49x14 | AG40: 47.4 | AI40: 1 | AJ40: =AI40*AG40 -> 47.4 | AK40: =AI40 -> 1 | AL40: 4.85 | AM40: =AL40*AK40 -> 4.85 | AP40: =AO40*AN40 -> 0 | AS40: =AR40*AQ40 -> 0 | AV40: =AU40*AT40 -> 0 | AW40: =O40 -> 1 | AX40: 3 | AY40: =AX40*AW40 -> 3 | AZ40: =AM40+AP40+AS40+AV40+AY40 -> 7.85 | BA40: 1 | BB40: =AJ40 -> 47.4 | BD40: 50 | BE40: =W40 -> 78054 | BF40: =X40 -> Villingen-Schwenningen | BG40: =Y40 -> DE | BH40: 46.558575 | BI40: =BH40 -> 46.558575 | BJ40: 2.5 | BK40: =0.024*BD40 -> 1.2 | BL40: 2.5 | BN40: =SUM(BJ40:BM40) -> 6.2 | BQ40: =BO40*BP40 -> 0 | BR40: =BI40+BN40+BQ40 -> 52.758575 | BS40: =AZ40+BR40 -> 60.608575
A41: ABM0009-251017-0002 | B41: =COUNTIF(A:A,A41) -> 1 | C41: 1 | E41: M | F41: 202510 | G41: 2025-10-17 | H41: 2025-10-17 | I41: Delivered | J41: YCD-EX:HUPPER TEK | K41: ABM0009-251017-0002 | L41: B2C | N41: qianhui.xu@miclogistik.de | O41: 1 | P41: NORMAL | Q41: 47.4 | R41: GELF-EML_HUPPERTEK | S41: RetourHermes_M | T41: 4618375932 | U41: =VLOOKUP(T41,[5]semitemu_order_export_251110144!$R:$S,2,0) -> PO-076-16156623279992626 | W41: 72766 | X41: Reutlingen | Y41: DE | AC41: ABM0009-251017-0002 | AD41: B07Q3SQT6C | AE41: 金属储物柜71英寸高 | AF41: 188x49x14 | AG41: 47.4 | AI41: 1 | AJ41: =AI41*AG41 -> 47.4 | AK41: =AI41 -> 1 | AL41: 4.85 | AM41: =AL41*AK41 -> 4.85 | AP41: =AO41*AN41 -> 0 | AS41: =AR41*AQ41 -> 0 | AV41: =AU41*AT41 -> 0 | AW41: =O41 -> 1 | AX41: 3 | AY41: =AX41*AW41 -> 3 | AZ41: =AM41+AP41+AS41+AV41+AY41 -> 7.85 | BA41: 1 | BB41: =AJ41 -> 47.4 | BD41: 50 | BE41: =W41 -> 72766 | BF41: =X41 -> Reutlingen | BG41: =Y41 -> DE | BH41: 46.558575 | BI41: =BH41 -> 46.558575 | BJ41: 2.5 | BK41: =0.024*BD41 -> 1.2 | BL41: 2.5 | BN41: =SUM(BJ41:BM41) -> 6.2 | BQ41: =BO41*BP41 -> 0 | BR41: =BI41+BN41+BQ41 -> 52.758575 | BS41: =AZ41+BR41 -> 60.608575
A42: ABM0009-251017-0001 | B42: =COUNTIF(A:A,A42) -> 1 | C42: 1 | E42: M | F42: 202510 | G42: 2025-10-17 | H42: 2025-10-17 | I42: Delivered | J42: YCD-EX:HUPPER TEK | K42: ABM0009-251017-0001 | L42: B2C | N42: qianhui.xu@miclogistik.de | O42: 1 | P42: NORMAL | Q42: 47.4 | R42: GELF-EML_HUPPERTEK | S42: RetourHermes_M | T42: 4618375925 | U42: =VLOOKUP(T42,[6]ebay_order_export_251110145132!$S:$T,2,0) -> 20-13696-61877 | W42: 27777 | X42: Ganderkesee | Y42: DE | AC42: ABM0009-251017-0001 | AD42: B07BK8W5MF | AE42: 金属储物柜71英寸银色 | AF42: 188x49x14 | AG42: 47.4 | AI42: 1 | AJ42: =AI42*AG42 -> 47.4 | AK42: =AI42 -> 1 | AL42: 4.85 | AM42: =AL42*AK42 -> 4.85 | AP42: =AO42*AN42 -> 0 | AS42: =AR42*AQ42 -> 0 | AV42: =AU42*AT42 -> 0 | AW42: =O42 -> 1 | AX42: 3 | AY42: =AX42*AW42 -> 3 | AZ42: =AM42+AP42+AS42+AV42+AY42 -> 7.85 | BA42: 1 | BB42: =AJ42 -> 47.4 | BD42: 50 | BE42: =W42 -> 27777 | BF42: =X42 -> Ganderkesee | BG42: =Y42 -> DE | BH42: 46.558575 | BI42: =BH42 -> 46.558575 | BJ42: 2.5 | BK42: =0.024*BD42 -> 1.2 | BL42: 2.5 | BN42: =SUM(BJ42:BM42) -> 6.2 | BQ42: =BO42*BP42 -> 0 | BR42: =BI42+BN42+BQ42 -> 52.758575 | BS42: =AZ42+BR42 -> 60.608575
A43: ABM0009-251020-0009 | B43: =COUNTIF(A:A,A43) -> 1 | C43: 1 | E43: M | F43: 202510 | G43: 2025-10-20 | H43: 2025-10-20 | I43: Delivered | J43: YCD-EX:HUPPER TEK | K43: ABM0009-251020-0009 | L43: B2C | N43: qianhui.xu@miclogistik.de | O43: 1 | P43: NORMAL | Q43: 47.4 | R43: GELF-EML_HUPPERTEK | S43: RetourHermes_M | T43: 4618385870 | U43: =VLOOKUP(T43,[5]semitemu_order_export_251110144!$R:$S,2,0) -> PO-076-21635569651831488 | W43: 21502 | X43: Geesthacht | Y43: DE | AC43: ABM0009-251020-0009 | AD43: B07BK8W5MF | AE43: 金属储物柜71英寸银色 | AF43: 188x49x14 | AG43: 47.4 | AI43: 1 | AJ43: =AI43*AG43 -> 47.4 | AK43: =AI43 -> 1 | AL43: 4.85 | AM43: =AL43*AK43 -> 4.85 | AP43: =AO43*AN43 -> 0 | AS43: =AR43*AQ43 -> 0 | AV43: =AU43*AT43 -> 0 | AW43: =O43 -> 1 | AX43: 3 | AY43: =AX43*AW43 -> 3 | AZ43: =AM43+AP43+AS43+AV43+AY43 -> 7.85 | BA43: 1 | BB43: =AJ43 -> 47.4 | BD43: 50 | BE43: =W43 -> 21502 | BF43: =X43 -> Geesthacht | BG43: =Y43 -> DE | BH43: 46.558575 | BI43: =BH43 -> 46.558575 | BJ43: 2.5 | BK43: =0.024*BD43 -> 1.2 | BL43: 2.5 | BN43: =SUM(BJ43:BM43) -> 6.2 | BQ43: =BO43*BP43 -> 0 | BR43: =BI43+BN43+BQ43 -> 52.758575 | BS43: =AZ43+BR43 -> 60.608575
A44: ABM0009-251020-0008 | B44: =COUNTIF(A:A,A44) -> 1 | C44: 1 | E44: M | F44: 202510 | G44: 2025-10-20 | H44: 2025-10-20 | I44: Delivered | J44: YCD-EX:HUPPER TEK | K44: ABM0009-251020-0008 | L44: B2C | N44: qianhui.xu@miclogistik.de | O44: 1 | P44: NORMAL | Q44: 47.4 | R44: GELF-EML_HUPPERTEK | S44: RetourHermes_M | T44: 4618385863 | U44: =VLOOKUP(T44,[5]semitemu_order_export_251110144!$R:$S,2,0) -> PO-076-21635569651831488 | W44: 21502 | X44: Geesthacht | Y44: DE | AC44: ABM0009-251020-0008 | AD44: B07BK8W5MF | AE44: 金属储物柜71英寸银色 | AF44: 188x49x14 | AG44: 47.4 | AI44: 1 | AJ44: =AI44*AG44 -> 47.4 | AK44: =AI44 -> 1 | AL44: 4.85 | AM44: =AL44*AK44 -> 4.85 | AP44: =AO44*AN44 -> 0 | AS44: =AR44*AQ44 -> 0 | AV44: =AU44*AT44 -> 0 | AW44: =O44 -> 1 | AX44: 3 | AY44: =AX44*AW44 -> 3 | AZ44: =AM44+AP44+AS44+AV44+AY44 -> 7.85 | BA44: 1 | BB44: =AJ44 -> 47.4 | BD44: 50 | BE44: =W44 -> 21502 | BF44: =X44 -> Geesthacht | BG44: =Y44 -> DE | BH44: 46.558575 | BI44: =BH44 -> 46.558575 | BJ44: 2.5 | BK44: =0.024*BD44 -> 1.2 | BL44: 2.5 | BN44: =SUM(BJ44:BM44) -> 6.2 | BQ44: =BO44*BP44 -> 0 | BR44: =BI44+BN44+BQ44 -> 52.758575 | BS44: =AZ44+BR44 -> 60.608575
A45: ABM0009-251020-0007 | B45: =COUNTIF(A:A,A45) -> 1 | C45: 1 | E45: M | F45: 202510 | G45: 2025-10-20 | H45: 2025-10-20 | I45: Delivered | J45: YCD-EX:HUPPER TEK | K45: ABM0009-251020-0007 | L45: B2C | N45: qianhui.xu@miclogistik.de | O45: 1 | P45: NORMAL | Q45: 47.4 | R45: GELF-EML_HUPPERTEK | S45: RetourHermes_M | T45: 4618385856 | U45: =VLOOKUP(T45,[5]semitemu_order_export_251110144!$R:$S,2,0) -> PO-076-02633160077433872 | W45: 84092 | X45: Bayerbach b. Ergoldsbach | Y45: DE | AC45: ABM0009-251020-0007 | AD45: B07BK8W5MF | AE45: 金属储物柜71英寸银色 | AF45: 188x49x14 | AG45: 47.4 | AI45: 1 | AJ45: =AI45*AG45 -> 47.4 | AK45: =AI45 -> 1 | AL45: 4.85 | AM45: =AL45*AK45 -> 4.85 | AP45: =AO45*AN45 -> 0 | AS45: =AR45*AQ45 -> 0 | AV45: =AU45*AT45 -> 0 | AW45: =O45 -> 1 | AX45: 3 | AY45: =AX45*AW45 -> 3 | AZ45: =AM45+AP45+AS45+AV45+AY45 -> 7.85 | BA45: 1 | BB45: =AJ45 -> 47.4 | BD45: 50 | BE45: =W45 -> 84092 | BF45: =X45 -> Bayerbach b. Ergoldsbach | BG45: =Y45 -> DE | BH45: 46.558575 | BI45: =BH45 -> 46.558575 | BJ45: 2.5 | BK45: =0.024*BD45 -> 1.2 | BL45: 2.5 | BN45: =SUM(BJ45:BM45) -> 6.2 | BQ45: =BO45*BP45 -> 0 | BR45: =BI45+BN45+BQ45 -> 52.758575 | BS45: =AZ45+BR45 -> 60.608575
A46: ABM0009-251020-0006 | B46: =COUNTIF(A:A,A46) -> 1 | C46: 1 | E46: M | F46: 202510 | G46: 2025-10-20 | H46: 2025-10-20 | I46: Delivered | J46: YCD-EX:HUPPER TEK | K46: ABM0009-251020-0006 | L46: B2C | N46: qianhui.xu@miclogistik.de | O46: 1 | P46: NORMAL | Q46: 47.4 | R46: GELF-EML_HUPPERTEK | S46: RetourHermes_M | T46: 4618385849 | U46: =VLOOKUP(T46,[5]semitemu_order_export_251110144!$R:$S,2,0) -> PO-076-02633160077433872 | W46: 84092 | X46: Bayerbach b. Ergoldsbach | Y46: DE | AC46: ABM0009-251020-0006 | AD46: B07BK8W5MF | AE46: 金属储物柜71英寸银色 | AF46: 188x49x14 | AG46: 47.4 | AI46: 1 | AJ46: =AI46*AG46 -> 47.4 | AK46: =AI46 -> 1 | AL46: 4.85 | AM46: =AL46*AK46 -> 4.85 | AP46: =AO46*AN46 -> 0 | AS46: =AR46*AQ46 -> 0 | AV46: =AU46*AT46 -> 0 | AW46: =O46 -> 1 | AX46: 3 | AY46: =AX46*AW46 -> 3 | AZ46: =AM46+AP46+AS46+AV46+AY46 -> 7.85 | BA46: 1 | BB46: =AJ46 -> 47.4 | BD46: 50 | BE46: =W46 -> 84092 | BF46: =X46 -> Bayerbach b. Ergoldsbach | BG46: =Y46 -> DE | BH46: 46.558575 | BI46: =BH46 -> 46.558575 | BJ46: 2.5 | BK46: =0.024*BD46 -> 1.2 | BL46: 2.5 | BN46: =SUM(BJ46:BM46) -> 6.2 | BQ46: =BO46*BP46 -> 0 | BR46: =BI46+BN46+BQ46 -> 52.758575 | BS46: =AZ46+BR46 -> 60.608575
A47: ABM0009-251020-0005 | B47: =COUNTIF(A:A,A47) -> 1 | C47: 1 | E47: M | F47: 202510 | G47: 2025-10-20 | H47: 2025-10-20 | I47: Delivered | J47: YCD-EX:HUPPER TEK | K47: ABM0009-251020-0005 | L47: B2C | N47: qianhui.xu@miclogistik.de | O47: 1 | P47: NORMAL | Q47: 47.4 | R47: GELF-EML_HUPPERTEK | S47: RetourHermes_M | T47: 4618385832 | U47: =VLOOKUP(T47,[5]semitemu_order_export_251110144!$R:$S,2,0) -> PO-076-10937699783033271 | W47: 81245 | X47: München | Y47: DE | AC47: ABM0009-251020-0005 | AD47: B07BK8W5MF | AE47: 金属储物柜71英寸银色 | AF47: 188x49x14 | AG47: 47.4 | AI47: 1 | AJ47: =AI47*AG47 -> 47.4 | AK47: =AI47 -> 1 | AL47: 4.85 | AM47: =AL47*AK47 -> 4.85 | AP47: =AO47*AN47 -> 0 | AS47: =AR47*AQ47 -> 0 | AV47: =AU47*AT47 -> 0 | AW47: =O47 -> 1 | AX47: 3 | AY47: =AX47*AW47 -> 3 | AZ47: =AM47+AP47+AS47+AV47+AY47 -> 7.85 | BA47: 1 | BB47: =AJ47 -> 47.4 | BD47: 50 | BE47: =W47 -> 81245 | BF47: =X47 -> München | BG47: =Y47 -> DE | BH47: 46.558575 | BI47: =BH47 -> 46.558575 | BJ47: 2.5 | BK47: =0.024*BD47 -> 1.2 | BL47: 2.5 | BM47: 7.8 | BN47: =SUM(BJ47:BM47) -> 14 | BQ47: =BO47*BP47 -> 0 | BR47: =BI47+BN47+BQ47 -> 60.558575 | BS47: =AZ47+BR47 -> 68.408575
...

Sheet 2.3 正向-2C-DHL
A1: MIC德国海外仓一件代发明细表 | AM1: =SUM(AM5:AM10) -> 4.8 | AP1: =SUM(AP5:AP10) -> 0 | AS1: =SUM(AS5:AS10) -> 0 | AV1: =SUM(AV5:AV10) -> 0 | AZ1: =SUM(AZ5:AZ10) -> 4.8 | BF1: =SUM(BF5:BF10) -> 33.14115 | BJ1: =SUM(BJ5:BJ10) -> 123.06851 | BK1: =SUM(BK5:BK10) -> 156.20966 | BL1: =SUM(BL5:BL10) -> 161.00966
A2: ,1m, | BA2: 尾程运输费 | BL2: 总费用合计
A3: 出库指令 | AD3: 物品-拣料及最小包装 | AK3: 拣货费 | AN3: 拣货续件费 | AQ3: 贴标费 | AT3: 包材费-包裹 | AW3: 打包费-包裹 | AZ3: 库内小计 | BA3: 基础费 | BK3: 尾程费用合计
A4: Order No. | B4: 订单 行数 | C4: 订单数 | D4: 对账 | E4: Warehouse | F4: 月份 | G4: Order Created At | H4: Shipped At | I4: Status | J4: Customer | K4: Original Reference | L4: Business Type | M4: Channel | N4: Creator | O4: 运单数 | P4: Priority | Q4: weight | R4: Carrier | S4: Carrier Return | T4: Shipments No1 | U4: Shipments No2 | V4: Retour No | W4: Postal Code | X4: 城市 | Y4: Country | Z4: sndZip | AA4: sndCity | AB4: sndCountry | AC4: RefOnLabel | AD4: Item ID | AE4: 物品描述 | AF4: 物品尺寸 长宽高cm | AG4: 单个物品 重量kg | AH4: Item Batch | AI4: Item Qty | AJ4: 订单重量 kg | AK4: 数量 套 | AL4: 单价 Euro | AM4: 金额 Euro | AN4: 数量 pcs | AO4: 单价 Euro | AP4: 金额 Euro | AQ4: 标签/张 | AR4: 单价 | AS4: 金额 | AT4: 数量 pcs | AU4: 单价 Euro | AV4: 金额 Euro | AW4: 数量 pcs | AX4: 单价 Euro | AY4: 金额 Euro | BA4: 数量 /包裹 | BB4: 实际重kg | BC4: 计费 重量 kg | BD4: 国家 | BE4: 单价 Euro | BF4: 金额 Euro | BG4: 燃油&路桥费 | BH4: 其它 | BI4: 能源附加费 | BJ4: 附加费小计
A5: ABM0009-251031-0009 | B5: =COUNTIF(A:A,A5) -> 1 | C5: 1 | E5: M | F5: 202510 | G5: 2025-10-31 | H5: 2025-10-31 | I5: Shipped | J5: YCD-EX:HUPPER TEK | K5: ABM0009-251031-0009 | L5: B2C | N5: klee.cao@miclogistik.de | O5: 1 | P5: NORMAL | Q5: 14 | R5: DHL_M2CEU_M | S5: RetourHermes_M | T5: 00340434789991020630 | U5: ST-PO-076-04282019543672524 | W5: 23556 | X5: Lübeck | Y5: DE | AC5: ABM0009-251031-0009 | AD5: B07GSF11XX | AE5: =VLOOKUP(AD5,物品明细!A:B,2,0) -> 白板 | AF5: =VLOOKUP(AD5,物品明细!A:I,9,0) -> 133x87x8 | AG5: =VLOOKUP(AD5,物品明细!A:D,4,0) -> 14 | AI5: 1 | AJ5: =AI5*AG5 -> 14 | AK5: =AI5 -> 1 | AL5: 0.8 | AM5: =AL5*AK5 -> 0.8 | AP5: =AO5*AN5 -> 0 | AS5: =AR5*AQ5 -> 0 | AV5: =AU5*AT5 -> 0 | AY5: =AX5*AW5 -> 0 | AZ5: =AM5+AP5+AS5+AV5+AY5 -> 0.8 | BA5: 1 | BB5: =AJ5 -> 14 | BC5: 15 | BD5: =Y5 -> DE | BE5: 5.523525 | BF5: =BA5*BE5 -> 5.523525 | BG5: =BA5*0.19 -> 0.19 | BH5: =BA5*20 -> 20 | BI5: =(BH5+BG5+BF5)*1.25% -> 0.32141906 | BJ5: =SUM(BG5:BI5) -> 20.511419 | BK5: =BF5+BJ5 -> 26.034944 | BL5: =AZ5+BK5 -> 26.834944
A6: ABM0009-251031-0008 | B6: =COUNTIF(A:A,A6) -> 1 | C6: 1 | E6: M | F6: 202510 | G6: 2025-10-31 | H6: 2025-10-31 | I6: Shipped | J6: YCD-EX:HUPPER TEK | K6: ABM0009-251031-0008 | L6: B2C | N6: klee.cao@miclogistik.de | O6: 1 | P6: NORMAL | Q6: 14 | R6: DHL_M2CEU_M | S6: RetourHermes_M | T6: 00340434789991020623 | U6: =VLOOKUP(T6,[5]semitemu_order_export_251110144!$R:$S,2,0) -> PO-076-11313748040313333 | W6: 97846 | X6: Partenstein | Y6: DE | AC6: ABM0009-251031-0008 | AD6: B07GSF11XX | AE6: =VLOOKUP(AD6,物品明细!A:B,2,0) -> 白板 | AF6: =VLOOKUP(AD6,物品明细!A:I,9,0) -> 133x87x8 | AG6: =VLOOKUP(AD6,物品明细!A:D,4,0) -> 14 | AI6: 1 | AJ6: =AI6*AG6 -> 14 | AK6: =AI6 -> 1 | AL6: 0.8 | AM6: =AL6*AK6 -> 0.8 | AP6: =AO6*AN6 -> 0 | AS6: =AR6*AQ6 -> 0 | AV6: =AU6*AT6 -> 0 | AY6: =AX6*AW6 -> 0 | AZ6: =AM6+AP6+AS6+AV6+AY6 -> 0.8 | BA6: 1 | BB6: =AJ6 -> 14 | BC6: 15 | BD6: =Y6 -> DE | BE6: 5.523525 | BF6: =BA6*BE6 -> 5.523525 | BG6: =BA6*0.19 -> 0.19 | BH6: =BA6*20 -> 20 | BI6: =(BH6+BG6+BF6)*1.25% -> 0.32141906 | BJ6: =SUM(BG6:BI6) -> 20.511419 | BK6: =BF6+BJ6 -> 26.034944 | BL6: =AZ6+BK6 -> 26.834944
A7: ABM0009-251031-0007 | B7: =COUNTIF(A:A,A7) -> 1 | C7: 1 | E7: M | F7: 202510 | G7: 2025-10-31 | H7: 2025-10-31 | I7: Shipped | J7: YCD-EX:HUPPER TEK | K7: ABM0009-251031-0007 | L7: B2C | N7: klee.cao@miclogistik.de | O7: 1 | P7: NORMAL | Q7: 14 | R7: DHL_M2CEU_M | S7: RetourHermes_M | T7: 00340434789991020616 | U7: =VLOOKUP(T7,[5]semitemu_order_export_251110144!$R:$S,2,0) -> PO-076-11441826061430008 | W7: 1762 | X7: Hartmannsdorf-Reichenau | Y7: DE | AC7: ABM0009-251031-0007 | AD7: B07GSF11XX | AE7: =VLOOKUP(AD7,物品明细!A:B,2,0) -> 白板 | AF7: =VLOOKUP(AD7,物品明细!A:I,9,0) -> 133x87x8 | AG7: =VLOOKUP(AD7,物品明细!A:D,4,0) -> 14 | AI7: 1 | AJ7: =AI7*AG7 -> 14 | AK7: =AI7 -> 1 | AL7: 0.8 | AM7: =AL7*AK7 -> 0.8 | AP7: =AO7*AN7 -> 0 | AS7: =AR7*AQ7 -> 0 | AV7: =AU7*AT7 -> 0 | AY7: =AX7*AW7 -> 0 | AZ7: =AM7+AP7+AS7+AV7+AY7 -> 0.8 | BA7: 1 | BB7: =AJ7 -> 14 | BC7: 15 | BD7: =Y7 -> DE | BE7: 5.523525 | BF7: =BA7*BE7 -> 5.523525 | BG7: =BA7*0.19 -> 0.19 | BH7: =BA7*20 -> 20 | BI7: =(BH7+BG7+BF7)*1.25% -> 0.32141906 | BJ7: =SUM(BG7:BI7) -> 20.511419 | BK7: =BF7+BJ7 -> 26.034944 | BL7: =AZ7+BK7 -> 26.834944
A8: ABM0009-251031-0006 | B8: =COUNTIF(A:A,A8) -> 1 | C8: 1 | E8: M | F8: 202510 | G8: 2025-10-31 | H8: 2025-10-31 | I8: Shipped | J8: YCD-EX:HUPPER TEK | K8: ABM0009-251031-0006 | L8: B2C | N8: klee.cao@miclogistik.de | O8: 1 | P8: NORMAL | Q8: 14 | R8: DHL_M2CEU_M | S8: RetourHermes_M | T8: 00340434789991020609 | U8: =VLOOKUP(T8,[5]semitemu_order_export_251110144!$R:$S,2,0) -> PO-076-05547350851192886 | W8: 2977 | X8: Hoyerswerda | Y8: DE | AC8: ABM0009-251031-0006 | AD8: B07GSF11XX | AE8: =VLOOKUP(AD8,物品明细!A:B,2,0) -> 白板 | AF8: =VLOOKUP(AD8,物品明细!A:I,9,0) -> 133x87x8 | AG8: =VLOOKUP(AD8,物品明细!A:D,4,0) -> 14 | AI8: 1 | AJ8: =AI8*AG8 -> 14 | AK8: =AI8 -> 1 | AL8: 0.8 | AM8: =AL8*AK8 -> 0.8 | AP8: =AO8*AN8 -> 0 | AS8: =AR8*AQ8 -> 0 | AV8: =AU8*AT8 -> 0 | AY8: =AX8*AW8 -> 0 | AZ8: =AM8+AP8+AS8+AV8+AY8 -> 0.8 | BA8: 1 | BB8: =AJ8 -> 14 | BC8: 15 | BD8: =Y8 -> DE | BE8: 5.523525 | BF8: =BA8*BE8 -> 5.523525 | BG8: =BA8*0.19 -> 0.19 | BH8: =BA8*20 -> 20 | BI8: =(BH8+BG8+BF8)*1.25% -> 0.32141906 | BJ8: =SUM(BG8:BI8) -> 20.511419 | BK8: =BF8+BJ8 -> 26.034944 | BL8: =AZ8+BK8 -> 26.834944
A9: ABM0009-251031-0005 | B9: =COUNTIF(A:A,A9) -> 1 | C9: 1 | E9: M | F9: 202510 | G9: 2025-10-31 | H9: 2025-10-31 | I9: Shipped | J9: YCD-EX:HUPPER TEK | K9: ABM0009-251031-0005 | L9: B2C | N9: klee.cao@miclogistik.de | O9: 1 | P9: NORMAL | Q9: 14 | R9: DHL_M2CEU_M | S9: RetourHermes_M | T9: 00340434789991020593 | U9: =VLOOKUP(T9,[5]semitemu_order_export_251110144!$R:$S,2,0) -> PO-076-16606314678392251 | W9: 73230 | X9: Kirchheim unter Teck | Y9: DE | AC9: ABM0009-251031-0005 | AD9: B07GSF11XX | AE9: =VLOOKUP(AD9,物品明细!A:B,2,0) -> 白板 | AF9: =VLOOKUP(AD9,物品明细!A:I,9,0) -> 133x87x8 | AG9: =VLOOKUP(AD9,物品明细!A:D,4,0) -> 14 | AI9: 1 | AJ9: =AI9*AG9 -> 14 | AK9: =AI9 -> 1 | AL9: 0.8 | AM9: =AL9*AK9 -> 0.8 | AP9: =AO9*AN9 -> 0 | AS9: =AR9*AQ9 -> 0 | AV9: =AU9*AT9 -> 0 | AY9: =AX9*AW9 -> 0 | AZ9: =AM9+AP9+AS9+AV9+AY9 -> 0.8 | BA9: 1 | BB9: =AJ9 -> 14 | BC9: 15 | BD9: =Y9 -> DE | BE9: 5.523525 | BF9: =BA9*BE9 -> 5.523525 | BG9: =BA9*0.19 -> 0.19 | BH9: =BA9*20 -> 20 | BI9: =(BH9+BG9+BF9)*1.25% -> 0.32141906 | BJ9: =SUM(BG9:BI9) -> 20.511419 | BK9: =BF9+BJ9 -> 26.034944 | BL9: =AZ9+BK9 -> 26.834944
A10: ABM0009-251031-0004 | B10: =COUNTIF(A:A,A10) -> 1 | C10: 1 | E10: M | F10: 202510 | G10: 2025-10-31 | H10: 2025-10-31 | I10: Shipped | J10: YCD-EX:HUPPER TEK | K10: ABM0009-251031-0004 | L10: B2C | N10: klee.cao@miclogistik.de | O10: 1 | P10: NORMAL | Q10: 14 | R10: DHL_M2CEU_M | S10: RetourHermes_M | T10: 00340434789991020586 | U10: =VLOOKUP(T10,[5]semitemu_order_export_251110144!$R:$S,2,0) -> PO-076-19667027295350902 | W10: 14770 | X10: Brandenburg an der Havel | Y10: DE | AC10: ABM0009-251031-0004 | AD10: B07GSF11XX | AE10: =VLOOKUP(AD10,物品明细!A:B,2,0) -> 白板 | AF10: =VLOOKUP(AD10,物品明细!A:I,9,0) -> 133x87x8 | AG10: =VLOOKUP(AD10,物品明细!A:D,4,0) -> 14 | AI10: 1 | AJ10: =AI10*AG10 -> 14 | AK10: =AI10 -> 1 | AL10: 0.8 | AM10: =AL10*AK10 -> 0.8 | AP10: =AO10*AN10 -> 0 | AS10: =AR10*AQ10 -> 0 | AV10: =AU10*AT10 -> 0 | AY10: =AX10*AW10 -> 0 | AZ10: =AM10+AP10+AS10+AV10+AY10 -> 0.8 | BA10: 1 | BB10: =AJ10 -> 14 | BC10: 15 | BD10: =Y10 -> DE | BE10: 5.523525 | BF10: =BA10*BE10 -> 5.523525 | BG10: =BA10*0.19 -> 0.19 | BH10: =BA10*20 -> 20 | BI10: =(BH10+BG10+BF10)*1.25% -> 0.32141906 | BJ10: =SUM(BG10:BI10) -> 20.511419 | BK10: =BF10+BJ10 -> 26.034944 | BL10: =AZ10+BK10 -> 26.834944

Sheet 2.4 正向-2C-PlanB 
A1: MIC德国海外仓一件代发明细表 | AY1: =SUM(AY5:AY6) -> 264 | BD1: =SUM(BD5:BD6) -> 0 | BG1: =SUM(BG5:BG6) -> 0 | BH1: =SUM(BH5:BH6) -> 264
A2: ,1m, | AQ2: 尾程运输费
A3: 出库指令 | AD3: 物品-拣料及最小包装 | AQ3: 基础费 | AZ3: 附加费 | BE3: 3件包裹以上运输续件费 | BH3: 尾程费用合计
A4: Order No. | B4: 订单 行数 | C4: 订单数 | D4: 对账 | E4: Warehouse | F4: 月份 | G4: Order Created At | H4: Shipped At | I4: Status | J4: Customer | K4: Original Reference | L4: Business Type | M4: Channel | N4: Creator | O4: 运单数 | P4: Priority | Q4: weight | R4: Carrier | S4: Carrier Return | T4: Shipments No1 | U4: Shipments No2 | V4: Retour No | W4: Postal Code | X4: 城市 | Y4: Country | Z4: sndZip | AA4: sndCity | AB4: sndCountry | AC4: RefOnLabel | AD4: Item ID | AE4: 物品描述 | AF4: 物品尺寸 长宽高cm | AG4: 单个物品 重量kg | AH4: Item Batch | AI4: Item Qty | AJ4: 托盘数量 | AK4: 打托规格 | AL4: 单托重 | AP4: 订单重量 kg | AQ4: 数量 票 | AR4: 实际重kg | AS4: 体积重KG | AT4: 计费 重量 kg | AU4: 邮编所属区域 | AV4: 城市 | AW4: 国家 | AX4: 单价 Euro | AY4: 金额 Euro | AZ4: 运输 订单 管理 * | BA4: 过路 过桥 * | BB4: 预约 通知 * | BC4: 其它 | BD4: 附加费小计 | BE4: 包裹数 个 | BF4: 单价 Euro | BG4: 金额 Euro
A5: MO202510240161 | B5: =COUNTIF(A:A,A5) -> 2 | C5: 1 | F5: 202510 | G5: 2025-10-24 | H5: 0001-01-01 | I5: FinWithoutOutbound | J5: YCD-EX:HUPPER TEK | L5: Transport | N5: vicky.peng@miclogistik.de | O5: 5 | P5: NORMAL | Q5: 290 | R5: PlanB | W5: 40670 | X5: Meerbusch | Y5: DE | Z5: 47533 | AA5: Kleve | AB5: DE | AC5: MO202510240161 | AJ5: 2 | AK5: 132.5X87X210 | AL5: 298.4 | AM5: 0 | AO5: 0 | AP5: =AL5*AJ5 -> 596.8 | AQ5: 1 | AR5: =AP5 -> 596.8 | AT5: 50 | AU5: =W5 -> 40670 | AV5: =X5 -> Meerbusch | AW5: =Y5 -> DE | AX5: 264 | AY5: =AQ5*AX5 -> 264 | BH5: =AY5+BD5+BG5 -> 264
A6: MO202510240161 | B6: =COUNTIF(A:A,A6) -> 2 | C6: 0 | F6: 202510 | G6: 2025-10-24 | H6: 0001-01-01 | I6: FinWithoutOutbound | J6: YCD-EX:HUPPER TEK | L6: Transport | N6: vicky.peng@miclogistik.de | O6: 5 | P6: NORMAL | Q6: 290 | R6: PlanB | W6: 40670 | X6: Meerbusch | Y6: DE | Z6: 47533 | AA6: Kleve | AB6: DE | AC6: MO202510240161 | AJ6: 3 | AK6: 132.5X87X210 | AL6: 283.1 | AM6: 0 | AO6: 0 | AP6: =AL6*AJ6 -> 849.3 | AQ6: 0 | AR6: =AP6 -> 849.3 | AT6: 50 | AU6: =W6 -> 40670 | AV6: =X6 -> Meerbusch | AW6: =Y6 -> DE | BH6: =AY6+BD6+BG6 -> 0

Sheet 3.1 正向-普货-仓储费 
AP1: =SUM(AP6:AP160) -> 829.10948
A2: 计费时间IStorage Charge Date | C2: 入仓信息Inbound Information | I2: 商品信息Product Information | Q2: 装箱信息 | V2: 打托信息 | AA2: 原始入仓数量 | AE2: 进销存信息 | AJ2: 仓储费计费信息/Storage Charge Infromation | AQ2: 备注
A3: 月份 | B3: 日期 | C3: 仓库名称 | D3: 仓库编码 | E3: 客户代码 | F3: 入库任务号 | G3: 原始参考号 | H3: 入库上架时间 | I3: 编码 | J3: 条码 | K3: 商品名称 | L3: 件型 | M3: 长 | N3: 宽 | O3: 高 | P3: 单品体积A | Q3: 装箱数 | R3: 长 | S3: 宽 | T3: 高 | U3: 单箱体积B | V3: 打托数 | W3: 长 | X3: 宽 | Y3: 高 | Z3: 单托体积C | AA3: 托数 | AB3: 箱数 | AC3: 总数 | AD3: 批次号 | AE3: 期初库存数 | AF3: 入库数 | AG3: 出库数 | AH3: 期末库存数 | AI3: 计费单元 | AJ3: 库存体积E | AK3: 实际计费体积F | AL3: 库龄 | AM3: 库龄段 | AN3: 计费单价 | AO3: 币种 | AP3: 仓储费
