Workbook
Name _dpx2: '[2]DHL City to Zone OB Vol'!$AF$7:$AO$45

Sheet 对账单-汇总页
A1: 应收账款对账单
A2: 客户：深圳市哈贝尔智能科技有限公司
A3: 联系人：
A4: 账单期间：2025.08.01~2025.09.08
A5: 业务场景 | B5: 费用项 | C5: 库内基础费用 A | D5: 运输基础费用 B | E5: 附加费 C | F5: 账单金额合计 A+B+C | G5: 已收金额 | H5: 应收余额（EUR） | I5: 备注
A6: 1. 正向 | B6: 1.1 入库 | C6: ='1.1 正向-入库'!V1 -> 882 | D6: 750 | F6: =C6+D6+E6 -> 1632 | H6: =F6-G6 -> 1632 | I6: 8月移仓入库费用
B7: 1.2 -1 2C订单-GEL | C7: 0 | D7: 0 | E7: 0 | F7: =C7+D7+E7 -> 0 | H7: =F7-G7 -> 0
A8: 2.仓储 | B8: 2.1 仓储费(8月） | C8: ='2.1 正向-普货&大件-仓储费(8月）'!AP1 -> 0 | F8: =C8+D8+E8 -> 0 | H8: =F8-G8 -> 0
F9: =C9+D9+E9 -> 0 | H9: =F9-G9 -> 0
A10: 3. 其他 | F10: =C10+D10+E10 -> 0 | H10: =F10-G10 -> 0
B15: 合计 | C15: =SUM(C6:C13) -> 882 | D15: =SUM(D6:D13) -> 750 | E15: =SUM(E6:E13) -> 0 | F15: =SUM(F6:F13) -> 1632 | G15: =SUM(G6:G13) -> 0 | H15: =SUM(H6:H13) -> 1632
A16: 应收余额负数代表有余额
A17: 感谢贵司选择我司的服务，烦请贵司仔细核对，如有问题请及时与我司业务员联系，核对无误请在右侧签章回传并及时安排付款，付款账号如下： | E17: 客户盖章
A18: 开户名： MIC Logistik GmbH
A19: 开户公司地址：Künkelstraße 43A, 41063 Mönchengladbach,Germany
A20: 银行名称： Volksbank Krefeld eG
A21: 银行地址：Tönisberger Str. 37-39, 47839 Krefeld,Germany
A22: 账号： DE96 3206 0362 4019 1180 08
A23: BIC: GENODED1HTK

Sheet 1.1 正向-入库
A1: MIC德国海外仓到货&收货&入库明细表 | V1: =SUM(V4:V7) -> 882 | W1: =SUM(W4:W7) -> 1632
A2: 退货信息 | S2: 卸货&收货费 | W2: 合计
A3: 任务号 | B3: 入库月份 | C3: Carrier | D3: 收货日期 | E3: 入库状态 | F3: 客户 | G3: 批次号 | H3: 批次号行数 | I3: 批次数 | J3: 类型 | K3: 物品SKU | L3: 物品描述 | M3: 物品 总数 | N3: 货位 | O3: 箱数 | P3: 托盘数 | Q3: Remark | R3: 运输费 | S3: 托盘数 | T3: 箱数 | U3: 单价 | V3: 金额
A4: MI202508130012 | B4: 8月 | C4: Truck | D4: 45889 | E4: Inbound Completed | F4: YCD-EX:HUPPER TEK | G4: DE2508031-G7-MIC | H4: =COUNTIF(G:G,G4) -> 4 | I4: 1 | J4: 大件 | K4: B07BK8W5MF | L4: =VLOOKUP(K4,物品明细!A:B,2,0) -> 金属储物柜71英寸银色 | M4: 247 | N4: M » N2 - 1 | O4: 247 | P4: 21 | R4: 750 | S4: =P4 -> 21 | U4: 14 | V4: =U4*S4 -> 294 | W4: =V4+R4 -> 1044
A5: MI202508130012 | B5: 8月 | C5: Truck | D5: 45889 | E5: Inbound Completed | F5: YCD-EX:HUPPER TEK | G5: DE2508031-G7-MIC | H5: =COUNTIF(G:G,G5) -> 4 | I5: 0 | J5: 大件 | K5: B076THQBHX | L5: =VLOOKUP(K5,物品明细!A:B,2,0) -> 金属储物柜71英寸灰色 | M5: 223 | N5: M » N2 - 1 | O5: 223 | P5: 19 | S5: =P5 -> 19 | U5: 14 | V5: =U5*S5 -> 266 | W5: =V5+R5 -> 266
A6: MI202508130012 | B6: 8月 | C6: Truck | D6: 45889 | E6: Inbound Completed | F6: YCD-EX:HUPPER TEK | G6: DE2508031-G7-MIC | H6: =COUNTIF(G:G,G6) -> 4 | I6: 0 | J6: 大件 | K6: B07Q3SQT6C | L6: =VLOOKUP(K6,物品明细!A:B,2,0) -> 金属储物柜71英寸高 | M6: 151 | N6: M » N2 - 1 | O6: 151 | P6: 13 | S6: =P6 -> 13 | U6: 14 | V6: =U6*S6 -> 182 | W6: =V6+R6 -> 182
A7: MI202508130012 | B7: 8月 | C7: Truck | D7: 45889 | E7: Inbound Completed | F7: YCD-EX:HUPPER TEK | G7: DE2508031-G7-MIC | H7: =COUNTIF(G:G,G7) -> 4 | I7: 0 | J7: 大件 | K7: B077RVYZRF | L7: =VLOOKUP(K7,物品明细!A:B,2,0) -> 德国联邦快递金属储物柜 | M7: 117 | N7: M » N2 - 1 | O7: 117 | P7: 10 | S7: =P7 -> 10 | U7: 14 | V7: =U7*S7 -> 140 | W7: =V7+R7 -> 140

Sheet 1.2-1正向-2C-GEL
A1: MIC德国海外仓一件代发明细表 | AI1: =SUM(#REF!) -> #REF! | AL1: =SUM(#REF!) -> #REF! | AO1: =SUM(#REF!) -> #REF! | AR1: =SUM(#REF!) -> #REF! | AU1: =SUM(#REF!) -> #REF! | AX1: =SUM(#REF!) -> #REF! | AY1: =SUM(#REF!) -> #REF! | BH1: =SUM(#REF!) -> #REF! | BJ1: =SUM(#REF!) -> #REF! | BQ1: =SUM(#REF!) -> #REF! | BT1: =SUM(#REF!) -> #REF! | BU1: =SUM(#REF!) -> #REF! | BV1: =SUM(#REF!) -> #REF!
AZ2: 尾程运输费 | BV2: 费用合计
A3: 出库指令 | Z3: 物品-拣料及最小包装 | AG3: 订单管理费 | AJ3: 拣货&包装费 | AM3: 拣货续件费 | AP3: 贴标费 | AS3: 包材费-包裹 | AV3: 装车费 | AY3: 合计 | AZ3: 基础费 | BI3: 续重费（超300公斤） | BK3: 附加费 | BR3: 3件包裹以上运输续件费 | BU3: 合计
A4: Order No. | B4: 订单 行数 | C4: 订单数 | D4: 对账 | E4: Warehouse | F4: 月份 | G4: Order Created At | H4: Shipped At | I4: Status | J4: Customer | K4: Original Reference | L4: Business Type | M4: Channel | N4: Creator | O4: 运单数 | P4: Priority | Q4: weight | R4: Carrier | S4: Carrier Return | T4: Shipments No1 | U4: Shipments No2 | V4: Retour No | W4: Postal Code | X4: 城市 | Y4: Country | Z4: Item ID | AA4: 物品描述 | AB4: 物品尺寸 长宽高cm | AC4: 单个物品 重量kg | AD4: Item Batch | AE4: Item Qty | AF4: 订单重量 kg | AG4: 数量 票 | AH4: 单价 Euro | AI4: 金额 Euro | AJ4: 数量 套 | AK4: 单价 Euro | AL4: 金额 Euro | AM4: 数量 pcs | AN4: 单价 Euro | AO4: 金额 Euro | AP4: 标签/张 | AQ4: 单价 | AR4: 金额 | AS4: 数量 pcs | AT4: 单价 Euro | AU4: 金额 Euro | AV4: 数量 /托 | AW4: 单价 Euro | AX4: 金额 Euro | AY4: 库内小计 | AZ4: 数量 票 | BA4: 实际重kg | BB4: 体积重KG | BC4: 计费 重量 kg | BD4: 邮编所属区域 | BE4: 城市 | BF4: 国家 | BG4: 单价 Euro | BH4: 金额 Euro | BI4: 单价 Euro | BJ4: 金额 Euro | BK4: 运输 订单 管理 * | BL4: 燃油 附加费 * | BM4: 过路 过桥 * | BN4: 运输 保险 | BO4: 预约 通知 * | BP4: 其它 | BQ4: 附加费小计 | BR4: 包裹数 个 | BS4: 单价 Euro | BT4: 金额 Euro

Sheet 2.1 正向-普货&大件-仓储费(8月）
AP1: =SUM(AP6:AP36) -> 0
A2: 计费时间IStorage Charge Date | C2: 入仓信息Inbound Information | I2: 商品信息Product Information | Q2: 装箱信息 | V2: 打托信息 | AA2: 原始入仓数量 | AE2: 进销存信息 | AJ2: 仓储费计费信息/Storage Charge Infromation | AQ2: 备注
A3: 月份 | B3: 日期 | C3: 仓库名称 | D3: 仓库编码 | E3: 客户代码 | F3: 入库任务号 | G3: 原始参考号 | H3: 入库上架时间 | I3: 编码 | J3: 条码 | K3: 商品名称 | L3: 件型 | M3: 长 | N3: 宽 | O3: 高 | P3: 单品体积A | Q3: 装箱数 | R3: 长 | S3: 宽 | T3: 高 | U3: 单箱体积B | V3: 打托数 | W3: 长 | X3: 宽 | Y3: 高 | Z3: 单托体积C | AA3: 托数 | AB3: 箱数 | AC3: 总数 | AD3: 批次号 | AE3: 期初库存数 | AF3: 入库数 | AG3: 出库数 | AH3: 期末库存数 | AI3: 计费单元 | AJ3: 库存体积E | AK3: 实际计费体积F | AL3: 库龄 | AM3: 库龄段 | AN3: 计费单价 | AO3: 币种 | AP3: 仓储费
A4: / | B4: / | C4: / | D4: / | E4: / | F4: / | G4: / | H4: / | I4: / | J4: / | K4: / | M4: cm | N4: cm | O4: cm | P4: CBM/m³ | Q4: pcs | R4: cm | S4: cm | T4: cm | U4: CBM/m³ | V4: pcs/box | W4: cm | X4: cm | Y4: cm | Z4: CBM/m³ | AA4: 托/Pallet | AB4: 箱/Box | AC4: 件/pcs | AE4: 件/pcs | AF4: 件/pcs | AG4: 件/pcs | AH4: 件/pcs | AI4: pcs/box/pallet | AJ4: CBM/m³ | AK4: CBM/m³ | AL4: 天/day | AM4: 天/day | AN4: / | AO4: Euro | AP4: Euro
A5: Month | B5: Date | C5: Warehouse Name | D5: Warehouse Code | E5: Client Code | F5: Task No. | G5: Original Ref. No. | H5: Inbound Time | I5: SKU | J5: Barcode | K5: Product Name | L5: Product Type | M5: Lenth | N5: Width | O5: Height | P5: Product Volume-A | Q5: Qty per Box | R5: Lenth | S5: Width | T5: Height | U5: Box Volume-B | V5: Qty per Pallet | W5: Lenth | X5: Width | Y5: Height | Z5: Pallet Volume-B | AA5: Qty of Pallet | AB5: Qty of Carton | AC5: Total Qty. | AD5: Batch No. | AE5: Beginning Inv | AF5: Inbound | AG5: Outbound | AH5: Ending Inv. | AI5: Charge Unit | AJ5: INV Volume-E | AK5: Charge Volume-F | AL5: Storage Age | AM5: Storage Age Range | AN5: Charge Price | AO5: Curreny | AP5: Storage Amount | AQ5: Rermar
A6: 202508 | B6: 45870 | C6: MIC德国仓 | D6: M » N2 - 1 | E6: YCD-EX:HUPPER TEK | F6: MI202508130012 | G6: DE2508031-G7-MIC | H6: 45889 | I6: B07BK8W5MF | K6: =VLOOKUP(I6,物品明细!A:B,2,0) -> 金属储物柜71英寸银色 | M6: =VLOOKUP(I6,物品明细!A:E,5,0) -> 188 | N6: =VLOOKUP(I6,物品明细!A:F,6,0) -> 49 | O6: =VLOOKUP(I6,物品明细!A:G,7,0) -> 14 | P6: =M6*N6*O6/1000000 -> 0.128968 | R6: =VLOOKUP(I6,物品明细!A:E,5,0) -> 188 | S6: =VLOOKUP(I6,物品明细!A:F,6,0) -> 49 | T6: =VLOOKUP(I6,物品明细!A:G,7,0) -> 14 | U6: =R6*S6*T6/1000000 -> 0.128968 | AA6: 21 | AB6: 247 | AC6: 247 | AD6: 0 | AE6: 0 | AH6: =AE6+AF6-AG6 -> 0 | AI6: pcs | AJ6: =AH6*P6 -> 0 | AK6: =AJ6 -> 0 | AL6: =B6-H6+1 -> -18 | AM6: =IF(AL6<=30,"30天内",IF(AL6<=90,"31-90天","91天以上")) -> 30天内 | AN6: 0 | AO6: Euro | AP6: =AK6*AN6 -> 0
A7: 202508 | B7: 45871 | C7: MIC德国仓 | D7: =D6 -> M » N2 - 1 | E7: =E6 -> YCD-EX:HUPPER TEK | F7: =F6 -> MI202508130012 | G7: =G6 -> DE2508031-G7-MIC | H7: =H6 -> 45889 | I7: =I6 -> B07BK8W5MF | K7: =K6 -> 金属储物柜71英寸银色 | M7: =M6 -> 188 | N7: =N6 -> 49 | O7: =O6 -> 14 | P7: =M7*N7*O7/1000000 -> 0.128968 | R7: =R6 -> 188 | S7: =S6 -> 49 | T7: =T6 -> 14 | U7: =R7*S7*T7/1000000 -> 0.128968 | AA7: =AA6 -> 21 | AB7: =AB6 -> 247 | AC7: =AC6 -> 247 | AD7: 0 | AE7: =AH6 -> 0 | AH7: =AE7+AF7-AG7 -> 0 | AI7: pcs | AJ7: =AH7*P7 -> 0 | AK7: =AJ7 -> 0 | AL7: =B7-H7+1 -> -17 | AM7: =IF(AL7<=30,"30天内",IF(AL7<=90,"31-90天","91天以上")) -> 30天内 | AN7: 0 | AO7: Euro | AP7: =AK7*AN7 -> 0
A8: 202508 | B8: 45872 | C8: MIC德国仓 | D8: =D7 -> M » N2 - 1 | E8: =E7 -> YCD-EX:HUPPER TEK | F8: =F7 -> MI202508130012 | G8: =G7 -> DE2508031-G7-MIC | H8: =H7 -> 45889 | I8: =I7 -> B07BK8W5MF | K8: =K7 -> 金属储物柜71英寸银色 | M8: =M7 -> 188 | N8: =N7 -> 49 | O8: =O7 -> 14 | P8: =M8*N8*O8/1000000 -> 0.128968 | R8: =R7 -> 188 | S8: =S7 -> 49 | T8: =T7 -> 14 | U8: =R8*S8*T8/1000000 -> 0.128968 | AA8: =AA7 -> 21 | AB8: =AB7 -> 247 | AC8: =AC7 -> 247 | AD8: 0 | AE8: =AH7 -> 0 | AH8: =AE8+AF8-AG8 -> 0 | AI8: pcs | AJ8: =AH8*P8 -> 0 | AK8: =AJ8 -> 0 | AL8: =B8-H8+1 -> -16 | AM8: =IF(AL8<=30,"30天内",IF(AL8<=90,"31-90天","91天以上")) -> 30天内 | AN8: 0 | AO8: Euro | AP8: =AK8*AN8 -> 0
A9: 202508 | B9: 45873 | C9: MIC德国仓 | D9: =D8 -> M » N2 - 1 | E9: =E8 -> YCD-EX:HUPPER TEK | F9: =F8 -> MI202508130012 | G9: =G8 -> DE2508031-G7-MIC | H9: =H8 -> 45889 | I9: =I8 -> B07BK8W5MF | K9: =K8 -> 金属储物柜71英寸银色 | M9: =M8 -> 188 | N9: =N8 -> 49 | O9: =O8 -> 14 | P9: =M9*N9*O9/1000000 -> 0.128968 | R9: =R8 -> 188 | S9: =S8 -> 49 | T9: =T8 -> 14 | U9: =R9*S9*T9/1000000 -> 0.128968 | AA9: =AA8 -> 21 | AB9: =AB8 -> 247 | AC9: =AC8 -> 247 | AD9: 0 | AE9: =AH8 -> 0 | AH9: =AE9+AF9-AG9 -> 0 | AI9: pcs | AJ9: =AH9*P9 -> 0 | AK9: =AJ9 -> 0 | AL9: =B9-H9+1 -> -15 | AM9: =IF(AL9<=30,"30天内",IF(AL9<=90,"31-90天","91天以上")) -> 30天内 | AN9: 0 | AO9: Euro | AP9: =AK9*AN9 -> 0
A10: 202508 | B10: 45874 | C10: MIC德国仓 | D10: =D9 -> M » N2 - 1 | E10: =E9 -> YCD-EX:HUPPER TEK | F10: =F9 -> MI202508130012 | G10: =G9 -> DE2508031-G7-MIC | H10: =H9 -> 45889 | I10: =I9 -> B07BK8W5MF | K10: =K9 -> 金属储物柜71英寸银色 | M10: =M9 -> 188 | N10: =N9 -> 49 | O10: =O9 -> 14 | P10: =M10*N10*O10/1000000 -> 0.128968 | R10: =R9 -> 188 | S10: =S9 -> 49 | T10: =T9 -> 14 | U10: =R10*S10*T10/1000000 -> 0.128968 | AA10: =AA9 -> 21 | AB10: =AB9 -> 247 | AC10: =AC9 -> 247 | AD10: 0 | AE10: =AH9 -> 0 | AH10: =AE10+AF10-AG10 -> 0 | AI10: pcs | AJ10: =AH10*P10 -> 0 | AK10: =AJ10 -> 0 | AL10: =B10-H10+1 -> -14 | AM10: =IF(AL10<=30,"30天内",IF(AL10<=90,"31-90天","91天以上")) -> 30天内 | AN10: 0 | AO10: Euro | AP10: =AK10*AN10 -> 0
A11: 202508 | B11: 45875 | C11: MIC德国仓 | D11: =D10 -> M » N2 - 1 | E11: =E10 -> YCD-EX:HUPPER TEK | F11: =F10 -> MI202508130012 | G11: =G10 -> DE2508031-G7-MIC | H11: =H10 -> 45889 | I11: =I10 -> B07BK8W5MF | K11: =K10 -> 金属储物柜71英寸银色 | M11: =M10 -> 188 | N11: =N10 -> 49 | O11: =O10 -> 14 | P11: =M11*N11*O11/1000000 -> 0.128968 | R11: =R10 -> 188 | S11: =S10 -> 49 | T11: =T10 -> 14 | U11: =R11*S11*T11/1000000 -> 0.128968 | AA11: =AA10 -> 21 | AB11: =AB10 -> 247 | AC11: =AC10 -> 247 | AD11: 0 | AE11: =AH10 -> 0 | AH11: =AE11+AF11-AG11 -> 0 | AI11: pcs | AJ11: =AH11*P11 -> 0 | AK11: =AJ11 -> 0 | AL11: =B11-H11+1 -> -13 | AM11: =IF(AL11<=30,"30天内",IF(AL11<=90,"31-90天","91天以上")) -> 30天内 | AN11: 0 | AO11: Euro | AP11: =AK11*AN11 -> 0
A12: 202508 | B12: 45876 | C12: MIC德国仓 | D12: =D11 -> M » N2 - 1 | E12: =E11 -> YCD-EX:HUPPER TEK | F12: =F11 -> MI202508130012 | G12: =G11 -> DE2508031-G7-MIC | H12: =H11 -> 45889 | I12: =I11 -> B07BK8W5MF | K12: =K11 -> 金属储物柜71英寸银色 | M12: =M11 -> 188 | N12: =N11 -> 49 | O12: =O11 -> 14 | P12: =M12*N12*O12/1000000 -> 0.128968 | R12: =R11 -> 188 | S12: =S11 -> 49 | T12: =T11 -> 14 | U12: =R12*S12*T12/1000000 -> 0.128968 | AA12: =AA11 -> 21 | AB12: =AB11 -> 247 | AC12: =AC11 -> 247 | AD12: 0 | AE12: =AH11 -> 0 | AH12: =AE12+AF12-AG12 -> 0 | AI12: pcs | AJ12: =AH12*P12 -> 0 | AK12: =AJ12 -> 0 | AL12: =B12-H12+1 -> -12 | AM12: =IF(AL12<=30,"30天内",IF(AL12<=90,"31-90天","91天以上")) -> 30天内 | AN12: 0 | AO12: Euro | AP12: =AK12*AN12 -> 0
A13: 202508 | B13: 45877 | C13: MIC德国仓 | D13: =D12 -> M » N2 - 1 | E13: =E12 -> YCD-EX:HUPPER TEK | F13: =F12 -> MI202508130012 | G13: =G12 -> DE2508031-G7-MIC | H13: =H12 -> 45889 | I13: =I12 -> B07BK8W5MF | K13: =K12 -> 金属储物柜71英寸银色 | M13: =M12 -> 188 | N13: =N12 -> 49 | O13: =O12 -> 14 | P13: =M13*N13*O13/1000000 -> 0.128968 | R13: =R12 -> 188 | S13: =S12 -> 49 | T13: =T12 -> 14 | U13: =R13*S13*T13/1000000 -> 0.128968 | AA13: =AA12 -> 21 | AB13: =AB12 -> 247 | AC13: =AC12 -> 247 | AD13: 0 | AE13: =AH12 -> 0 | AH13: =AE13+AF13-AG13 -> 0 | AI13: pcs | AJ13: =AH13*P13 -> 0 | AK13: =AJ13 -> 0 | AL13: =B13-H13+1 -> -11 | AM13: =IF(AL13<=30,"30天内",IF(AL13<=90,"31-90天","91天以上")) -> 30天内 | AN13: 0 | AO13: Euro | AP13: =AK13*AN13 -> 0
A14: 202508 | B14: 45878 | C14: MIC德国仓 | D14: =D13 -> M » N2 - 1 | E14: =E13 -> YCD-EX:HUPPER TEK | F14: =F13 -> MI202508130012 | G14: =G13 -> DE2508031-G7-MIC | H14: =H13 -> 45889 | I14: =I13 -> B07BK8W5MF | K14: =K13 -> 金属储物柜71英寸银色 | M14: =M13 -> 188 | N14: =N13 -> 49 | O14: =O13 -> 14 | P14: =M14*N14*O14/1000000 -> 0.128968 | R14: =R13 -> 188 | S14: =S13 -> 49 | T14: =T13 -> 14 | U14: =R14*S14*T14/1000000 -> 0.128968 | AA14: =AA13 -> 21 | AB14: =AB13 -> 247 | AC14: =AC13 -> 247 | AD14: 0 | AE14: =AH13 -> 0 | AH14: =AE14+AF14-AG14 -> 0 | AI14: pcs | AJ14: =AH14*P14 -> 0 | AK14: =AJ14 -> 0 | AL14: =B14-H14+1 -> -10 | AM14: =IF(AL14<=30,"30天内",IF(AL14<=90,"31-90天","91天以上")) -> 30天内 | AN14: 0 | AO14: Euro | AP14: =AK14*AN14 -> 0
A15: 202508 | B15: 45879 | C15: MIC德国仓 | D15: =D14 -> M » N2 - 1 | E15: =E14 -> YCD-EX:HUPPER TEK | F15: =F14 -> MI202508130012 | G15: =G14 -> DE2508031-G7-MIC | H15: =H14 -> 45889 | I15: =I14 -> B07BK8W5MF | K15: =K14 -> 金属储物柜71英寸银色 | M15: =M14 -> 188 | N15: =N14 -> 49 | O15: =O14 -> 14 | P15: =M15*N15*O15/1000000 -> 0.128968 | R15: =R14 -> 188 | S15: =S14 -> 49 | T15: =T14 -> 14 | U15: =R15*S15*T15/1000000 -> 0.128968 | AA15: =AA14 -> 21 | AB15: =AB14 -> 247 | AC15: =AC14 -> 247 | AD15: 0 | AE15: =AH14 -> 0 | AH15: =AE15+AF15-AG15 -> 0 | AI15: pcs | AJ15: =AH15*P15 -> 0 | AK15: =AJ15 -> 0 | AL15: =B15-H15+1 -> -9 | AM15: =IF(AL15<=30,"30天内",IF(AL15<=90,"31-90天","91天以上")) -> 30天内 | AN15: 0 | AO15: Euro | AP15: =AK15*AN15 -> 0
A16: 202508 | B16: 45880 | C16: MIC德国仓 | D16: =D15 -> M » N2 - 1 | E16: =E15 -> YCD-EX:HUPPER TEK | F16: =F15 -> MI202508130012 | G16: =G15 -> DE2508031-G7-MIC | H16: =H15 -> 45889 | I16: =I15 -> B07BK8W5MF | K16: =K15 -> 金属储物柜71英寸银色 | M16: =M15 -> 188 | N16: =N15 -> 49 | O16: =O15 -> 14 | P16: =M16*N16*O16/1000000 -> 0.128968 | R16: =R15 -> 188 | S16: =S15 -> 49 | T16: =T15 -> 14 | U16: =R16*S16*T16/1000000 -> 0.128968 | AA16: =AA15 -> 21 | AB16: =AB15 -> 247 | AC16: =AC15 -> 247 | AD16: 0 | AE16: =AH15 -> 0 | AH16: =AE16+AF16-AG16 -> 0 | AI16: pcs | AJ16: =AH16*P16 -> 0 | AK16: =AJ16 -> 0 | AL16: =B16-H16+1 -> -8 | AM16: =IF(AL16<=30,"30天内",IF(AL16<=90,"31-90天","91天以上")) -> 30天内 | AN16: 0 | AO16: Euro | AP16: =AK16*AN16 -> 0
A17: 202508 | B17: 45881 | C17: MIC德国仓 | D17: =D16 -> M » N2 - 1 | E17: =E16 -> YCD-EX:HUPPER TEK | F17: =F16 -> MI202508130012 | G17: =G16 -> DE2508031-G7-MIC | H17: =H16 -> 45889 | I17: =I16 -> B07BK8W5MF | K17: =K16 -> 金属储物柜71英寸银色 | M17: =M16 -> 188 | N17: =N16 -> 49 | O17: =O16 -> 14 | P17: =M17*N17*O17/1000000 -> 0.128968 | R17: =R16 -> 188 | S17: =S16 -> 49 | T17: =T16 -> 14 | U17: =R17*S17*T17/1000000 -> 0.128968 | AA17: =AA16 -> 21 | AB17: =AB16 -> 247 | AC17: =AC16 -> 247 | AD17: 0 | AE17: =AH16 -> 0 | AH17: =AE17+AF17-AG17 -> 0 | AI17: pcs | AJ17: =AH17*P17 -> 0 | AK17: =AJ17 -> 0 | AL17: =B17-H17+1 -> -7 | AM17: =IF(AL17<=30,"30天内",IF(AL17<=90,"31-90天","91天以上")) -> 30天内 | AN17: 0 | AO17: Euro | AP17: =AK17*AN17 -> 0
A18: 202508 | B18: 45882 | C18: MIC德国仓 | D18: =D17 -> M » N2 - 1 | E18: =E17 -> YCD-EX:HUPPER TEK | F18: =F17 -> MI202508130012 | G18: =G17 -> DE2508031-G7-MIC | H18: =H17 -> 45889 | I18: =I17 -> B07BK8W5MF | K18: =K17 -> 金属储物柜71英寸银色 | M18: =M17 -> 188 | N18: =N17 -> 49 | O18: =O17 -> 14 | P18: =M18*N18*O18/1000000 -> 0.128968 | R18: =R17 -> 188 | S18: =S17 -> 49 | T18: =T17 -> 14 | U18: =R18*S18*T18/1000000 -> 0.128968 | AA18: =AA17 -> 21 | AB18: =AB17 -> 247 | AC18: =AC17 -> 247 | AD18: 0 | AE18: =AH17 -> 0 | AH18: =AE18+AF18-AG18 -> 0 | AI18: pcs | AJ18: =AH18*P18 -> 0 | AK18: =AJ18 -> 0 | AL18: =B18-H18+1 -> -6 | AM18: =IF(AL18<=30,"30天内",IF(AL18<=90,"31-90天","91天以上")) -> 30天内 | AN18: 0 | AO18: Euro | AP18: =AK18*AN18 -> 0
... A24: 202508 | B24: 45888 | C24: MIC德国仓 | D24: =D23 -> M » N2 - 1 | E24: =E23 -> YCD-EX:HUPPER TEK | F24: =F23 -> MI202508130012 | G24: =G23 -> DE2508031-G7-MIC | H24: =H23 -> 45889 | I24: =I23 -> B07BK8W5MF | K24: =K23 -> 金属储物柜71英寸银色 | M24: =M23 -> 188 | N24: =N23 -> 49 | O24: =O23 -> 14 | P24: =M24*N24*O24/1000000 -> 0.128968 | R24: =R23 -> 188 | S24: =S23 -> 49 | T24: =T23 -> 14 | U24: =R24*S24*T24/1000000 -> 0.128968 | AA24: =AA23 -> 21 | AB24: =AB23 -> 247 | AC24: =AC23 -> 247 | AD24: 0 | AE24: =AH23 -> 0 | AH24: =AE24+AF24-AG24 -> 0 | AI24: pcs | AJ24: =AH24*P24 -> 0 | AK24: =AJ24 -> 0 | AL24: =B24-H24+1 -> 0 | AM24: =IF(AL24<=30,"30天内",IF(AL24<=90,"31-90天","91天以上")) -> 30天内 | AN24: 0 | AO24: Euro | AP24: =AK24*AN24 -> 0
A25: 202508 | B25: 45889 | C25: MIC德国仓 | D25: =D24 -> M » N2 - 1 | E25: =E24 -> YCD-EX:HUPPER TEK | F25: =F24 -> MI202508130012 | G25: =G24 -> DE2508031-G7-MIC | H25: =H24 -> 45889 | I25: =I24 -> B07BK8W5MF | K25: =K24 -> 金属储物柜71英寸银色 | M25: =M24 -> 188 | N25: =N24 -> 49 | O25: =O24 -> 14 | P25: =M25*N25*O25/1000000 -> 0.128968 | R25: =R24 -> 188 | S25: =S24 -> 49 | T25: =T24 -> 14 | U25: =R25*S25*T25/1000000 -> 0.128968 | AA25: =AA24 -> 21 | AB25: =AB24 -> 247 | AC25: =AC24 -> 247 | AD25: 0 | AE25: =AH24 -> 0 | AF25: 247 | AH25: =AE25+AF25-AG25 -> 247 | AI25: pcs | AJ25: =AH25*P25 -> 31.855096 | AK25: =AJ25 -> 31.855096 | AL25: =B25-H25+1 -> 1 | AM25: =IF(AL25<=30,"30天内",IF(AL25<=90,"31-90天","91天以上")) -> 30天内 | AN25: 0 | AO25: Euro | AP25: =AK25*AN25 -> 0
A26: 202508 | B26: 45890 | C26: MIC德国仓 | D26: =D25 -> M » N2 - 1 | E26: =E25 -> YCD-EX:HUPPER TEK | F26: =F25 -> MI202508130012 | G26: =G25 -> DE2508031-G7-MIC | H26: =H25 -> 45889 | I26: =I25 -> B07BK8W5MF | K26: =K25 -> 金属储物柜71英寸银色 | M26: =M25 -> 188 | N26: =N25 -> 49 | O26: =O25 -> 14 | P26: =M26*N26*O26/1000000 -> 0.128968 | R26: =R25 -> 188 | S26: =S25 -> 49 | T26: =T25 -> 14 | U26: =R26*S26*T26/1000000 -> 0.128968 | AA26: =AA25 -> 21 | AB26: =AB25 -> 247 | AC26: =AC25 -> 247 | AD26: 0 | AE26: =AH25 -> 247 | AH26: =AE26+AF26-AG26 -> 247 | AI26: pcs | AJ26: =AH26*P26 -> 31.855096 | AK26: =AJ26 -> 31.855096 | AL26: =B26-H26+1 -> 2 | AM26: =IF(AL26<=30,"30天内",IF(AL26<=90,"31-90天","91天以上")) -> 30天内 | AN26: 0 | AO26: Euro | AP26: =AK26*AN26 -> 0
A27: 202508 | B27: 45891 | C27: MIC德国仓 | D27: =D26 -> M » N2 - 1 | E27: =E26 -> YCD-EX:HUPPER TEK | F27: =F26 -> MI202508130012 | G27: =G26 -> DE2508031-G7-MIC | H27: =H26 -> 45889 | I27: =I26 -> B07BK8W5MF | K27: =K26 -> 金属储物柜71英寸银色 | M27: =M26 -> 188 | N27: =N26 -> 49 | O27: =O26 -> 14 | P27: =M27*N27*O27/1000000 -> 0.128968 | R27: =R26 -> 188 | S27: =S26 -> 49 | T27: =T26 -> 14 | U27: =R27*S27*T27/1000000 -> 0.128968 | AA27: =AA26 -> 21 | AB27: =AB26 -> 247 | AC27: =AC26 -> 247 | AD27: 0 | AE27: =AH26 -> 247 | AH27: =AE27+AF27-AG27 -> 247 | AI27: pcs | AJ27: =AH27*P27 -> 31.855096 | AK27: =AJ27 -> 31.855096 | AL27: =B27-H27+1 -> 3 | AM27: =IF(AL27<=30,"30天内",IF(AL27<=90,"31-90天","91天以上")) -> 30天内 | AN27: 0 | AO27: Euro | AP27: =AK27*AN27 -> 0
A28: 202508 | B28: 45892 | C28: MIC德国仓 | D28: =D27 -> M » N2 - 1 | E28: =E27 -> YCD-EX:HUPPER TEK | F28: =F27 -> MI202508130012 | G28: =G27 -> DE2508031-G7-MIC | H28: =H27 -> 45889 | I28: =I27 -> B07BK8W5MF | K28: =K27 -> 金属储物柜71英寸银色 | M28: =M27 -> 188 | N28: =N27 -> 49 | O28: =O27 -> 14 | P28: =M28*N28*O28/1000000 -> 0.128968 | R28: =R27 -> 188 | S28: =S27 -> 49 | T28: =T27 -> 14 | U28: =R28*S28*T28/1000000 -> 0.128968 | AA28: =AA27 -> 21 | AB28: =AB27 -> 247 | AC28: =AC27 -> 247 | AD28: 0 | AE28: =AH27 -> 247 | AH28: =AE28+AF28-AG28 -> 247 | AI28: pcs | AJ28: =AH28*P28 -> 31.855096 | AK28: =AJ28 -> 31.855096 | AL28: =B28-H28+1 -> 4 | AM28: =IF(AL28<=30,"30天内",IF(AL28<=90,"31-90天","91天以上")) -> 30天内 | AN28: 0 | AO28: Euro | AP28: =AK28*AN28 -> 0
A29: 202508 | B29: 45893 | C29: MIC德国仓 | D29: =D28 -> M » N2 - 1 | E29: =E28 -> YCD-EX:HUPPER TEK | F29: =F28 -> MI202508130012 | G29: =G28 -> DE2508031-G7-MIC | H29: =H28 -> 45889 | I29: =I28 -> B07BK8W5MF | K29: =K28 -> 金属储物柜71英寸银色 | M29: =M28 -> 188 | N29: =N28 -> 49 | O29: =O28 -> 14 | P29: =M29*N29*O29/1000000 -> 0.128968 | R29: =R28 -> 188 | S29: =S28 -> 49 | T29: =T28 -> 14 | U29: =R29*S29*T29/1000000 -> 0.128968 | AA29: =AA28 -> 21 | AB29: =AB28 -> 247 | AC29: =AC28 -> 247 | AD29: 0 | AE29: =AH28 -> 247 | AH29: =AE29+AF29-AG29 -> 247 | AI29: pcs | AJ29: =AH29*P29 -> 31.855096 | AK29: =AJ29 -> 31.855096 | AL29: =B29-H29+1 -> 5 | AM29: =IF(AL29<=30,"30天内",IF(AL29<=90,"31-90天","91天以上")) -> 30天内 | AN29: 0 | AO29: Euro | AP29: =AK29*AN29 -> 0
A30: 202508 | B30: 45894 | C30: MIC德国仓 | D30: =D29 -> M » N2 - 1 | E30: =E29 -> YCD-EX:HUPPER TEK | F30: =F29 -> MI202508130012 | G30: =G29 -> DE2508031-G7-MIC | H30: =H29 -> 45889 | I30: =I29 -> B07BK8W5MF | K30: =K29 -> 金属储物柜71英寸银色 | M30: =M29 -> 188 | N30: =N29 -> 49 | O30: =O29 -> 14 | P30: =M30*N30*O30/1000000 -> 0.128968 | R30: =R29 -> 188 | S30: =S29 -> 49 | T30: =T29 -> 14 | U30: =R30*S30*T30/1000000 -> 0.128968 | AA30: =AA29 -> 21 | AB30: =AB29 -> 247 | AC30: =AC29 -> 247 | AD30: 0 | AE30: =AH29 -> 247 | AH30: =AE30+AF30-AG30 -> 247 | AI30: pcs | AJ30: =AH30*P30 -> 31.855096 | AK30: =AJ30 -> 31.855096 | AL30: =B30-H30+1 -> 6 | AM30: =IF(AL30<=30,"30天内",IF(AL30<=90,"31-90天","91天以上")) -> 30天内 | AN30: 0 | AO30: Euro | AP30: =AK30*AN30 -> 0
A31: 202508 | B31: 45895 | C31: MIC德国仓 | D31: =D30 -> M » N2 - 1 | E31: =E30 -> YCD-EX:HUPPER TEK | F31: =F30 -> MI202508130012 | G31: =G30 -> DE2508031-G7-MIC | H31: =H30 -> 45889 | I31: =I30 -> B07BK8W5MF | K31: =K30 -> 金属储物柜71英寸银色 | M31: =M30 -> 188 | N31: =N30 -> 49 | O31: =O30 -> 14 | P31: =M31*N31*O31/1000000 -> 0.128968 | R31: =R30 -> 188 | S31: =S30 -> 49 | T31: =T30 -> 14 | U31: =R31*S31*T31/1000000 -> 0.128968 | AA31: =AA30 -> 21 | AB31: =AB30 -> 247 | AC31: =AC30 -> 247 | AD31: 0 | AE31: =AH30 -> 247 | AH31: =AE31+AF31-AG31 -> 247 | AI31: pcs | AJ31: =AH31*P31 -> 31.855096 | AK31: =AJ31 -> 31.855096 | AL31: =B31-H31+1 -> 7 | AM31: =IF(AL31<=30,"30天内",IF(AL31<=90,"31-90天","91天以上")) -> 30天内 | AN31: 0 | AO31: Euro | AP31: =AK31*AN31 -> 0
A32: 202508 | B32: 45896 | C32: MIC德国仓 | D32: =D31 -> M » N2 - 1 | E32: =E31 -> YCD-EX:HUPPER TEK | F32: =F31 -> MI202508130012 | G32: =G31 -> DE2508031-G7-MIC | H32: =H31 -> 45889 | I32: =I31 -> B07BK8W5MF | K32: =K31 -> 金属储物柜71英寸银色 | M32: =M31 -> 188 | N32: =N31 -> 49 | O32: =O31 -> 14 | P32: =M32*N32*O32/1000000 -> 0.128968 | R32: =R31 -> 188 | S32: =S31 -> 49 | T32: =T31 -> 14 | U32: =R32*S32*T32/1000000 -> 0.128968 | AA32: =AA31 -> 21 | AB32: =AB31 -> 247 | AC32: =AC31 -> 247 | AD32: 0 | AE32: =AH31 -> 247 | AH32: =AE32+AF32-AG32 -> 247 | AI32: pcs | AJ32: =AH32*P32 -> 31.855096 | AK32: =AJ32 -> 31.855096 | AL32: =B32-H32+1 -> 8 | AM32: =IF(AL32<=30,"30天内",IF(AL32<=90,"31-90天","91天以上")) -> 30天内 | AN32: 0 | AO32: Euro | AP32: =AK32*AN32 -> 0
A33: 202508 | B33: 45897 | C33: MIC德国仓 | D33: =D32 -> M » N2 - 1 | E33: =E32 -> YCD-EX:HUPPER TEK | F33: =F32 -> MI202508130012 | G33: =G32 -> DE2508031-G7-MIC | H33: =H32 -> 45889 | I33: =I32 -> B07BK8W5MF | K33: =K32 -> 金属储物柜71英寸银色 | M33: =M32 -> 188 | N33: =N32 -> 49 | O33: =O32 -> 14 | P33: =M33*N33*O33/1000000 -> 0.128968 | R33: =R32 -> 188 | S33: =S32 -> 49 | T33: =T32 -> 14 | U33: =R33*S33*T33/1000000 -> 0.128968 | AA33: =AA32 -> 21 | AB33: =AB32 -> 247 | AC33: =AC32 -> 247 | AD33: 0 | AE33: =AH32 -> 247 | AH33: =AE33+AF33-AG33 -> 247 | AI33: pcs | AJ33: =AH33*P33 -> 31.855096 | AK33: =AJ33 -> 31.855096 | AL33: =B33-H33+1 -> 9 | AM33: =IF(AL33<=30,"30天内",IF(AL33<=90,"31-90天","91天以上")) -> 30天内 | AN33: 0 | AO33: Euro | AP33: =AK33*AN33 -> 0
A34: 202508 | B34: 45898 | C34: MIC德国仓 | D34: =D33 -> M » N2 - 1 | E34: =E33 -> YCD-EX:HUPPER TEK | F34: =F33 -> MI202508130012 | G34: =G33 -> DE2508031-G7-MIC | H34: =H33 -> 45889 | I34: =I33 -> B07BK8W5MF | K34: =K33 -> 金属储物柜71英寸银色 | M34: =M33 -> 188 | N34: =N33 -> 49 | O34: =O33 -> 14 | P34: =M34*N34*O34/1000000 -> 0.128968 | R34: =R33 -> 188 | S34: =S33 -> 49 | T34: =T33 -> 14 | U34: =R34*S34*T34/1000000 -> 0.128968 | AA34: =AA33 -> 21 | AB34: =AB33 -> 247 | AC34: =AC33 -> 247 | AD34: 0 | AE34: =AH33 -> 247 | AH34: =AE34+AF34-AG34 -> 247 | AI34: pcs | AJ34: =AH34*P34 -> 31.855096 | AK34: =AJ34 -> 31.855096 | AL34: =B34-H34+1 -> 10 | AM34: =IF(AL34<=30,"30天内",IF(AL34<=90,"31-90天","91天以上")) -> 30天内 | AN34: 0 | AO34: Euro | AP34: =AK34*AN34 -> 0
A35: 202508 | B35: 45899 | C35: MIC德国仓 | D35: =D34 -> M » N2 - 1 | E35: =E34 -> YCD-EX:HUPPER TEK | F35: =F34 -> MI202508130012 | G35: =G34 -> DE2508031-G7-MIC | H35: =H34 -> 45889 | I35: =I34 -> B07BK8W5MF | K35: =K34 -> 金属储物柜71英寸银色 | M35: =M34 -> 188 | N35: =N34 -> 49 | O35: =O34 -> 14 | P35: =M35*N35*O35/1000000 -> 0.128968 | R35: =R34 -> 188 | S35: =S34 -> 49 | T35: =T34 -> 14 | U35: =R35*S35*T35/1000000 -> 0.128968 | AA35: =AA34 -> 21 | AB35: =AB34 -> 247 | AC35: =AC34 -> 247 | AD35: 0 | AE35: =AH34 -> 247 | AH35: =AE35+AF35-AG35 -> 247 | AI35: pcs | AJ35: =AH35*P35 -> 31.855096 | AK35: =AJ35 -> 31.855096 | AL35: =B35-H35+1 -> 11 | AM35: =IF(AL35<=30,"30天内",IF(AL35<=90,"31-90天","91天以上")) -> 30天内 | AN35: 0 | AO35: Euro | AP35: =AK35*AN35 -> 0
A36: 202508 | B36: 45900 | C36: MIC德国仓 | D36: =D35 -> M » N2 - 1 | E36: =E35 -> YCD-EX:HUPPER TEK | F36: =F35 -> MI202508130012 | G36: =G35 -> DE2508031-G7-MIC | H36: =H35 -> 45889 | I36: =I35 -> B07BK8W5MF | K36: =K35 -> 金属储物柜71英寸银色 | M36: =M35 -> 188 | N36: =N35 -> 49 | O36: =O35 -> 14 | P36: =M36*N36*O36/1000000 -> 0.128968 | R36: =R35 -> 188 | S36: =S35 -> 49 | T36: =T35 -> 14 | U36: =R36*S36*T36/1000000 -> 0.128968 | AA36: =AA35 -> 21 | AB36: =AB35 -> 247 | AC36: =AC35 -> 247 | AD36: 0 | AE36: =AH35 -> 247 | AH36: =AE36+AF36-AG36 -> 247 | AI36: pcs | AJ36: =AH36*P36 -> 31.855096 | AK36: =AJ36 -> 31.855096 | AL36: =B36-H36+1 -> 12 | AM36: =IF(AL36<=30,"30天内",IF(AL36<=90,"31-90天","91天以上")) -> 30天内 | AN36: 0 | AO36: Euro | AP36: =AK36*AN36 -> 0
A37: 202508 | B37: 45870 | C37: MIC德国仓 | D37: M » N2 - 1 | E37: YCD-EX:HUPPER TEK | F37: MI202508130012 | G37: DE2508031-G7-MIC | H37: 45889 | I37: B076THQBHX | K37: =VLOOKUP(I37,物品明细!A:B,2,0) -> 金属储物柜71英寸灰色 | M37: =VLOOKUP(I37,物品明细!A:E,5,0) -> 188 | N37: =VLOOKUP(I37,物品明细!A:F,6,0) -> 49 | O37: =VLOOKUP(I37,物品明细!A:G,7,0) -> 14 | P37: =M37*N37*O37/1000000 -> 0.128968 | R37: =VLOOKUP(I37,物品明细!A:E,5,0) -> 188 | S37: =VLOOKUP(I37,物品明细!A:F,6,0) -> 49 | T37: =VLOOKUP(I37,物品明细!A:G,7,0) -> 14 | U37: =R37*S37*T37/1000000 -> 0.128968 | AA37: 19 | AB37: 223 | AC37: 223 | AD37: 0 | AE37: 0 | AH37: =AE37+AF37-AG37 -> 0 | AI37: pcs | AJ37: =AH37*P37 -> 0 | AK37: =AJ37 -> 0 | AL37: =B37-H37+1 -> -18 | AM37: =IF(AL37<=30,"30天内",IF(AL37<=90,"31-90天","91天以上")) -> 30天内 | AN37: 0 | AO37: Euro | AP37: =AK37*AN37 -> 0
A38: 202508 | B38: 45871 | C38: MIC德国仓 | D38: =D37 -> M » N2 - 1 | E38: =E37 -> YCD-EX:HUPPER TEK | F38: =F37 -> MI202508130012 | G38: =G37 -> DE2508031-G7-MIC | H38: =H37 -> 45889 | I38: =I37 -> B076THQBHX | K38: =K37 -> 金属储物柜71英寸灰色 | M38: =M37 -> 188 | N38: =N37 -> 49 | O38: =O37 -> 14 | P38: =M38*N38*O38/1000000 -> 0.128968 | R38: =R37 -> 188 | S38: =S37 -> 49 | T38: =T37 -> 14 | U38: =R38*S38*T38/1000000 -> 0.128968 | AA38: =AA37 -> 19 | AB38: =AB37 -> 223 | AC38: =AC37 -> 223 | AD38: 0 | AE38: =AH37 -> 0 | AH38: =AE38+AF38-AG38 -> 0 | AI38: pcs | AJ38: =AH38*P38 -> 0 | AK38: =AJ38 -> 0 | AL38: =B38-H38+1 -> -17 | AM38: =IF(AL38<=30,"30天内",IF(AL38<=90,"31-90天","91天以上")) -> 30天内 | AN38: 0 | AO38: Euro | AP38: =AK38*AN38 -> 0
A39: 202508 | B39: 45872 | C39: MIC德国仓 | D39: =D38 -> M » N2 - 1 | E39: =E38 -> YCD-EX:HUPPER TEK | F39: =F38 -> MI202508130012 | G39: =G38 -> DE2508031-G7-MIC | H39: =H38 -> 45889 | I39: =I38 -> B076THQBHX | K39: =K38 -> 金属储物柜71英寸灰色 | M39: =M38 -> 188 | N39: =N38 -> 49 | O39: =O38 -> 14 | P39: =M39*N39*O39/1000000 -> 0.128968 | R39: =R38 -> 188 | S39: =S38 -> 49 | T39: =T38 -> 14 | U39: =R39*S39*T39/1000000 -> 0.128968 | AA39: =AA38 -> 19 | AB39: =AB38 -> 223 | AC39: =AC38 -> 223 | AD39: 0 | AE39: =AH38 -> 0 | AH39: =AE39+AF39-AG39 -> 0 | AI39: pcs | AJ39: =AH39*P39 -> 0 | AK39: =AJ39 -> 0 | AL39: =B39-H39+1 -> -16 | AM39: =IF(AL39<=30,"30天内",IF(AL39<=90,"31-90天","91天以上")) -> 30天内 | AN39: 0 | AO39: Euro | AP39: =AK39*AN39 -> 0
A40: 202508 | B40: 45873 | C40: MIC德国仓 | D40: =D39 -> M » N2 - 1 | E40: =E39 -> YCD-EX:HUPPER TEK | F40: =F39 -> MI202508130012 | G40: =G39 -> DE2508031-G7-MIC | H40: =H39 -> 45889 | I40: =I39 -> B076THQBHX | K40: =K39 -> 金属储物柜71英寸灰色 | M40: =M39 -> 188 | N40: =N39 -> 49 | O40: =O39 -> 14 | P40: =M40*N40*O40/1000000 -> 0.128968 | R40: =R39 -> 188 | S40: =S39 -> 49 | T40: =T39 -> 14 | U40: =R40*S40*T40/1000000 -> 0.128968 | AA40: =AA39 -> 19 | AB40: =AB39 -> 223 | AC40: =AC39 -> 223 | AD40: 0 | AE40: =AH39 -> 0 | AH40: =AE40+AF40-AG40 -> 0 | AI40: pcs | AJ40: =AH40*P40 -> 0 | AK40: =AJ40 -> 0 | AL40: =B40-H40+1 -> -15 | AM40: =IF(AL40<=30,"30天内",IF(AL40<=90,"31-90天","91天以上")) -> 30天内 | AN40: 0 | AO40: Euro | AP40: =AK40*AN40 -> 0
A41: 202508 | B41: 45874 | C41: MIC德国仓 | D41: =D40 -> M » N2 - 1 | E41: =E40 -> YCD-EX:HUPPER TEK | F41: =F40 -> MI202508130012 | G41: =G40 -> DE2508031-G7-MIC | H41: =H40 -> 45889 | I41: =I40 -> B076THQBHX | K41: =K40 -> 金属储物柜71英寸灰色 | M41: =M40 -> 188 | N41: =N40 -> 49 | O41: =O40 -> 14 | P41: =M41*N41*O41/1000000 -> 0.128968 | R41: =R40 -> 188 | S41: =S40 -> 49 | T41: =T40 -> 14 | U41: =R41*S41*T41/1000000 -> 0.128968 | AA41: =AA40 -> 19 | AB41: =AB40 -> 223 | AC41: =AC40 -> 223 | AD41: 0 | AE41: =AH40 -> 0 | AH41: =AE41+AF41-AG41 -> 0 | AI41: pcs | AJ41: =AH41*P41 -> 0 | AK41: =AJ41 -> 0 | AL41: =B41-H41+1 -> -14 | AM41: =IF(AL41<=30,"30天内",IF(AL41<=90,"31-90天","91天以上")) -> 30天内 | AN41: 0 | AO41: Euro | AP41: =AK41*AN41 -> 0
A42: 202508 | B42: 45875 | C42: MIC德国仓 | D42: =D41 -> M » N2 - 1 | E42: =E41 -> YCD-EX:HUPPER TEK | F42: =F41 -> MI202508130012 | G42: =G41 -> DE2508031-G7-MIC | H42: =H41 -> 45889 | I42: =I41 -> B076THQBHX | K42: =K41 -> 金属储物柜71英寸灰色 | M42: =M41 -> 188 | N42: =N41 -> 49 | O42: =O41 -> 14 | P42: =M42*N42*O42/1000000 -> 0.128968 | R42: =R41 -> 188 | S42: =S41 -> 49 | T42: =T41 -> 14 | U42: =R42*S42*T42/1000000 -> 0.128968 | AA42: =AA41 -> 19 | AB42: =AB41 -> 223 | AC42: =AC41 -> 223 | AD42: 0 | AE42: =AH41 -> 0 | AH42: =AE42+AF42-AG42 -> 0 | AI42: pcs | AJ42: =AH42*P42 -> 0 | AK42: =AJ42 -> 0 | AL42: =B42-H42+1 -> -13 | AM42: =IF(AL42<=30,"30天内",IF(AL42<=90,"31-90天","91天以上")) -> 30天内 | AN42: 0 | AO42: Euro | AP42: =AK42*AN42 -> 0
A43: 202508 | B43: 45876 | C43: MIC德国仓 | D43: =D42 -> M » N2 - 1 | E43: =E42 -> YCD-EX:HUPPER TEK | F43: =F42 -> MI202508130012 | G43: =G42 -> DE2508031-G7-MIC | H43: =H42 -> 45889 | I43: =I42 -> B076THQBHX | K43: =K42 -> 金属储物柜71英寸灰色 | M43: =M42 -> 188 | N43: =N42 -> 49 | O43: =O42 -> 14 | P43: =M43*N43*O43/1000000 -> 0.128968 | R43: =R42 -> 188 | S43: =S42 -> 49 | T43: =T42 -> 14 | U43: =R43*S43*T43/1000000 -> 0.128968 | AA43: =AA42 -> 19 | AB43: =AB42 -> 223 | AC43: =AC42 -> 223 | AD43: 0 | AE43: =AH42 -> 0 | AH43: =AE43+AF43-AG43 -> 0 | AI43: pcs | AJ43: =AH43*P43 -> 0 | AK43: =AJ43 -> 0 | AL43: =B43-H43+1 -> -12 | AM43: =IF(AL43<=30,"30天内",IF(AL43<=90,"31-90天","91天以上")) -> 30天内 | AN43: 0 | AO43: Euro | AP43: =AK43*AN43 -> 0
A44: 202508 | B44: 45877 | C44: MIC德国仓 | D44: =D43 -> M » N2 - 1 | E44: =E43 -> YCD-EX:HUPPER TEK | F44: =F43 -> MI202508130012 | G44: =G43 -> DE2508031-G7-MIC | H44: =H43 -> 45889 | I44: =I43 -> B076THQBHX | K44: =K43 -> 金属储物柜71英寸灰色 | M44: =M43 -> 188 | N44: =N43 -> 49 | O44: =O43 -> 14 | P44: =M44*N44*O44/1000000 -> 0.128968 | R44: =R43 -> 188 | S44: =S43 -> 49 | T44: =T43 -> 14 | U44: =R44*S44*T44/1000000 -> 0.128968 | AA44: =AA43 -> 19 | AB44: =AB43 -> 223 | AC44: =AC43 -> 223 | AD44: 0 | AE44: =AH43 -> 0 | AH44: =AE44+AF44-AG44 -> 0 | AI44: pcs | AJ44: =AH44*P44 -> 0 | AK44: =AJ44 -> 0 | AL44: =B44-H44+1 -> -11 | AM44: =IF(AL44<=30,"30天内",IF(AL44<=90,"31-90天","91天以上")) -> 30天内 | AN44: 0 | AO44: Euro | AP44: =AK44*AN44 -> 0
A45: 202508 | B45: 45878 | C45: MIC德国仓 | D45: =D44 -> M » N2 - 1 | E45: =E44 -> YCD-EX:HUPPER TEK | F45: =F44 -> MI202508130012 | G45: =G44 -> DE2508031-G7-MIC | H45: =H44 -> 45889 | I45: =I44 -> B076THQBHX | K45: =K44 -> 金属储物柜71英寸灰色 | M45: =M44 -> 188 | N45: =N44 -> 49 | O45: =O44 -> 14 | P45: =M45*N45*O45/1000000 -> 0.128968 | R45: =R44 -> 188 | S45: =S44 -> 49 | T45: =T44 -> 14 | U45: =R45*S45*T45/1000000 -> 0.128968 | AA45: =AA44 -> 19 | AB45: =AB44 -> 223 | AC45: =AC44 -> 223 | AD45: 0 | AE45: =AH44 -> 0 | AH45: =AE45+AF45-AG45 -> 0 | AI45: pcs | AJ45: =AH45*P45 -> 0 | AK45: =AJ45 -> 0 | AL45: =B45-H45+1 -> -10 | AM45: =IF(AL45<=30,"30天内",IF(AL45<=90,"31-90天","91天以上")) -> 30天内 | AN45: 0 | AO45: Euro | AP45: =AK45*AN45 -> 0
...

Sheet 物品明细
A1: Item ID | B1: Name | C1: Barcode | D1: Weight | E1: Length | F1: Width | G1: Height | H1: HS Code | I1: 规格 | J1: 体积 | K1: 原始名称 | L1: 打托数
A2: B076THQBHX | B2: 金属储物柜71英寸灰色 | C2: 7434503987965 | D2: 47.4 | E2: 188 | F2: 49 | G2: 14 | I2: =E2&"x"&F2&"x"&G2 -> 188x49x14 | J2: =E2*F2*G2/1000000 -> 0.128968 | K2: Metal Storage Cabinet 71 inches Gray | L2: 12个/托
A3: B07BK8W5MF | B3: 金属储物柜71英寸银色 | C3: 7434503791791 | D3: 47.4 | E3: 188 | F3: 49 | G3: 14 | I3: =E3&"x"&F3&"x"&G3 -> 188x49x14 | J3: =E3*F3*G3/1000000 -> 0.128968 | K3: Metal Storage Cabinet 71 inches Silver | L3: 12个/托
A4: B077RVYZRF | B4: 德国联邦快递金属储物柜 | C4: 7434503188171 | D4: 47.4 | E4: 188 | F4: 49 | G4: 14 | I4: =E4&"x"&F4&"x"&G4 -> 188x49x14 | J4: =E4*F4*G4/1000000 -> 0.128968 | K4: DE - Fedmax Metal Storage Cabinet | L4: 12个/托
A5: B07Q3SQT6C | B5: 金属储物柜71英寸高 | C5: 600413399021 | D5: 47.4 | E5: 188 | F5: 49 | G5: 14 | I5: =E5&"x"&F5&"x"&G5 -> 188x49x14 | J5: =E5*F5*G5/1000000 -> 0.128968 | K5: Metal Storage Cabinet 71" Tall | L5: 12个/托
