Workbook
Name _dpx2: '[2]DHL City to Zone OB Vol'!$AF$7:$AO$45

Sheet 对账单-汇总页
D1: MIC Logistik GmbH对账单（9月）
G2: 报价版本号： | H2: YCD20250701
A3: 客户 | B3: 哈贝尔HUPPER TEK | D3: 海外仓地点 | E3: 德国北威州门兴格拉德巴赫（40670 ）
A4: 报价生效日期 | B4: 2025.07.01 | D4: 公司邮箱 | E4: info@miclogistik.de
A5: 对账期 | B5: 2025.09.09~2025.09.30 | D5: 公司网页 | E5: www.miclogistik.de
A7: 一、服务内容及对账明细 | G7: 计费币种：欧元/Euro
A8: 业务场景 | B8: 费用项 | C8: 库内基础费用 A | D8: 运输基础费用 B | E8: 附加费 C | F8: 开票费用合计 A-B+C | G8: 备注
A9: 1. 正向 | B9: 1.1 入库 | C9: ='1.1 正向-入库'!V1 -> 0 | D9: 0 | E9: 0 | F9: =C9+D9+E9 -> 0 | G9: 9月无入库
B10: 2.1 2B | C10: ='2.1 正向-2B'!BF1 -> 400.95 | D10: 0 | E10: ='2.1 正向-2B'!BX1+'2.1 正向-2B'!CA1 -> 0 | F10: =C10+D10+E10 -> 400.95
B11: 2.2 2C订单-GEL | C11: ='2.2 正向-2C-GEL'!AV1 -> 635.85 | D11: ='2.2 正向-2C-GEL'!BE1 -> 3647.4669 | E11: ='2.2 正向-2C-GEL'!BJ1+'2.2 正向-2C-GEL'!BM1 -> 509.6 | F11: =C11+D11+E11 -> 4792.9169
B12: 3.2 仓储费(9月） | C12: ='3.1 正向-普货-仓储费 '!AP1 -> 674.82506 | D12: 0 | E12: 0 | F12: =C12+D12+E12 -> 674.82506 | G12: 每月月底统一核算
A13: 3. 其他 | C13: 0 | D13: 0 | E13: 0 | F13: =C13+D13+E13 -> 0
A14: 合计 | C14: =SUM(C9:C13) -> 1711.6251 | D14: =SUM(D9:D13) -> 3647.4669 | E14: =SUM(E9:E13) -> 509.6 | F14: =C14+D14+E14 -> 5868.692
A15: 预付款（9月16日充值4000欧元+9月28日充值2700欧元） | C15: =4000+2700 -> 6700 | G15: 减去8月账单1632欧元
A16: 截止到9月30日余额 | C16: =C15-F14-1632 -> -800.69196 | G16: 9月已欠费（建议充值）
A18: 关键说明
A19: 1. 报价： | B19: 不含德国VAT，相关的附加费具体详见每项报价说明。
A20: 2. 账号使用前提： | B20: 采用预充值+保证金的方式： 预充值：根据未来2周或1个月预测消费额提前充值，按照不同重量段及对应报价，出单时进行预扣（含退货），充值余额不足则暂停出单； 保证金：主要是应对相关异常费用，不含常规的出单基础费、附加费，具体额度按月度预充值*15%来收取。
A21: 3. 结算： | B21: 结算币种为欧元，月结，开票与预充值核销。
A22: 4. 运输保险： | B22: 建议购买，发送丢失或损毁，按商业发票金额（需含运费）赔偿；若不购买，只能按照德国道理运输法则，货物实际重量*8.33欧/kg进行赔偿，运费也不赔偿。
A23: 5. 服务时间： | B23: 若遇当地国法定节假日，导致服务商不收货，我司会提前知会客户。
A24: 6. 报价申明： | B24: 卡派运输市场价格波动大，若变化浮动超过10%，MIC提前一个月书面/邮件通知确认。
A26: 客户签章 | F26: MIC Logistik GmbH
A31: 日期： | B31: 45933 | F31: 日期： | G31: =B31 -> 45933

Sheet 1.1 正向-入库
A1: MIC德国海外仓到货&收货&入库明细表 | U1: =SUM(U4:U7) -> 0 | V1: =SUM(V4:V7) -> 0
A2: 退货信息 | R2: 卸货&收货费 | V2: 合计
A3: 任务号 | B3: 入库月份 | C3: Carrier | D3: 收货日期 | E3: 入库状态 | F3: 客户 | G3: 批次号 | H3: 批次号行数 | I3: 批次数 | J3: 类型 | K3: 物品SKU | L3: 物品描述 | M3: 物品 总数 | N3: 货位 | O3: 箱数 | P3: 托盘数 | Q3: Remark | R3: 托盘数 | S3: 箱数 | T3: 单价 | U3: 金额

Sheet 2.1 正向-2B
A1: MIC德国海外仓一件代发明细表 | AP1: =SUM(AP5:AP8) -> 319.95 | AS1: =SUM(AS5:AS8) -> 0 | AV1: =SUM(AV5:AV8) -> 0 | AY1: =SUM(AY5:AY8) -> 0 | BB1: =SUM(BB5:BB8) -> 81 | BE1: =SUM(BE5:BE8) -> 0 | BF1: =SUM(BF5:BF8) -> 400.95 | BO1: =SUM(BO5:BO8) -> 0 | BQ1: =SUM(BQ5:BQ8) -> 0 | BX1: =SUM(BX5:BX8) -> 0 | CA1: =SUM(CA5:CA8) -> 0 | CB1: =SUM(CB5:CB8) -> 0 | CC1: =SUM(CC5:CC8) -> 400.95
A2: ,1m, | BG2: 尾程运输费 | CC2: 费用合计
A3: 出库指令 | Z3: 物品-拣料及最小包装 | AN3: 拣货&包装费 | AQ3: 拣货续件费 | AT3: 贴标费 | AW3: 包材费-包裹 | AZ3: 装车费 | BC3: 自提附加费 | BF3: 合计 | BG3: 基础费 | BP3: 续重费（超300公斤） | BR3: 附加费 | BY3: 3件包裹以上运输续件费 | CB3: 合计
A4: Order No. | B4: 订单 行数 | C4: 订单数 | D4: 对账 | E4: Warehouse | F4: 月份 | G4: Order Created At | H4: Shipped At | I4: Status | J4: Customer | K4: Original Reference | L4: Business Type | M4: Channel | N4: Creator | O4: 运单数 | P4: Priority | Q4: weight | R4: Carrier | S4: Carrier Return | T4: Shipments No1 | U4: Shipments No2 | V4: Retour No | W4: Postal Code | X4: 城市 | Y4: Country | Z4: Item ID | AA4: 物品描述 | AB4: 物品尺寸 长宽高cm | AC4: 单个物品 重量kg | AD4: Item Batch | AE4: Item Qty | AF4: 订单重量 kg | AG4: PltQty | AH4: PltDim | AI4: PltWeight | AJ4: BoxQty | AK4: BoxDim | AL4: BoxWeight | AM4: 备注 | AN4: 数量 套 | AO4: 单价 Euro | AP4: 金额 Euro | AQ4: 数量 pcs | AR4: 单价 Euro | AS4: 金额 Euro | AT4: 标签/张 | AU4: 单价 | AV4: 金额 | AW4: 数量 pcs | AX4: 单价 Euro | AY4: 金额 Euro | AZ4: 数量 /托 | BA4: 单价 Euro | BB4: 金额 Euro | BC4: 数量 /托 | BD4: 单价 Euro | BE4: 金额 Euro | BF4: 库内小计 | BG4: 数量 票 | BH4: 实际重kg | BI4: 体积重KG | BJ4: 计费 重量 kg | BK4: 邮编所属区域 | BL4: 城市 | BM4: 国家 | BN4: 单价 Euro | BO4: 金额 Euro | BP4: 单价 Euro | BQ4: 金额 Euro | BR4: 运输 订单 管理 * | BS4: 燃油 附加费 * | BT4: 过路 过桥 * | BU4: 运输 保险 | BV4: 预约 通知 * | BW4: 其它 | BX4: 附加费小计 | BY4: 包裹数 个 | BZ4: 单价 Euro | CA4: 金额 Euro | CD4: MIC回复
A5: MO202509230417 | B5: =COUNTIF(A:A,A5) -> 4 | C5: 1 | E5: M | F5: 202509 | G5: 2025-09-23 | H5: 2025-09-29 | I5: Shipped | J5: YCD-EX:HUPPER TEK | K5: ABM0009-250922-0010 | L5: B2B | N5: qianhui.xu@miclogistik.de | O5: 27 | P5: NORMAL | Q5: 15357.6 | R5: Self | Y5: DE | Z5: B07Q3SQT6C | AA5: =VLOOKUP(Z5,物品明细!A:B,2,0) -> 金属储物柜71英寸高 | AB5: =VLOOKUP(Z5,物品明细!A:I,9,0) -> 188x49x14 | AC5: =VLOOKUP(Z5,物品明细!A:D,4,0) -> 47.4 | AE5: 60 | AF5: =AE5*AC5 -> 2844 | AG5: 5 | AH5: 120x80x205 | AI5: 599 | AJ5: 60 | AL5: 47.4 | AM5: 原托整出 | AN5: =AG5 -> 5 | AO5: 11.85 | AP5: =AO5*AN5 -> 59.25 | AS5: =AR5*AQ5 -> 0 | AV5: =AU5*AT5 -> 0 | AY5: =AX5*AW5 -> 0 | AZ5: =AG5 -> 5 | BA5: 3 | BB5: =BA5*AZ5 -> 15 | BE5: =BD5*BC5 -> 0 | BF5: =AP5+AS5+AV5+AY5+BB5+BE5 -> 74.25 | CC5: =BF5+CB5 -> 74.25
A6: MO202509230417 | B6: =COUNTIF(A:A,A6) -> 4 | C6: 0 | E6: M | F6: 202509 | G6: 2025-09-23 | H6: 2025-09-29 | I6: Shipped | J6: YCD-EX:HUPPER TEK | K6: ABM0009-250922-0010 | L6: B2B | N6: qianhui.xu@miclogistik.de | O6: 27 | P6: NORMAL | Q6: 15357.6 | R6: Self | Y6: DE | Z6: B07BK8W5MF | AA6: =VLOOKUP(Z6,物品明细!A:B,2,0) -> 金属储物柜71英寸银色 | AB6: =VLOOKUP(Z6,物品明细!A:I,9,0) -> 188x49x14 | AC6: =VLOOKUP(Z6,物品明细!A:D,4,0) -> 47.4 | AE6: 120 | AF6: =AE6*AC6 -> 5688 | AG6: 10 | AH6: 120x80x205 | AI6: 599 | AJ6: 120 | AL6: 47.4 | AM6: 原托整出 | AN6: =AG6 -> 10 | AO6: 11.85 | AP6: =AO6*AN6 -> 118.5 | AS6: =AR6*AQ6 -> 0 | AV6: =AU6*AT6 -> 0 | AY6: =AX6*AW6 -> 0 | AZ6: =AG6 -> 10 | BA6: 3 | BB6: =BA6*AZ6 -> 30 | BE6: =BD6*BC6 -> 0 | BF6: =AP6+AS6+AV6+AY6+BB6+BE6 -> 148.5 | CC6: =BF6+CB6 -> 148.5
A7: MO202509230417 | B7: =COUNTIF(A:A,A7) -> 4 | C7: 0 | E7: M | F7: 202509 | G7: 2025-09-23 | H7: 2025-09-29 | I7: Shipped | J7: YCD-EX:HUPPER TEK | K7: ABM0009-250922-0010 | L7: B2B | N7: qianhui.xu@miclogistik.de | O7: 27 | P7: NORMAL | Q7: 15357.6 | R7: Self | Y7: DE | Z7: B076THQBHX | AA7: =VLOOKUP(Z7,物品明细!A:B,2,0) -> 金属储物柜71英寸灰色 | AB7: =VLOOKUP(Z7,物品明细!A:I,9,0) -> 188x49x14 | AC7: =VLOOKUP(Z7,物品明细!A:D,4,0) -> 47.4 | AE7: 72 | AF7: =AE7*AC7 -> 3412.8 | AG7: 6 | AH7: 120x80x205 | AI7: 599 | AJ7: 72 | AL7: 47.4 | AM7: 原托整出 | AN7: =AG7 -> 6 | AO7: 11.85 | AP7: =AO7*AN7 -> 71.1 | AS7: =AR7*AQ7 -> 0 | AV7: =AU7*AT7 -> 0 | AY7: =AX7*AW7 -> 0 | AZ7: =AG7 -> 6 | BA7: 3 | BB7: =BA7*AZ7 -> 18 | BE7: =BD7*BC7 -> 0 | BF7: =AP7+AS7+AV7+AY7+BB7+BE7 -> 89.1 | CC7: =BF7+CB7 -> 89.1
A8: MO202509230417 | B8: =COUNTIF(A:A,A8) -> 4 | C8: 0 | E8: M | F8: 202509 | G8: 2025-09-23 | H8: 2025-09-29 | I8: Shipped | J8: YCD-EX:HUPPER TEK | K8: ABM0009-250922-0010 | L8: B2B | N8: qianhui.xu@miclogistik.de | O8: 27 | P8: NORMAL | Q8: 15357.6 | R8: Self | Y8: DE | Z8: B077RVYZRF | AA8: =VLOOKUP(Z8,物品明细!A:B,2,0) -> 德国联邦快递金属储物柜 | AB8: =VLOOKUP(Z8,物品明细!A:I,9,0) -> 188x49x14 | AC8: =VLOOKUP(Z8,物品明细!A:D,4,0) -> 47.4 | AE8: 72 | AF8: =AE8*AC8 -> 3412.8 | AG8: 6 | AH8: 120x80x205 | AI8: 599 | AJ8: 72 | AL8: 47.4 | AM8: 原托整出 | AN8: =AG8 -> 6 | AO8: 11.85 | AP8: =AO8*AN8 -> 71.1 | AS8: =AR8*AQ8 -> 0 | AV8: =AU8*AT8 -> 0 | AY8: =AX8*AW8 -> 0 | AZ8: =AG8 -> 6 | BA8: 3 | BB8: =BA8*AZ8 -> 18 | BE8: =BD8*BC8 -> 0 | BF8: =AP8+AS8+AV8+AY8+BB8+BE8 -> 89.1 | CC8: =BF8+CB8 -> 89.1

Sheet 2.2 正向-2C-GEL
A1: MIC德国海外仓一件代发明细表 | AI1: =SUM(AI5:AI79) -> 392.85 | AL1: =SUM(AL5:AL79) -> 0 | AO1: =SUM(AO5:AO79) -> 0 | AR1: =SUM(AR5:AR79) -> 0 | AU1: =SUM(AU5:AU79) -> 243 | AV1: =SUM(AV5:AV79) -> 635.85 | BE1: =SUM(BE5:BE79) -> 3647.4669 | BJ1: =SUM(BJ5:BJ79) -> 499.6 | BM1: =SUM(BM5:BM79) -> 10 | BN1: =SUM(BN5:BN79) -> 4157.0669 | BO1: =SUM(BO5:BO79) -> 4792.9169
A2: ,1m, | AW2: 尾程运输费 | BO2: 总费用合计
A3: 出库指令 | Z3: 物品-拣料及最小包装 | AG3: 拣货&包装费 | AJ3: 拣货续件费 | AM3: 贴标费 | AP3: 包材费-包裹 | AS3: 装车费 | AV3: 库内小计 | AW3: 基础费 | BF3: 附加费 | BK3: 3件包裹以上运输续件费 | BN3: 尾程费用合计
A4: Order No. | B4: 订单 行数 | C4: 订单数 | D4: 对账 | E4: Warehouse | F4: 月份 | G4: Order Created At | H4: Shipped At | I4: Status | J4: Customer | K4: Original Reference | L4: Business Type | M4: Channel | N4: Creator | O4: 运单数 | P4: Priority | Q4: weight | R4: Carrier | S4: Carrier Return | T4: Shipments No1 | U4: Shipments No2 | V4: Retour No | W4: Postal Code | X4: 城市 | Y4: Country | Z4: Item ID | AA4: 物品描述 | AB4: 物品尺寸 长宽高cm | AC4: 单个物品 重量kg | AD4: Item Batch | AE4: Item Qty | AF4: 订单重量 kg | AG4: 数量 套 | AH4: 单价 Euro | AI4: 金额 Euro | AJ4: 数量 pcs | AK4: 单价 Euro | AL4: 金额 Euro | AM4: 标签/张 | AN4: 单价 | AO4: 金额 | AP4: 数量 pcs | AQ4: 单价 Euro | AR4: 金额 Euro | AS4: 数量 /托 | AT4: 单价 Euro | AU4: 金额 Euro | AW4: 数量 票 | AX4: 实际重kg | AY4: 体积重KG | AZ4: 计费 重量 kg | BA4: 邮编所属区域 | BB4: 城市 | BC4: 国家 | BD4: 单价 Euro | BE4: 金额 Euro | BF4: 运输 订单 管理 * | BG4: 过路 过桥 * | BH4: 预约 通知 * | BI4: 其它 | BJ4: 附加费小计 | BK4: 包裹数 个 | BL4: 单价 Euro | BM4: 金额 Euro | BP4: MIC回复
A5: MO202508290008 | B5: =COUNTIF(A:A,A5) -> 1 | C5: 1 | E5: M | F5: 202509 | G5: 2025-08-29 | H5: 2025-09-01 | I5: Delivered | J5: YCD-EX:HUPPER TEK | K5: PO-076-04297086148472146 | L5: B2C | N5: devindai@huppertek.com | O5: 1 | P5: NORMAL | Q5: 47.4 | R5: GELF-EML_HUPPERTEK | T5: 4618130043 | W5: 91723 | X5: Dittenheim | Y5: DE | Z5: B076THQBHX | AA5: =VLOOKUP(Z5,物品明细!A:B,2,0) -> 金属储物柜71英寸灰色 | AB5: =VLOOKUP(Z5,物品明细!A:I,9,0) -> 188x49x14 | AC5: =VLOOKUP(Z5,物品明细!A:D,4,0) -> 47.4 | AE5: 1 | AF5: =AE5*AC5 -> 47.4 | AG5: =AE5 -> 1 | AH5: 4.85 | AI5: =AH5*AG5 -> 4.85 | AS5: =AE5 -> 1 | AT5: 3 | AU5: =AT58*AS5 -> 3 | AV5: =AI5+AL5+AO5+AR5+AU5 -> 7.85 | AW5: 1 | AX5: 47.4 | AZ5: 50 | BA5: 91723 | BB5: Dittenheim | BC5: DE | BD5: 46.558575 | BE5: =BD5*AW5 -> 46.558575 | BF5: 2.5 | BG5: =AZ5*0.024 -> 1.2 | BH5: 2.5 | BJ5: =SUM(BF5:BI5) -> 6.2 | BN5: =BE5+BJ5+BM5 -> 52.758575 | BO5: =AV5+BN5 -> 60.608575 | BP5: 已对账
A6: MO202508290009 | B6: =COUNTIF(A:A,A6) -> 1 | C6: 1 | E6: M | F6: 202509 | G6: 2025-08-29 | H6: 2025-09-01 | I6: Delivered | J6: YCD-EX:HUPPER TEK | K6: PO-076-04170828474233442 | L6: B2C | N6: devindai@huppertek.com | O6: 1 | P6: NORMAL | Q6: 47.4 | R6: GELF-EML_HUPPERTEK | T6: 4618131309 | W6: 63075 | X6: Offenbach am Main | Y6: DE | Z6: B076THQBHX | AA6: =VLOOKUP(Z6,物品明细!A:B,2,0) -> 金属储物柜71英寸灰色 | AB6: =VLOOKUP(Z6,物品明细!A:I,9,0) -> 188x49x14 | AC6: =VLOOKUP(Z6,物品明细!A:D,4,0) -> 47.4 | AE6: 1 | AF6: =AE6*AC6 -> 47.4 | AG6: =AE6 -> 1 | AH6: 4.85 | AI6: =AH6*AG6 -> 4.85 | AS6: =AE6 -> 1 | AT6: 3 | AU6: =AT59*AS6 -> 3 | AV6: =AI6+AL6+AO6+AR6+AU6 -> 7.85 | AW6: 1 | AX6: 47.4 | AZ6: 50 | BA6: 63075 | BB6: Offenbach am Main | BC6: DE | BD6: 46.558575 | BE6: =BD6*AW6 -> 46.558575 | BF6: 2.5 | BG6: =AZ6*0.024 -> 1.2 | BH6: 2.5 | BJ6: =SUM(BF6:BI6) -> 6.2 | BN6: =BE6+BJ6+BM6 -> 52.758575 | BO6: =AV6+BN6 -> 60.608575 | BP6: 已对账
A7: MO202508290010 | B7: =COUNTIF(A:A,A7) -> 1 | C7: 1 | E7: M | F7: 202509 | G7: 2025-08-29 | H7: 2025-09-01 | I7: Delivery Notify | J7: YCD-EX:HUPPER TEK | K7: PO-076-04557322616951653 | L7: B2C | N7: devindai@huppertek.com | O7: 1 | P7: NORMAL | Q7: 47.4 | R7: GELF-EML_HUPPERTEK | T7: 4618129764 | W7: 93053 | X7: Regensburg | Y7: DE | Z7: B076THQBHX | AA7: =VLOOKUP(Z7,物品明细!A:B,2,0) -> 金属储物柜71英寸灰色 | AB7: =VLOOKUP(Z7,物品明细!A:I,9,0) -> 188x49x14 | AC7: =VLOOKUP(Z7,物品明细!A:D,4,0) -> 47.4 | AE7: 1 | AF7: =AE7*AC7 -> 47.4 | AG7: =AE7 -> 1 | AH7: 4.85 | AI7: =AH7*AG7 -> 4.85 | AS7: =AE7 -> 1 | AT7: 3 | AU7: =AT60*AS7 -> 3 | AV7: =AI7+AL7+AO7+AR7+AU7 -> 7.85 | AW7: 1 | AX7: 47.4 | AZ7: 50 | BA7: 93053 | BB7: Regensburg | BC7: DE | BD7: 46.558575 | BE7: =BD7*AW7 -> 46.558575 | BF7: 2.5 | BG7: =AZ7*0.024 -> 1.2 | BH7: 2.5 | BJ7: =SUM(BF7:BI7) -> 6.2 | BN7: =BE7+BJ7+BM7 -> 52.758575 | BO7: =AV7+BN7 -> 60.608575 | BP7: 已对账
A8: MO202509010338 | B8: =COUNTIF(A:A,A8) -> 1 | C8: 1 | E8: M | F8: 202509 | G8: 2025-09-01 | H8: 2025-09-01 | I8: Delivered | J8: YCD-EX:HUPPER TEK | K8: PO-076-10226771743350626 | L8: B2C | N8: devindai@huppertek.com | O8: 1 | P8: NORMAL | Q8: 47.4 | R8: GELF-EML_HUPPERTEK | S8: RetourHermes_M | T8: 4618131446 | W8: 42551 | X8: Velbert | Y8: DE | Z8: B07BK8W5MF | AA8: =VLOOKUP(Z8,物品明细!A:B,2,0) -> 金属储物柜71英寸银色 | AB8: =VLOOKUP(Z8,物品明细!A:I,9,0) -> 188x49x14 | AC8: =VLOOKUP(Z8,物品明细!A:D,4,0) -> 47.4 | AE8: 1 | AF8: =AE8*AC8 -> 47.4 | AG8: =AE8 -> 1 | AH8: 4.85 | AI8: =AH8*AG8 -> 4.85 | AS8: =AE8 -> 1 | AT8: 3 | AU8: =AT61*AS8 -> 3 | AV8: =AI8+AL8+AO8+AR8+AU8 -> 7.85 | AW8: 1 | AX8: 47.4 | AZ8: 50 | BA8: 42551 | BB8: Velbert | BC8: DE | BD8: 46.558575 | BE8: =BD8*AW8 -> 46.558575 | BF8: 2.5 | BG8: =AZ8*0.024 -> 1.2 | BH8: 2.5 | BJ8: =SUM(BF8:BI8) -> 6.2 | BN8: =BE8+BJ8+BM8 -> 52.758575 | BO8: =AV8+BN8 -> 60.608575 | BP8: 已对账
A9: MO202509010339 | B9: =COUNTIF(A:A,A9) -> 1 | E9: M | F9: 202509 | G9: 2025-09-01 | H9: 2025-09-01 | I9: Canceled | J9: YCD-EX:HUPPER TEK | K9: PO-076-09977348467831059 | L9: B2C | N9: devindai@huppertek.com | O9: 1 | P9: NORMAL | Q9: 47.4 | R9: GELF-EML_HUPPERTEK | S9: RetourHermes_M | W9: 21493 | X9: Schwarzenbek | Y9: DE | Z9: B076THQBHX | AA9: =VLOOKUP(Z9,物品明细!A:B,2,0) -> 金属储物柜71英寸灰色 | AB9: =VLOOKUP(Z9,物品明细!A:I,9,0) -> 188x49x14 | AC9: =VLOOKUP(Z9,物品明细!A:D,4,0) -> 47.4 | AF9: =AE9*AC9 -> 0 | AG9: =AE9 -> 0 | AH9: 4.85 | AI9: =AH9*AG9 -> 0 | AS9: =AE9 -> 0 | AT9: 3 | AU9: =AT62*AS9 -> 0 | AV9: =AI9+AL9+AO9+AR9+AU9 -> 0 | BN9: =BE9+BJ9+BM9 -> 0 | BO9: =AV9+BN9 -> 0 | BP9: 已对账
A10: MO202509010340 | B10: =COUNTIF(A:A,A10) -> 1 | C10: 1 | E10: M | F10: 202509 | G10: 2025-09-01 | H10: 2025-09-01 | I10: Delivered | J10: YCD-EX:HUPPER TEK | K10: PO-076-10182554455670378 | L10: B2C | N10: devindai@huppertek.com | O10: 1 | P10: NORMAL | Q10: 47.4 | R10: GELF-EML_HUPPERTEK | S10: RetourHermes_M | T10: 4618131460 | W10: 97650 | X10: Fladungen | Y10: DE | Z10: B076THQBHX | AA10: =VLOOKUP(Z10,物品明细!A:B,2,0) -> 金属储物柜71英寸灰色 | AB10: =VLOOKUP(Z10,物品明细!A:I,9,0) -> 188x49x14 | AC10: =VLOOKUP(Z10,物品明细!A:D,4,0) -> 47.4 | AE10: 1 | AF10: =AE10*AC10 -> 47.4 | AG10: =AE10 -> 1 | AH10: 4.85 | AI10: =AH10*AG10 -> 4.85 | AS10: =AE10 -> 1 | AT10: 3 | AU10: =AT63*AS10 -> 3 | AV10: =AI10+AL10+AO10+AR10+AU10 -> 7.85 | AW10: 1 | AX10: 47.4 | AZ10: 50 | BA10: 97650 | BB10: Fladungen | BC10: DE | BD10: 46.558575 | BE10: =BD10*AW10 -> 46.558575 | BF10: 2.5 | BG10: =AZ10*0.024 -> 1.2 | BH10: 2.5 | BJ10: =SUM(BF10:BI10) -> 6.2 | BN10: =BE10+BJ10+BM10 -> 52.758575 | BO10: =AV10+BN10 -> 60.608575 | BP10: 已对账
A11: MO202509020002 | B11: =COUNTIF(A:A,A11) -> 1 | C11: 1 | E11: M | F11: 202509 | G11: 2025-09-02 | H11: 2025-09-02 | I11: Delivered | J11: YCD-EX:HUPPER TEK | K11: PO-076-01718713105271130 | L11: B2C | N11: devindai@huppertek.com | O11: 1 | P11: NORMAL | Q11: 47.4 | R11: GELF-EML_HUPPERTEK | T11: 4618148529 | W11: 31840 | X11: Hessisch Oldendorf | Y11: DE | Z11: B076THQBHX | AA11: =VLOOKUP(Z11,物品明细!A:B,2,0) -> 金属储物柜71英寸灰色 | AB11: =VLOOKUP(Z11,物品明细!A:I,9,0) -> 188x49x14 | AC11: =VLOOKUP(Z11,物品明细!A:D,4,0) -> 47.4 | AE11: 1 | AF11: =AE11*AC11 -> 47.4 | AG11: =AE11 -> 1 | AH11: 4.85 | AI11: =AH11*AG11 -> 4.85 | AS11: =AE11 -> 1 | AT11: 3 | AU11: =AT64*AS11 -> 3 | AV11: =AI11+AL11+AO11+AR11+AU11 -> 7.85 | AW11: 1 | AX11: 47.4 | AZ11: 50 | BA11: 31840 | BB11: Hessisch Oldendorf | BC11: DE | BD11: 46.558575 | BE11: =BD11*AW11 -> 46.558575 | BF11: 2.5 | BG11: =AZ11*0.024 -> 1.2 | BH11: 2.5 | BJ11: =SUM(BF11:BI11) -> 6.2 | BN11: =BE11+BJ11+BM11 -> 52.758575 | BO11: =AV11+BN11 -> 60.608575 | BP11: 已对账
A12: MO202509020633 | B12: =COUNTIF(A:A,A12) -> 1 | C12: 1 | E12: M | F12: 202509 | G12: 2025-09-02 | H12: 2025-09-02 | I12: Delivered | J12: YCD-EX:HUPPER TEK | K12: PO-076-12878415094391975-1 | L12: B2C | N12: devindai@huppertek.com | O12: 1 | P12: NORMAL | Q12: 47.4 | R12: GELF-EML_HUPPERTEK | T12: 4618148741 | W12: 23866 | X12: Nahe | Y12: DE | Z12: B07Q3SQT6C | AA12: =VLOOKUP(Z12,物品明细!A:B,2,0) -> 金属储物柜71英寸高 | AB12: =VLOOKUP(Z12,物品明细!A:I,9,0) -> 188x49x14 | AC12: =VLOOKUP(Z12,物品明细!A:D,4,0) -> 47.4 | AE12: 1 | AF12: =AE12*AC12 -> 47.4 | AG12: =AE12 -> 1 | AH12: 4.85 | AI12: =AH12*AG12 -> 4.85 | AS12: =AE12 -> 1 | AT12: 3 | AU12: =AT65*AS12 -> 3 | AV12: =AI12+AL12+AO12+AR12+AU12 -> 7.85 | AW12: 1 | AX12: 47.4 | AZ12: 50 | BA12: 23866 | BB12: Nahe | BC12: DE | BD12: 46.558575 | BE12: =BD12*AW12 -> 46.558575 | BF12: 2.5 | BG12: =AZ12*0.024 -> 1.2 | BH12: 2.5 | BJ12: =SUM(BF12:BI12) -> 6.2 | BN12: =BE12+BJ12+BM12 -> 52.758575 | BO12: =AV12+BN12 -> 60.608575 | BP12: 已对账
A13: MO202509020633-01 | B13: =COUNTIF(A:A,A13) -> 1 | C13: 1 | E13: M | F13: 202509 | G13: 2025-09-02 | H13: 2025-09-02 | I13: Delivered | J13: YCD-EX:HUPPER TEK | K13: PO-076-12878415094391975-2 | L13: B2C | N13: devindai@huppertek.com | O13: 1 | P13: NORMAL | Q13: 47.4 | R13: GELF-EML_HUPPERTEK | T13: 4618148758 | W13: 23866 | X13: Nahe | Y13: DE | Z13: B07Q3SQT6C | AA13: =VLOOKUP(Z13,物品明细!A:B,2,0) -> 金属储物柜71英寸高 | AB13: =VLOOKUP(Z13,物品明细!A:I,9,0) -> 188x49x14 | AC13: =VLOOKUP(Z13,物品明细!A:D,4,0) -> 47.4 | AE13: 1 | AF13: =AE13*AC13 -> 47.4 | AG13: =AE13 -> 1 | AH13: 4.85 | AI13: =AH13*AG13 -> 4.85 | AS13: =AE13 -> 1 | AT13: 3 | AU13: =AT66*AS13 -> 3 | AV13: =AI13+AL13+AO13+AR13+AU13 -> 7.85 | AW13: 1 | AX13: 47.4 | AZ13: 50 | BA13: 23866 | BB13: Nahe | BC13: DE | BD13: 46.558575 | BE13: =BD13*AW13 -> 46.558575 | BF13: 2.5 | BG13: =AZ13*0.024 -> 1.2 | BH13: 2.5 | BJ13: =SUM(BF13:BI13) -> 6.2 | BN13: =BE13+BJ13+BM13 -> 52.758575 | BO13: =AV13+BN13 -> 60.608575 | BP13: 已对账
A14: MO202509030202 | B14: =COUNTIF(A:A,A14) -> 1 | C14: 1 | E14: M | F14: 202509 | G14: 2025-09-03 | H14: 2025-09-03 | I14: Shipped | J14: YCD-EX:HUPPER TEK | K14: PO-076-12612912981112500 | L14: B2C | N14: devindai@huppertek.com | O14: 1 | P14: NORMAL | Q14: 47.4 | R14: GELF-EML_HUPPERTEK | S14: RetourHermes_M | T14: 4618152489 | W14: 63776 | X14: Mömbris | Y14: DE | Z14: B07BK8W5MF | AA14: =VLOOKUP(Z14,物品明细!A:B,2,0) -> 金属储物柜71英寸银色 | AB14: =VLOOKUP(Z14,物品明细!A:I,9,0) -> 188x49x14 | AC14: =VLOOKUP(Z14,物品明细!A:D,4,0) -> 47.4 | AE14: 1 | AF14: =AE14*AC14 -> 47.4 | AG14: =AE14 -> 1 | AH14: 4.85 | AI14: =AH14*AG14 -> 4.85 | AS14: =AE14 -> 1 | AT14: 3 | AU14: =AT67*AS14 -> 3 | AV14: =AI14+AL14+AO14+AR14+AU14 -> 7.85 | AW14: 1 | AX14: 47.4 | AZ14: 50 | BA14: 63776 | BB14: Mömbris | BC14: DE | BD14: 46.558575 | BE14: =BD14*AW14 -> 46.558575 | BF14: 2.5 | BG14: =AZ14*0.024 -> 1.2 | BH14: 2.5 | BJ14: =SUM(BF14:BI14) -> 6.2 | BN14: =BE14+BJ14+BM14 -> 52.758575 | BO14: =AV14+BN14 -> 60.608575 | BP14: 已对账
A15: MO202509030203 | B15: =COUNTIF(A:A,A15) -> 1 | C15: 1 | E15: M | F15: 202509 | G15: 2025-09-03 | H15: 2025-09-03 | I15: Shipped | J15: YCD-EX:HUPPER TEK | K15: PO-076-12903771914870030 | L15: B2C | N15: devindai@huppertek.com | O15: 1 | P15: NORMAL | Q15: 47.4 | R15: GELF-EML_HUPPERTEK | S15: RetourHermes_M | T15: 4618152496 | W15: 90765 | X15: Fürth | Y15: DE | Z15: B077RVYZRF | AA15: =VLOOKUP(Z15,物品明细!A:B,2,0) -> 德国联邦快递金属储物柜 | AB15: =VLOOKUP(Z15,物品明细!A:I,9,0) -> 188x49x14 | AC15: =VLOOKUP(Z15,物品明细!A:D,4,0) -> 47.4 | AE15: 1 | AF15: =AE15*AC15 -> 47.4 | AG15: =AE15 -> 1 | AH15: 4.85 | AI15: =AH15*AG15 -> 4.85 | AS15: =AE15 -> 1 | AT15: 3 | AU15: =AT68*AS15 -> 3 | AV15: =AI15+AL15+AO15+AR15+AU15 -> 7.85 | AW15: 1 | AX15: 47.4 | AZ15: 50 | BA15: 90765 | BB15: Fürth | BC15: DE | BD15: 46.558575 | BE15: =BD15*AW15 -> 46.558575 | BF15: 2.5 | BG15: =AZ15*0.024 -> 1.2 | BH15: 2.5 | BJ15: =SUM(BF15:BI15) -> 6.2 | BN15: =BE15+BJ15+BM15 -> 52.758575 | BO15: =AV15+BN15 -> 60.608575 | BP15: 已对账
A16: MO202509030204 | B16: =COUNTIF(A:A,A16) -> 1 | C16: 1 | E16: M | F16: 202509 | G16: 2025-09-03 | H16: 2025-09-03 | I16: Shipped | J16: YCD-EX:HUPPER TEK | K16: PO-076-12499994650233943 | L16: B2C | N16: devindai@huppertek.com | O16: 1 | P16: NORMAL | Q16: 47.4 | R16: GELF-EML_HUPPERTEK | S16: RetourHermes_M | T16: 4618152502 | W16: 70794 | X16: Filderstadt | Y16: DE | Z16: B07Q3SQT6C | AA16: =VLOOKUP(Z16,物品明细!A:B,2,0) -> 金属储物柜71英寸高 | AB16: =VLOOKUP(Z16,物品明细!A:I,9,0) -> 188x49x14 | AC16: =VLOOKUP(Z16,物品明细!A:D,4,0) -> 47.4 | AE16: 1 | AF16: =AE16*AC16 -> 47.4 | AG16: =AE16 -> 1 | AH16: 4.85 | AI16: =AH16*AG16 -> 4.85 | AS16: =AE16 -> 1 | AT16: 3 | AU16: =AT69*AS16 -> 3 | AV16: =AI16+AL16+AO16+AR16+AU16 -> 7.85 | AW16: 1 | AX16: 47.4 | AZ16: 50 | BA16: 70794 | BB16: Filderstadt | BC16: DE | BD16: 46.558575 | BE16: =BD16*AW16 -> 46.558575 | BF16: 2.5 | BG16: =AZ16*0.024 -> 1.2 | BH16: 2.5 | BJ16: =SUM(BF16:BI16) -> 6.2 | BN16: =BE16+BJ16+BM16 -> 52.758575 | BO16: =AV16+BN16 -> 60.608575 | BP16: 已对账
A17: MO202509030363 | B17: =COUNTIF(A:A,A17) -> 1 | C17: 1 | E17: M | F17: 202509 | G17: 2025-09-03 | H17: 2025-09-03 | I17: Shipped | J17: YCD-EX:HUPPER TEK | K17: 11-13526-16962 | L17: B2C | N17: devindai@huppertek.com | O17: 1 | P17: NORMAL | Q17: 47.4 | R17: GELF_HUPPERTEK | S17: RetourHermes_M | T17: 4618154933 | W17: 40670 | X17: Meerbusch | Y17: DE | Z17: B07BK8W5MF | AA17: =VLOOKUP(Z17,物品明细!A:B,2,0) -> 金属储物柜71英寸银色 | AB17: =VLOOKUP(Z17,物品明细!A:I,9,0) -> 188x49x14 | AC17: =VLOOKUP(Z17,物品明细!A:D,4,0) -> 47.4 | AE17: 1 | AF17: =AE17*AC17 -> 47.4 | AG17: =AE17 -> 1 | AH17: 4.85 | AI17: =AH17*AG17 -> 4.85 | AS17: =AE17 -> 1 | AT17: 3 | AU17: =AT70*AS17 -> 3 | AV17: =AI17+AL17+AO17+AR17+AU17 -> 7.85 | AW17: 1 | AX17: 47.4 | AZ17: 50 | BA17: 40670 | BB17: Meerbusch | BC17: DE | BD17: 46.558575 | BE17: =BD17*AW17 -> 46.558575 | BF17: 2.5 | BG17: =AZ17*0.024 -> 1.2 | BH17: 2.5 | BJ17: =SUM(BF17:BI17) -> 6.2 | BN17: =BE17+BJ17+BM17 -> 52.758575 | BO17: =AV17+BN17 -> 60.608575 | BP17: 已对账
A18: MO202509040286 | B18: =COUNTIF(A:A,A18) -> 1 | C18: 1 | E18: M | F18: 202509 | G18: 2025-09-04 | H18: 2025-09-04 | I18: Shipped | J18: YCD-EX:HUPPER TEK | K18: PO-076-18014211876473843 | L18: B2C | N18: devindai@huppertek.com | O18: 1 | P18: NORMAL | Q18: 47.4 | R18: GELF-EML_HUPPERTEK | T18: 4618159570 | W18: 93170 | X18: Bernhardswald | Y18: DE | Z18: B076THQBHX | AA18: =VLOOKUP(Z18,物品明细!A:B,2,0) -> 金属储物柜71英寸灰色 | AB18: =VLOOKUP(Z18,物品明细!A:I,9,0) -> 188x49x14 | AC18: =VLOOKUP(Z18,物品明细!A:D,4,0) -> 47.4 | AE18: 1 | AF18: =AE18*AC18 -> 47.4 | AG18: =AE18 -> 1 | AH18: 4.85 | AI18: =AH18*AG18 -> 4.85 | AS18: =AE18 -> 1 | AT18: 3 | AU18: =AT71*AS18 -> 3 | AV18: =AI18+AL18+AO18+AR18+AU18 -> 7.85 | AW18: 1 | AX18: 47.4 | AZ18: 50 | BA18: 93170 | BB18: Bernhardswald | BC18: DE | BD18: 46.558575 | BE18: =BD18*AW18 -> 46.558575 | BF18: 2.5 | BG18: =AZ18*0.024 -> 1.2 | BH18: 2.5 | BJ18: =SUM(BF18:BI18) -> 6.2 | BN18: =BE18+BJ18+BM18 -> 52.758575 | BO18: =AV18+BN18 -> 60.608575 | BP18: 已对账
A19: MO202509080347 | B19: =COUNTIF(A:A,A19) -> 1 | C19: 1 | E19: M | F19: 202509 | G19: 2025-09-08 | H19: 2025-09-09 | I19: ReadyToShip | J19: YCD-EX:HUPPER TEK | K19: 12-13542-95015 | L19: B2C | N19: devindai@huppertek.com | O19: 2 | P19: NORMAL | Q19: 47.4 | R19: GELF_HUPPERTEK | S19: RetourHermes_M | T19: 4618174160 4618174177 | U19: 4618174160 4618174177 | W19: 46117 | X19: Oberhausen | Y19: DE | Z19: B07BK8W5MF | AA19: =VLOOKUP(Z19,物品明细!A:B,2,0) -> 金属储物柜71英寸银色 | AB19: =VLOOKUP(Z19,物品明细!A:I,9,0) -> 188x49x14 | AC19: =VLOOKUP(Z19,物品明细!A:D,4,0) -> 47.4 | AE19: 2 | AF19: =AE19*AC19 -> 94.8 | AG19: =AE19 -> 2 | AH19: 4.85 | AI19: =AH19*AG19 -> 9.7 | AL19: =AK19*AJ19 -> 0 | AS19: =AE19 -> 2 | AT19: 3 | AU19: =AT72*AS19 -> 6 | AV19: =AI19+AL19+AO19+AR19+AU19 -> 15.7 | AW19: 1 | AX19: 47.4 | AZ19: 100 | BA19: 46117 | BB19: Oberhausen | BC19: DE | BD19: 78.354675 | BE19: =BD19*AW19 -> 78.354675 | BF19: 2.5 | BG19: =AZ19*0.024 -> 2.4 | BH19: 2.5 | BJ19: =SUM(BF19:BI19) -> 7.4 | BN19: =BE19+BJ19+BM19 -> 85.754675 | BO19: =AV19+BN19 -> 101.45467 | BP19: 已对账
A20: MO202509080584 | B20: =COUNTIF(A:A,A20) -> 1 | C20: 1 | E20: M | F20: 202509 | G20: 2025-09-08 | H20: 2025-09-08 | I20: Shipped | J20: YCD-EX:HUPPER TEK | K20: PO-076-09412637668471865 | L20: B2C | N20: devindai@huppertek.com | O20: 1 | P20: NORMAL | Q20: 47.4 | R20: GELF-EML_HUPPERTEK | S20: RetourHermes_M | T20: 4618172968 | W20: 84405 | X20: Dorfen | Y20: DE | Z20: B07Q3SQT6C | AA20: =VLOOKUP(Z20,物品明细!A:B,2,0) -> 金属储物柜71英寸高 | AB20: =VLOOKUP(Z20,物品明细!A:I,9,0) -> 188x49x14 | AC20: =VLOOKUP(Z20,物品明细!A:D,4,0) -> 47.4 | AE20: 1 | AF20: =AE20*AC20 -> 47.4 | AG20: =AE20 -> 1 | AH20: 4.85 | AI20: =AH20*AG20 -> 4.85 | AS20: =AE20 -> 1 | AT20: 3 | AU20: =AT73*AS20 -> 3 | AV20: =AI20+AL20+AO20+AR20+AU20 -> 7.85 | AW20: 1 | AX20: 47.4 | AZ20: 50 | BA20: 84405 | BB20: Dorfen | BC20: DE | BD20: 46.558575 | BE20: =BD20*AW20 -> 46.558575 | BF20: 2.5 | BG20: =AZ20*0.024 -> 1.2 | BH20: 2.5 | BJ20: =SUM(BF20:BI20) -> 6.2 | BN20: =BE20+BJ20+BM20 -> 52.758575 | BO20: =AV20+BN20 -> 60.608575 | BP20: 已对账
A21: MO202509080585 | B21: =COUNTIF(A:A,A21) -> 1 | C21: 1 | E21: M | F21: 202509 | G21: 2025-09-08 | H21: 2025-09-08 | I21: Shipped | J21: YCD-EX:HUPPER TEK | K21: PO-076-09080733322873843 | L21: B2C | N21: devindai@huppertek.com | O21: 1 | P21: NORMAL | Q21: 47.4 | R21: GELF-EML_HUPPERTEK | S21: RetourHermes_M | T21: 4618172951 | W21: 93170 | X21: Bernhardswald | Y21: DE | Z21: B07BK8W5MF | AA21: =VLOOKUP(Z21,物品明细!A:B,2,0) -> 金属储物柜71英寸银色 | AB21: =VLOOKUP(Z21,物品明细!A:I,9,0) -> 188x49x14 | AC21: =VLOOKUP(Z21,物品明细!A:D,4,0) -> 47.4 | AE21: 1 | AF21: =AE21*AC21 -> 47.4 | AG21: =AE21 -> 1 | AH21: 4.85 | AI21: =AH21*AG21 -> 4.85 | AS21: =AE21 -> 1 | AT21: 3 | AU21: =AT74*AS21 -> 3 | AV21: =AI21+AL21+AO21+AR21+AU21 -> 7.85 | AW21: 1 | AX21: 47.4 | AZ21: 50 | BA21: 93170 | BB21: Bernhardswald | BC21: DE | BD21: 46.558575 | BE21: =BD21*AW21 -> 46.558575 | BF21: 2.5 | BG21: =AZ21*0.024 -> 1.2 | BH21: 2.5 | BJ21: =SUM(BF21:BI21) -> 6.2 | BN21: =BE21+BJ21+BM21 -> 52.758575 | BO21: =AV21+BN21 -> 60.608575 | BP21: 已对账
A22: MO202509080586 | B22: =COUNTIF(A:A,A22) -> 1 | C22: 1 | E22: M | F22: 202509 | G22: 2025-09-08 | H22: 2025-09-08 | I22: Shipped | J22: YCD-EX:HUPPER TEK | K22: PO-076-14513305964153460 | L22: B2C | N22: devindai@huppertek.com | O22: 1 | P22: NORMAL | Q22: 47.4 | R22: GELF-EML_HUPPERTEK | S22: RetourHermes_M | T22: 4618172944 | W22: 80933 | X22: München | Y22: DE | Z22: B077RVYZRF | AA22: =VLOOKUP(Z22,物品明细!A:B,2,0) -> 德国联邦快递金属储物柜 | AB22: =VLOOKUP(Z22,物品明细!A:I,9,0) -> 188x49x14 | AC22: =VLOOKUP(Z22,物品明细!A:D,4,0) -> 47.4 | AE22: 1 | AF22: =AE22*AC22 -> 47.4 | AG22: =AE22 -> 1 | AH22: 4.85 | AI22: =AH22*AG22 -> 4.85 | AS22: =AE22 -> 1 | AT22: 3 | AU22: =AT75*AS22 -> 3 | AV22: =AI22+AL22+AO22+AR22+AU22 -> 7.85 | AW22: 1 | AX22: 47.4 | AZ22: 50 | BA22: 80933 | BB22: München | BC22: DE | BD22: 46.558575 | BE22: =BD22*AW22 -> 46.558575 | BF22: 2.5 | BG22: =AZ22*0.024 -> 1.2 | BH22: 2.5 | BI22: 7.8 | BJ22: =SUM(BF22:BI22) -> 14 | BN22: =BE22+BJ22+BM22 -> 60.558575 | BO22: =AV22+BN22 -> 68.408575 | BP22: 已对账
A23: MO202509080587 | B23: =COUNTIF(A:A,A23) -> 1 | C23: 1 | E23: M | F23: 202509 | G23: 2025-09-08 | H23: 2025-09-08 | I23: Shipped | J23: YCD-EX:HUPPER TEK | K23: PO-076-15048957921910524 | L23: B2C | N23: devindai@huppertek.com | O23: 1 | P23: NORMAL | Q23: 47.4 | R23: GELF-EML_HUPPERTEK | S23: RetourHermes_M | T23: 4618172937 | W23: 14656 | X23: Brieselang | Y23: DE | Z23: B07Q3SQT6C | AA23: =VLOOKUP(Z23,物品明细!A:B,2,0) -> 金属储物柜71英寸高 | AB23: =VLOOKUP(Z23,物品明细!A:I,9,0) -> 188x49x14 | AC23: =VLOOKUP(Z23,物品明细!A:D,4,0) -> 47.4 | AE23: 1 | AF23: =AE23*AC23 -> 47.4 | AG23: =AE23 -> 1 | AH23: 4.85 | AI23: =AH23*AG23 -> 4.85 | AS23: =AE23 -> 1 | AT23: 3 | AU23: =AT76*AS23 -> 3 | AV23: =AI23+AL23+AO23+AR23+AU23 -> 7.85 | AW23: 1 | AX23: 47.4 | AZ23: 50 | BA23: 14656 | BB23: Brieselang | BC23: DE | BD23: 46.558575 | BE23: =BD23*AW23 -> 46.558575 | BF23: 2.5 | BG23: =AZ23*0.024 -> 1.2 | BH23: 2.5 | BJ23: =SUM(BF23:BI23) -> 6.2 | BN23: =BE23+BJ23+BM23 -> 52.758575 | BO23: =AV23+BN23 -> 60.608575 | BP23: 已对账
A24: MO202509080588 | B24: =COUNTIF(A:A,A24) -> 1 | C24: 1 | E24: M | F24: 202509 | G24: 2025-09-08 | H24: 2025-09-08 | I24: Shipped | J24: YCD-EX:HUPPER TEK | K24: PO-076-14897119923831719 | L24: B2C | N24: devindai@huppertek.com | O24: 1 | P24: NORMAL | Q24: 47.4 | R24: GELF-EML_HUPPERTEK | S24: RetourHermes_M | T24: 4618172920 | W24: 88427 | X24: Bad Schussenried | Y24: DE | Z24: B07Q3SQT6C | AA24: =VLOOKUP(Z24,物品明细!A:B,2,0) -> 金属储物柜71英寸高 | AB24: =VLOOKUP(Z24,物品明细!A:I,9,0) -> 188x49x14 | AC24: =VLOOKUP(Z24,物品明细!A:D,4,0) -> 47.4 | AE24: 1 | AF24: =AE24*AC24 -> 47.4 | AG24: =AE24 -> 1 | AH24: 4.85 | AI24: =AH24*AG24 -> 4.85 | AS24: =AE24 -> 1 | AT24: 3 | AU24: =AT77*AS24 -> 3 | AV24: =AI24+AL24+AO24+AR24+AU24 -> 7.85 | AW24: 1 | AX24: 47.4 | AZ24: 50 | BA24: 88427 | BB24: Bad Schussenried | BC24: DE | BD24: 46.558575 | BE24: =BD24*AW24 -> 46.558575 | BF24: 2.5 | BG24: =AZ24*0.024 -> 1.2 | BH24: 2.5 | BJ24: =SUM(BF24:BI24) -> 6.2 | BN24: =BE24+BJ24+BM24 -> 52.758575 | BO24: =AV24+BN24 -> 60.608575 | BP24: 已对账
A25: MO202509090010 | B25: =COUNTIF(A:A,A25) -> 1 | C25: 1 | E25: M | F25: 202509 | G25: 2025-09-09 | H25: 2025-09-09 | I25: Delivered | J25: YCD-EX:HUPPER TEK | K25: PO-076-20390142055031744 | L25: B2C | N25: devindai@huppertek.com | O25: 1 | P25: NORMAL | Q25: 47.4 | R25: GELF-EML_HUPPERTEK | T25: 4618180710 | W25: 92552 | X25: Teunz | Y25: DE | Z25: B07BK8W5MF | AA25: =VLOOKUP(Z25,物品明细!A:B,2,0) -> 金属储物柜71英寸银色 | AB25: =VLOOKUP(Z25,物品明细!A:I,9,0) -> 188x49x14 | AC25: =VLOOKUP(Z25,物品明细!A:D,4,0) -> 47.4 | AE25: 1 | AF25: =AE25*AC25 -> 47.4 | AG25: =AE25 -> 1 | AH25: 4.85 | AI25: =AH25*AG25 -> 4.85 | AL25: =AK25*AJ25 -> 0 | AO25: =AN25*AM25 -> 0 | AR25: =AQ25*AP25 -> 0 | AS25: =O25 -> 1 | AT25: 3 | AU25: =AT25*AS25 -> 3 | AV25: =AI25+AL25+AO25+AR25+AU25 -> 7.85 | AW25: 1 | AX25: =AF25 -> 47.4 | AZ25: 50 | BA25: =W25 -> 92552 | BB25: =X25 -> Teunz | BC25: =Y25 -> DE | BD25: 46.558575 | BE25: =AW25*BD25 -> 46.558575 | BF25: 2.5 | BG25: =0.024*AZ25 -> 1.2 | BH25: 2.5 | BJ25: =SUM(BF25:BI25) -> 6.2 | BM25: =BK25*BL25 -> 0 | BN25: =BE25+BJ25+BM25 -> 52.758575 | BO25: =AV25+BN25 -> 60.608575
A26: MO202509150298 | B26: =COUNTIF(A:A,A26) -> 1 | C26: 1 | D26: Y | E26: M | F26: 202509 | G26: 2025-09-15 | H26: 2025-09-15 | I26: Delivered | J26: YCD-EX:HUPPER TEK | K26: ABM0009-250915-0019 | L26: B2C | N26: devindai@huppertek.com | O26: 1 | P26: NORMAL | Q26: 47.4 | R26: GELF_HUPPERTEK | S26: RetourHermes_M | T26: 4618199057 | W26: 79418 | X26: schliengen | Y26: DE | Z26: B07BK8W5MF | AA26: =VLOOKUP(Z26,物品明细!A:B,2,0) -> 金属储物柜71英寸银色 | AB26: =VLOOKUP(Z26,物品明细!A:I,9,0) -> 188x49x14 | AC26: =VLOOKUP(Z26,物品明细!A:D,4,0) -> 47.4 | AE26: 1 | AF26: =AE26*AC26 -> 47.4 | AG26: =AE26 -> 1 | AH26: 4.85 | AI26: =AH26*AG26 -> 4.85 | AL26: =AK26*AJ26 -> 0 | AO26: =AN26*AM26 -> 0 | AR26: =AQ26*AP26 -> 0 | AS26: =O26 -> 1 | AT26: 3 | AU26: =AT26*AS26 -> 3 | AV26: =AI26+AL26+AO26+AR26+AU26 -> 7.85 | AW26: 1 | AX26: =AF26 -> 47.4 | AZ26: 50 | BA26: =W26 -> 79418 | BB26: =X26 -> schliengen | BC26: =Y26 -> DE | BD26: 46.558575 | BE26: =AW26*BD26 -> 46.558575 | BF26: 2.5 | BG26: =0.024*AZ26 -> 1.2 | BH26: 2.5 | BJ26: =SUM(BF26:BI26) -> 6.2 | BM26: =BK26*BL26 -> 0 | BN26: =BE26+BJ26+BM26 -> 52.758575 | BO26: =AV26+BN26 -> 60.608575
A27: MO202509150299 | B27: =COUNTIF(A:A,A27) -> 1 | C27: 1 | D27: Y | E27: M | F27: 202509 | G27: 2025-09-15 | H27: 2025-09-15 | I27: Delivered | J27: YCD-EX:HUPPER TEK | K27: ABM0009-250915-0018 | L27: B2C | N27: devindai@huppertek.com | O27: 1 | P27: NORMAL | Q27: 47.4 | R27: GELF_HUPPERTEK | S27: RetourHermes_M | T27: 4618199040 | W27: 44809 | X27: Bochum | Y27: DE | Z27: B07Q3SQT6C | AA27: =VLOOKUP(Z27,物品明细!A:B,2,0) -> 金属储物柜71英寸高 | AB27: =VLOOKUP(Z27,物品明细!A:I,9,0) -> 188x49x14 | AC27: =VLOOKUP(Z27,物品明细!A:D,4,0) -> 47.4 | AE27: 1 | AF27: =AE27*AC27 -> 47.4 | AG27: =AE27 -> 1 | AH27: 4.85 | AI27: =AH27*AG27 -> 4.85 | AL27: =AK27*AJ27 -> 0 | AO27: =AN27*AM27 -> 0 | AR27: =AQ27*AP27 -> 0 | AS27: =O27 -> 1 | AT27: 3 | AU27: =AT27*AS27 -> 3 | AV27: =AI27+AL27+AO27+AR27+AU27 -> 7.85 | AW27: 1 | AX27: =AF27 -> 47.4 | AZ27: 50 | BA27: =W27 -> 44809 | BB27: =X27 -> Bochum | BC27: =Y27 -> DE | BD27: 46.558575 | BE27: =AW27*BD27 -> 46.558575 | BF27: 2.5 | BG27: =0.024*AZ27 -> 1.2 | BH27: 2.5 | BJ27: =SUM(BF27:BI27) -> 6.2 | BM27: =BK27*BL27 -> 0 | BN27: =BE27+BJ27+BM27 -> 52.758575 | BO27: =AV27+BN27 -> 60.608575
A28: MO202509150300 | B28: =COUNTIF(A:A,A28) -> 1 | C28: 1 | D28: Y | E28: M | F28: 202509 | G28: 2025-09-15 | H28: 2025-09-15 | I28: Delivered | J28: YCD-EX:HUPPER TEK | K28: ABM0009-250915-0017 | L28: B2C | N28: devindai@huppertek.com | O28: 1 | P28: NORMAL | Q28: 47.4 | R28: GELF_HUPPERTEK | S28: RetourHermes_M | T28: 4618199033 | W28: 59399 | X28: Olfen | Y28: DE | Z28: B076THQBHX | AA28: =VLOOKUP(Z28,物品明细!A:B,2,0) -> 金属储物柜71英寸灰色 | AB28: =VLOOKUP(Z28,物品明细!A:I,9,0) -> 188x49x14 | AC28: =VLOOKUP(Z28,物品明细!A:D,4,0) -> 47.4 | AE28: 1 | AF28: =AE28*AC28 -> 47.4 | AG28: =AE28 -> 1 | AH28: 4.85 | AI28: =AH28*AG28 -> 4.85 | AL28: =AK28*AJ28 -> 0 | AO28: =AN28*AM28 -> 0 | AR28: =AQ28*AP28 -> 0 | AS28: =O28 -> 1 | AT28: 3 | AU28: =AT28*AS28 -> 3 | AV28: =AI28+AL28+AO28+AR28+AU28 -> 7.85 | AW28: 1 | AX28: =AF28 -> 47.4 | AZ28: 50 | BA28: =W28 -> 59399 | BB28: =X28 -> Olfen | BC28: =Y28 -> DE | BD28: 46.558575 | BE28: =AW28*BD28 -> 46.558575 | BF28: 2.5 | BG28: =0.024*AZ28 -> 1.2 | BH28: 2.5 | BJ28: =SUM(BF28:BI28) -> 6.2 | BM28: =BK28*BL28 -> 0 | BN28: =BE28+BJ28+BM28 -> 52.758575 | BO28: =AV28+BN28 -> 60.608575
A29: ABM0009-250915-0016 | B29: =COUNTIF(A:A,A29) -> 1 | C29: 1 | D29: Y | E29: M | F29: 202509 | G29: 2025-09-15 | H29: 2025-09-15 | I29: Delivered | J29: YCD-EX:HUPPER TEK | K29: ABM0009-250915-0016 | L29: B2C | N29: rossmo@miclogistik.de | O29: 1 | P29: NORMAL | Q29: 47.4 | R29: GELF-EML_HUPPERTEK | S29: RetourHermes_M | T29: 4618207998 | W29: 71665 | X29: Vaihingen an der Enz | Y29: DE | Z29: B07Q3SQT6C | AA29: =VLOOKUP(Z29,物品明细!A:B,2,0) -> 金属储物柜71英寸高 | AB29: =VLOOKUP(Z29,物品明细!A:I,9,0) -> 188x49x14 | AC29: =VLOOKUP(Z29,物品明细!A:D,4,0) -> 47.4 | AE29: 1 | AF29: =AE29*AC29 -> 47.4 | AG29: =AE29 -> 1 | AH29: 4.85 | AI29: =AH29*AG29 -> 4.85 | AL29: =AK29*AJ29 -> 0 | AO29: =AN29*AM29 -> 0 | AR29: =AQ29*AP29 -> 0 | AS29: =O29 -> 1 | AT29: 3 | AU29: =AT29*AS29 -> 3 | AV29: =AI29+AL29+AO29+AR29+AU29 -> 7.85 | AW29: 1 | AX29: =AF29 -> 47.4 | AZ29: 50 | BA29: =W29 -> 71665 | BB29: =X29 -> Vaihingen an der Enz | BC29: =Y29 -> DE | BD29: 46.558575 | BE29: =AW29*BD29 -> 46.558575 | BF29: 2.5 | BG29: =0.024*AZ29 -> 1.2 | BH29: 2.5 | BJ29: =SUM(BF29:BI29) -> 6.2 | BM29: =BK29*BL29 -> 0 | BN29: =BE29+BJ29+BM29 -> 52.758575 | BO29: =AV29+BN29 -> 60.608575
A30: ABM0009-250915-0015 | B30: =COUNTIF(A:A,A30) -> 1 | C30: 1 | D30: Y | E30: M | F30: 202509 | G30: 2025-09-15 | H30: 2025-09-15 | I30: Delivered | J30: YCD-EX:HUPPER TEK | K30: ABM0009-250915-0015 | L30: B2C | N30: rossmo@miclogistik.de | O30: 1 | P30: NORMAL | Q30: 47.4 | R30: GELF-EML_HUPPERTEK | S30: RetourHermes_M | T30: 4618207981 | W30: 33609 | X30: Bielefeld | Y30: DE | Z30: B076THQBHX | AA30: =VLOOKUP(Z30,物品明细!A:B,2,0) -> 金属储物柜71英寸灰色 | AB30: =VLOOKUP(Z30,物品明细!A:I,9,0) -> 188x49x14 | AC30: =VLOOKUP(Z30,物品明细!A:D,4,0) -> 47.4 | AE30: 1 | AF30: =AE30*AC30 -> 47.4 | AG30: =AE30 -> 1 | AH30: 4.85 | AI30: =AH30*AG30 -> 4.85 | AL30: =AK30*AJ30 -> 0 | AO30: =AN30*AM30 -> 0 | AR30: =AQ30*AP30 -> 0 | AS30: =O30 -> 1 | AT30: 3 | AU30: =AT30*AS30 -> 3 | AV30: =AI30+AL30+AO30+AR30+AU30 -> 7.85 | AW30: 1 | AX30: =AF30 -> 47.4 | AZ30: 50 | BA30: =W30 -> 33609 | BB30: =X30 -> Bielefeld | BC30: =Y30 -> DE | BD30: 46.558575 | BE30: =AW30*BD30 -> 46.558575 | BF30: 2.5 | BG30: =0.024*AZ30 -> 1.2 | BH30: 2.5 | BJ30: =SUM(BF30:BI30) -> 6.2 | BM30: =BK30*BL30 -> 0 | BN30: =BE30+BJ30+BM30 -> 52.758575 | BO30: =AV30+BN30 -> 60.608575
A31: ABM0009-250915-0014 | B31: =COUNTIF(A:A,A31) -> 1 | C31: 1 | D31: Y | E31: M | F31: 202509 | G31: 2025-09-15 | H31: 2025-09-15 | I31: Delivered | J31: YCD-EX:HUPPER TEK | K31: ABM0009-250915-0014 | L31: B2C | N31: rossmo@miclogistik.de | O31: 1 | P31: NORMAL | Q31: 47.4 | R31: GELF-EML_HUPPERTEK | S31: RetourHermes_M | T31: 4618207974 | W31: 24963 | X31: Tarp | Y31: DE | Z31: B07Q3SQT6C | AA31: =VLOOKUP(Z31,物品明细!A:B,2,0) -> 金属储物柜71英寸高 | AB31: =VLOOKUP(Z31,物品明细!A:I,9,0) -> 188x49x14 | AC31: =VLOOKUP(Z31,物品明细!A:D,4,0) -> 47.4 | AE31: 1 | AF31: =AE31*AC31 -> 47.4 | AG31: =AE31 -> 1 | AH31: 4.85 | AI31: =AH31*AG31 -> 4.85 | AL31: =AK31*AJ31 -> 0 | AO31: =AN31*AM31 -> 0 | AR31: =AQ31*AP31 -> 0 | AS31: =O31 -> 1 | AT31: 3 | AU31: =AT31*AS31 -> 3 | AV31: =AI31+AL31+AO31+AR31+AU31 -> 7.85 | AW31: 1 | AX31: =AF31 -> 47.4 | AZ31: 50 | BA31: =W31 -> 24963 | BB31: =X31 -> Tarp | BC31: =Y31 -> DE | BD31: 46.558575 | BE31: =AW31*BD31 -> 46.558575 | BF31: 2.5 | BG31: =0.024*AZ31 -> 1.2 | BH31: 2.5 | BJ31: =SUM(BF31:BI31) -> 6.2 | BM31: =BK31*BL31 -> 0 | BN31: =BE31+BJ31+BM31 -> 52.758575 | BO31: =AV31+BN31 -> 60.608575
A32: ABM0009-250915-0013 | B32: =COUNTIF(A:A,A32) -> 1 | C32: 1 | D32: Y | E32: M | F32: 202509 | G32: 2025-09-15 | H32: 2025-09-15 | I32: Delivered | J32: YCD-EX:HUPPER TEK | K32: ABM0009-250915-0013 | L32: B2C | N32: rossmo@miclogistik.de | O32: 1 | P32: NORMAL | Q32: 47.4 | R32: GELF-EML_HUPPERTEK | S32: RetourHermes_M | T32: 4618207967 | W32: 99996 | X32: Unstruttal | Y32: DE | Z32: B07BK8W5MF | AA32: =VLOOKUP(Z32,物品明细!A:B,2,0) -> 金属储物柜71英寸银色 | AB32: =VLOOKUP(Z32,物品明细!A:I,9,0) -> 188x49x14 | AC32: =VLOOKUP(Z32,物品明细!A:D,4,0) -> 47.4 | AE32: 1 | AF32: =AE32*AC32 -> 47.4 | AG32: =AE32 -> 1 | AH32: 4.85 | AI32: =AH32*AG32 -> 4.85 | AL32: =AK32*AJ32 -> 0 | AO32: =AN32*AM32 -> 0 | AR32: =AQ32*AP32 -> 0 | AS32: =O32 -> 1 | AT32: 3 | AU32: =AT32*AS32 -> 3 | AV32: =AI32+AL32+AO32+AR32+AU32 -> 7.85 | AW32: 1 | AX32: =AF32 -> 47.4 | AZ32: 50 | BA32: =W32 -> 99996 | BB32: =X32 -> Unstruttal | BC32: =Y32 -> DE | BD32: 46.558575 | BE32: =AW32*BD32 -> 46.558575 | BF32: 2.5 | BG32: =0.024*AZ32 -> 1.2 | BH32: 2.5 | BJ32: =SUM(BF32:BI32) -> 6.2 | BM32: =BK32*BL32 -> 0 | BN32: =BE32+BJ32+BM32 -> 52.758575 | BO32: =AV32+BN32 -> 60.608575
A33: ABM0009-250915-0012 | B33: =COUNTIF(A:A,A33) -> 1 | C33: 1 | D33: Y | E33: M | F33: 202509 | G33: 2025-09-15 | H33: 2025-09-15 | I33: Delivered | J33: YCD-EX:HUPPER TEK | K33: ABM0009-250915-0012 | L33: B2C | N33: rossmo@miclogistik.de | O33: 1 | P33: NORMAL | Q33: 47.4 | R33: GELF-EML_HUPPERTEK | S33: RetourHermes_M | T33: 4618207950 | W33: 33378 | X33: Rheda-Wiedenbrück | Y33: DE | Z33: B07Q3SQT6C | AA33: =VLOOKUP(Z33,物品明细!A:B,2,0) -> 金属储物柜71英寸高 | AB33: =VLOOKUP(Z33,物品明细!A:I,9,0) -> 188x49x14 | AC33: =VLOOKUP(Z33,物品明细!A:D,4,0) -> 47.4 | AE33: 1 | AF33: =AE33*AC33 -> 47.4 | AG33: =AE33 -> 1 | AH33: 4.85 | AI33: =AH33*AG33 -> 4.85 | AL33: =AK33*AJ33 -> 0 | AO33: =AN33*AM33 -> 0 | AR33: =AQ33*AP33 -> 0 | AS33: =O33 -> 1 | AT33: 3 | AU33: =AT33*AS33 -> 3 | AV33: =AI33+AL33+AO33+AR33+AU33 -> 7.85 | AW33: 1 | AX33: =AF33 -> 47.4 | AZ33: 50 | BA33: =W33 -> 33378 | BB33: =X33 -> Rheda-Wiedenbrück | BC33: =Y33 -> DE | BD33: 46.558575 | BE33: =AW33*BD33 -> 46.558575 | BF33: 2.5 | BG33: =0.024*AZ33 -> 1.2 | BH33: 2.5 | BJ33: =SUM(BF33:BI33) -> 6.2 | BM33: =BK33*BL33 -> 0 | BN33: =BE33+BJ33+BM33 -> 52.758575 | BO33: =AV33+BN33 -> 60.608575
A34: ABM0009-250915-0011 | B34: =COUNTIF(A:A,A34) -> 1 | C34: 1 | D34: Y | E34: M | F34: 202509 | G34: 2025-09-15 | H34: 2025-09-15 | I34: Delivered | J34: YCD-EX:HUPPER TEK | K34: ABM0009-250915-0011 | L34: B2C | N34: rossmo@miclogistik.de | O34: 1 | P34: NORMAL | Q34: 47.4 | R34: GELF-EML_HUPPERTEK | S34: RetourHermes_M | T34: 4618207943 | W34: 77694 | X34: Kehl | Y34: DE | Z34: B076THQBHX | AA34: =VLOOKUP(Z34,物品明细!A:B,2,0) -> 金属储物柜71英寸灰色 | AB34: =VLOOKUP(Z34,物品明细!A:I,9,0) -> 188x49x14 | AC34: =VLOOKUP(Z34,物品明细!A:D,4,0) -> 47.4 | AE34: 1 | AF34: =AE34*AC34 -> 47.4 | AG34: =AE34 -> 1 | AH34: 4.85 | AI34: =AH34*AG34 -> 4.85 | AL34: =AK34*AJ34 -> 0 | AO34: =AN34*AM34 -> 0 | AR34: =AQ34*AP34 -> 0 | AS34: =O34 -> 1 | AT34: 3 | AU34: =AT34*AS34 -> 3 | AV34: =AI34+AL34+AO34+AR34+AU34 -> 7.85 | AW34: 1 | AX34: =AF34 -> 47.4 | AZ34: 50 | BA34: =W34 -> 77694 | BB34: =X34 -> Kehl | BC34: =Y34 -> DE | BD34: 46.558575 | BE34: =AW34*BD34 -> 46.558575 | BF34: 2.5 | BG34: =0.024*AZ34 -> 1.2 | BH34: 2.5 | BJ34: =SUM(BF34:BI34) -> 6.2 | BM34: =BK34*BL34 -> 0 | BN34: =BE34+BJ34+BM34 -> 52.758575 | BO34: =AV34+BN34 -> 60.608575
A35: ABM0009-250915-0010 | B35: =COUNTIF(A:A,A35) -> 1 | C35: 1 | D35: Y | E35: M | F35: 202509 | G35: 2025-09-15 | H35: 2025-09-15 | I35: Delivered | J35: YCD-EX:HUPPER TEK | K35: ABM0009-250915-0010 | L35: B2C | N35: rossmo@miclogistik.de | O35: 1 | P35: NORMAL | Q35: 47.4 | R35: GELF-EML_HUPPERTEK | S35: RetourHermes_M | T35: 4618207936 | W35: 91616 | X35: Neusitz | Y35: DE | Z35: B076THQBHX | AA35: =VLOOKUP(Z35,物品明细!A:B,2,0) -> 金属储物柜71英寸灰色 | AB35: =VLOOKUP(Z35,物品明细!A:I,9,0) -> 188x49x14 | AC35: =VLOOKUP(Z35,物品明细!A:D,4,0) -> 47.4 | AE35: 1 | AF35: =AE35*AC35 -> 47.4 | AG35: =AE35 -> 1 | AH35: 4.85 | AI35: =AH35*AG35 -> 4.85 | AL35: =AK35*AJ35 -> 0 | AO35: =AN35*AM35 -> 0 | AR35: =AQ35*AP35 -> 0 | AS35: =O35 -> 1 | AT35: 3 | AU35: =AT35*AS35 -> 3 | AV35: =AI35+AL35+AO35+AR35+AU35 -> 7.85 | AW35: 1 | AX35: =AF35 -> 47.4 | AZ35: 50 | BA35: =W35 -> 91616 | BB35: =X35 -> Neusitz | BC35: =Y35 -> DE | BD35: 46.558575 | BE35: =AW35*BD35 -> 46.558575 | BF35: 2.5 | BG35: =0.024*AZ35 -> 1.2 | BH35: 2.5 | BJ35: =SUM(BF35:BI35) -> 6.2 | BM35: =BK35*BL35 -> 0 | BN35: =BE35+BJ35+BM35 -> 52.758575 | BO35: =AV35+BN35 -> 60.608575
A36: ABM0009-250915-0009 | B36: =COUNTIF(A:A,A36) -> 1 | C36: 1 | D36: Y | E36: M | F36: 202509 | G36: 2025-09-15 | H36: 2025-09-15 | I36: Delivered | J36: YCD-EX:HUPPER TEK | K36: ABM0009-250915-0009 | L36: B2C | N36: rossmo@miclogistik.de | O36: 1 | P36: NORMAL | Q36: 47.4 | R36: GELF-EML_HUPPERTEK | S36: RetourHermes_M | T36: 4618207929 | W36: 37120 | X36: Bovenden | Y36: DE | Z36: B076THQBHX | AA36: =VLOOKUP(Z36,物品明细!A:B,2,0) -> 金属储物柜71英寸灰色 | AB36: =VLOOKUP(Z36,物品明细!A:I,9,0) -> 188x49x14 | AC36: =VLOOKUP(Z36,物品明细!A:D,4,0) -> 47.4 | AE36: 1 | AF36: =AE36*AC36 -> 47.4 | AG36: =AE36 -> 1 | AH36: 4.85 | AI36: =AH36*AG36 -> 4.85 | AL36: =AK36*AJ36 -> 0 | AO36: =AN36*AM36 -> 0 | AR36: =AQ36*AP36 -> 0 | AS36: =O36 -> 1 | AT36: 3 | AU36: =AT36*AS36 -> 3 | AV36: =AI36+AL36+AO36+AR36+AU36 -> 7.85 | AW36: 1 | AX36: =AF36 -> 47.4 | AZ36: 50 | BA36: =W36 -> 37120 | BB36: =X36 -> Bovenden | BC36: =Y36 -> DE | BD36: 46.558575 | BE36: =AW36*BD36 -> 46.558575 | BF36: 2.5 | BG36: =0.024*AZ36 -> 1.2 | BH36: 2.5 | BJ36: =SUM(BF36:BI36) -> 6.2 | BM36: =BK36*BL36 -> 0 | BN36: =BE36+BJ36+BM36 -> 52.758575 | BO36: =AV36+BN36 -> 60.608575
A37: ABM0009-250915-0008 | B37: =COUNTIF(A:A,A37) -> 1 | C37: 1 | D37: Y | E37: M | F37: 202509 | G37: 2025-09-15 | H37: 2025-09-15 | I37: Delivered | J37: YCD-EX:HUPPER TEK | K37: ABM0009-250915-0008 | L37: B2C | N37: rossmo@miclogistik.de | O37: 1 | P37: NORMAL | Q37: 47.4 | R37: GELF-EML_HUPPERTEK | S37: RetourHermes_M | T37: 4618207912 | W37: 1662 | X37: Meißen | Y37: DE | Z37: B076THQBHX | AA37: =VLOOKUP(Z37,物品明细!A:B,2,0) -> 金属储物柜71英寸灰色 | AB37: =VLOOKUP(Z37,物品明细!A:I,9,0) -> 188x49x14 | AC37: =VLOOKUP(Z37,物品明细!A:D,4,0) -> 47.4 | AE37: 1 | AF37: =AE37*AC37 -> 47.4 | AG37: =AE37 -> 1 | AH37: 4.85 | AI37: =AH37*AG37 -> 4.85 | AL37: =AK37*AJ37 -> 0 | AO37: =AN37*AM37 -> 0 | AR37: =AQ37*AP37 -> 0 | AS37: =O37 -> 1 | AT37: 3 | AU37: =AT37*AS37 -> 3 | AV37: =AI37+AL37+AO37+AR37+AU37 -> 7.85 | AW37: 1 | AX37: =AF37 -> 47.4 | AZ37: 50 | BA37: =W37 -> 1662 | BB37: =X37 -> Meißen | BC37: =Y37 -> DE | BD37: 46.558575 | BE37: =AW37*BD37 -> 46.558575 | BF37: 2.5 | BG37: =0.024*AZ37 -> 1.2 | BH37: 2.5 | BJ37: =SUM(BF37:BI37) -> 6.2 | BM37: =BK37*BL37 -> 0 | BN37: =BE37+BJ37+BM37 -> 52.758575 | BO37: =AV37+BN37 -> 60.608575
A38: ABM0009-250916-0003 | B38: =COUNTIF(A:A,A38) -> 1 | C38: 1 | D38: Y | E38: M | F38: 202509 | G38: 2025-09-16 | H38: 2025-09-16 | I38: Delivered | J38: YCD-EX:HUPPER TEK | K38: ABM0009-250916-0003 | L38: B2C | N38: rossmo@miclogistik.de | O38: 2 | P38: NORMAL | Q38: 94.8 | R38: GELF-EML_HUPPERTEK | S38: RetourHermes_M | T38: 4618214088 4618214095 | U38: 4618214088 4618214095 | W38: 72461 | X38: Albstadt | Y38: DE | Z38: B076THQBHX | AA38: =VLOOKUP(Z38,物品明细!A:B,2,0) -> 金属储物柜71英寸灰色 | AB38: =VLOOKUP(Z38,物品明细!A:I,9,0) -> 188x49x14 | AC38: =VLOOKUP(Z38,物品明细!A:D,4,0) -> 47.4 | AE38: 2 | AF38: =AE38*AC38 -> 94.8 | AG38: =AE38 -> 2 | AH38: 4.85 | AI38: =AH38*AG38 -> 9.7 | AL38: =AK38*AJ38 -> 0 | AO38: =AN38*AM38 -> 0 | AR38: =AQ38*AP38 -> 0 | AS38: =O38 -> 2 | AT38: 3 | AU38: =AT38*AS38 -> 6 | AV38: =AI38+AL38+AO38+AR38+AU38 -> 15.7 | AW38: 1 | AX38: =AF38 -> 94.8 | AZ38: 100 | BA38: =W38 -> 72461 | BB38: =X38 -> Albstadt | BC38: =Y38 -> DE | BD38: 78.354675 | BE38: =AW38*BD38 -> 78.354675 | BF38: 2.5 | BG38: =0.024*AZ38 -> 2.4 | BH38: 2.5 | BJ38: =SUM(BF38:BI38) -> 7.4 | BM38: =BK38*BL38 -> 0 | BN38: =BE38+BJ38+BM38 -> 85.754675 | BO38: =AV38+BN38 -> 101.45467
A39: ABM0009-250917-0004 | B39: =COUNTIF(A:A,A39) -> 1 | C39: 1 | D39: Y | E39: M | F39: 202509 | G39: 2025-09-17 | H39: 2025-09-18 | I39: Delivered | J39: YCD-EX:HUPPER TEK | K39: ABM0009-250917-0004 | L39: B2C | N39: rossmo@miclogistik.de | O39: 1 | P39: NORMAL | Q39: 47.4 | R39: GELF-EML_HUPPERTEK | S39: RetourHermes_M | T39: 4618219007 | W39: 86860 | X39: Jengen | Y39: DE | Z39: B07Q3SQT6C | AA39: =VLOOKUP(Z39,物品明细!A:B,2,0) -> 金属储物柜71英寸高 | AB39: =VLOOKUP(Z39,物品明细!A:I,9,0) -> 188x49x14 | AC39: =VLOOKUP(Z39,物品明细!A:D,4,0) -> 47.4 | AE39: 1 | AF39: =AE39*AC39 -> 47.4 | AG39: =AE39 -> 1 | AH39: 4.85 | AI39: =AH39*AG39 -> 4.85 | AL39: =AK39*AJ39 -> 0 | AO39: =AN39*AM39 -> 0 | AR39: =AQ39*AP39 -> 0 | AS39: =O39 -> 1 | AT39: 3 | AU39: =AT39*AS39 -> 3 | AV39: =AI39+AL39+AO39+AR39+AU39 -> 7.85 | AW39: 1 | AX39: =AF39 -> 47.4 | AZ39: 50 | BA39: =W39 -> 86860 | BB39: =X39 -> Jengen | BC39: =Y39 -> DE | BD39: 46.558575 | BE39: =AW39*BD39 -> 46.558575 | BF39: 2.5 | BG39: =0.024*AZ39 -> 1.2 | BH39: 2.5 | BJ39: =SUM(BF39:BI39) -> 6.2 | BM39: =BK39*BL39 -> 0 | BN39: =BE39+BJ39+BM39 -> 52.758575 | BO39: =AV39+BN39 -> 60.608575
A40: ABM0009-250917-0003 | B40: =COUNTIF(A:A,A40) -> 1 | C40: 1 | D40: Y | E40: M | F40: 202509 | G40: 2025-09-17 | H40: 2025-09-18 | I40: Delivered | J40: YCD-EX:HUPPER TEK | K40: ABM0009-250917-0003 | L40: B2C | N40: rossmo@miclogistik.de | O40: 1 | P40: NORMAL | Q40: 47.4 | R40: GELF-EML_HUPPERTEK | S40: RetourHermes_M | T40: 4618219038 | W40: 94405 | X40: Landau a.d.Isar | Y40: DE | Z40: B07BK8W5MF | AA40: =VLOOKUP(Z40,物品明细!A:B,2,0) -> 金属储物柜71英寸银色 | AB40: =VLOOKUP(Z40,物品明细!A:I,9,0) -> 188x49x14 | AC40: =VLOOKUP(Z40,物品明细!A:D,4,0) -> 47.4 | AE40: 1 | AF40: =AE40*AC40 -> 47.4 | AG40: =AE40 -> 1 | AH40: 4.85 | AI40: =AH40*AG40 -> 4.85 | AL40: =AK40*AJ40 -> 0 | AO40: =AN40*AM40 -> 0 | AR40: =AQ40*AP40 -> 0 | AS40: =O40 -> 1 | AT40: 3 | AU40: =AT40*AS40 -> 3 | AV40: =AI40+AL40+AO40+AR40+AU40 -> 7.85 | AW40: 1 | AX40: =AF40 -> 47.4 | AZ40: 50 | BA40: =W40 -> 94405 | BB40: =X40 -> Landau a.d.Isar | BC40: =Y40 -> DE | BD40: 46.558575 | BE40: =AW40*BD40 -> 46.558575 | BF40: 2.5 | BG40: =0.024*AZ40 -> 1.2 | BH40: 2.5 | BJ40: =SUM(BF40:BI40) -> 6.2 | BM40: =BK40*BL40 -> 0 | BN40: =BE40+BJ40+BM40 -> 52.758575 | BO40: =AV40+BN40 -> 60.608575
...

Sheet 3.1 正向-普货-仓储费 
AP1: =SUM(AP6:AP10000) -> 674.82506
A2: 计费时间IStorage Charge Date | C2: 入仓信息Inbound Information | I2: 商品信息Product Information | Q2: 装箱信息 | V2: 打托信息 | AA2: 原始入仓数量 | AE2: 进销存信息 | AJ2: 仓储费计费信息/Storage Charge Infromation | AQ2: 备注
A3: 月份 | B3: 日期 | C3: 仓库名称 | D3: 仓库编码 | E3: 客户代码 | F3: 入库任务号 | G3: 原始参考号 | H3: 入库上架时间 | I3: 编码 | J3: 条码 | K3: 商品名称 | L3: 件型 | M3: 长 | N3: 宽 | O3: 高 | P3: 单品体积A | Q3: 装箱数 | R3: 长 | S3: 宽 | T3: 高 | U3: 单箱体积B | V3: 打托数 | W3: 长 | X3: 宽 | Y3: 高 | Z3: 单托体积C | AA3: 托数 | AB3: 箱数 | AC3: 总数 | AD3: 批次号 | AE3: 期初库存数 | AF3: 入库数 | AG3: 出库数 | AH3: 期末库存数 | AI3: 计费单元 | AJ3: 库存体积E | AK3: 实际计费体积F | AL3: 库龄 | AM3: 库龄段 | AN3: 计费单价 | AO3: 币种 | AP3: 仓储费
A4: / | B4: / | C4: / | D4: / | E4: / | F4: / | G4: / | H4: / | I4: / | J4: / | K4: / | M4: cm | N4: cm | O4: cm | P4: CBM/m³ | Q4: pcs | R4: cm | S4: cm | T4: cm | U4: CBM/m³ | V4: pcs/box | W4: cm | X4: cm | Y4: cm | Z4: CBM/m³ | AA4: 托/Pallet | AB4: 箱/Box | AC4: 件/pcs | AE4: 件/pcs | AF4: 件/pcs | AG4: 件/pcs | AH4: 件/pcs | AI4: pcs/box/pallet | AJ4: CBM/m³ | AK4: CBM/m³ | AL4: 天/day | AM4: 天/day | AN4: / | AO4: Euro | AP4: Euro
A5: Month | B5: Date | C5: Warehouse Name | D5: Warehouse Code | E5: Client Code | F5: Task No. | G5: Original Ref. No. | H5: Inbound Time | I5: SKU | J5: Barcode | K5: Product Name | L5: Product Type | M5: Lenth | N5: Width | O5: Height | P5: Product Volume-A | Q5: Qty per Box | R5: Lenth | S5: Width | T5: Height | U5: Box Volume-B | V5: Qty per Pallet | W5: Lenth | X5: Width | Y5: Height | Z5: Pallet Volume-B | AA5: Qty of Pallet | AB5: Qty of Carton | AC5: Total Qty. | AD5: Batch No. | AE5: Beginning Inv | AF5: Inbound | AG5: Outbound | AH5: Ending Inv. | AI5: Charge Unit | AJ5: INV Volume-E | AK5: Charge Volume-F | AL5: Storage Age | AM5: Storage Age Range | AN5: Charge Price | AO5: Curreny | AP5: Storage Amount | AQ5: Rermar
A6: 202509 | B6: 45901 | C6: MIC德国仓 | D6: M » N2 - 1 | E6: YCD-EX:HUPPER TEK | F6: MI202508130012 | G6: DE2508031-G7-MIC | H6: 45889 | I6: B07BK8W5MF | K6: =VLOOKUP(I6,物品明细!A:B,2,0) -> 金属储物柜71英寸银色 | M6: =VLOOKUP(I6,物品明细!A:E,5,0) -> 188 | N6: =VLOOKUP(I6,物品明细!A:F,6,0) -> 49 | O6: =VLOOKUP(I6,物品明细!A:G,7,0) -> 14 | P6: =M6*N6*O6/1000000 -> 0.128968 | R6: =VLOOKUP(I6,物品明细!A:E,5,0) -> 188 | S6: =VLOOKUP(I6,物品明细!A:F,6,0) -> 49 | T6: =VLOOKUP(I6,物品明细!A:G,7,0) -> 14 | U6: =R6*S6*T6/1000000 -> 0.128968 | AA6: 21 | AB6: 247 | AC6: 247 | AD6: 0 | AE6: 247 | AG6: 1 | AH6: =AE6+AF6-AG6 -> 246 | AI6: pcs | AJ6: =AH6*P6 -> 31.726128 | AK6: =AJ6 -> 31.726128 | AL6: =B6-H6+1 -> 13 | AM6: =IF(AL6<=0,"0天",IF(AL6<=30,"30天内",IF(AL6<=90,"31-90天","91天以上"))) -> 30天内 | AN6: =IF(AM6="0天",0,IF(AM6="30天内",0,IF(AM6="31-90天",0.6,1))) -> 0 | AO6: Euro | AP6: =AK6*AN6 -> 0
A7: 202509 | B7: 45902 | C7: MIC德国仓 | D7: =D6 -> M » N2 - 1 | E7: =E6 -> YCD-EX:HUPPER TEK | F7: =F6 -> MI202508130012 | G7: =G6 -> DE2508031-G7-MIC | H7: =H6 -> 45889 | I7: =I6 -> B07BK8W5MF | K7: =K6 -> 金属储物柜71英寸银色 | M7: =M6 -> 188 | N7: =N6 -> 49 | O7: =O6 -> 14 | P7: =M7*N7*O7/1000000 -> 0.128968 | R7: =R6 -> 188 | S7: =S6 -> 49 | T7: =T6 -> 14 | U7: =R7*S7*T7/1000000 -> 0.128968 | AA7: =AA6 -> 21 | AB7: =AB6 -> 247 | AC7: =AC6 -> 247 | AD7: 0 | AE7: =AH6 -> 246 | AH7: =AE7+AF7-AG7 -> 246 | AI7: pcs | AJ7: =AH7*P7 -> 31.726128 | AK7: =AJ7 -> 31.726128 | AL7: =B7-H7+1 -> 14 | AM7: =IF(AL7<=0,"0天",IF(AL7<=30,"30天内",IF(AL7<=90,"31-90天","91天以上"))) -> 30天内 | AN7: =IF(AM7="0天",0,IF(AM7="30天内",0,IF(AM7="31-90天",0.6,1))) -> 0 | AO7: Euro | AP7: =AK7*AN7 -> 0
A8: 202509 | B8: 45903 | C8: MIC德国仓 | D8: =D7 -> M » N2 - 1 | E8: =E7 -> YCD-EX:HUPPER TEK | F8: =F7 -> MI202508130012 | G8: =G7 -> DE2508031-G7-MIC | H8: =H7 -> 45889 | I8: =I7 -> B07BK8W5MF | K8: =K7 -> 金属储物柜71英寸银色 | M8: =M7 -> 188 | N8: =N7 -> 49 | O8: =O7 -> 14 | P8: =M8*N8*O8/1000000 -> 0.128968 | R8: =R7 -> 188 | S8: =S7 -> 49 | T8: =T7 -> 14 | U8: =R8*S8*T8/1000000 -> 0.128968 | AA8: =AA7 -> 21 | AB8: =AB7 -> 247 | AC8: =AC7 -> 247 | AD8: 0 | AE8: =AH7 -> 246 | AG8: 2 | AH8: =AE8+AF8-AG8 -> 244 | AI8: pcs | AJ8: =AH8*P8 -> 31.468192 | AK8: =AJ8 -> 31.468192 | AL8: =B8-H8+1 -> 15 | AM8: =IF(AL8<=0,"0天",IF(AL8<=30,"30天内",IF(AL8<=90,"31-90天","91天以上"))) -> 30天内 | AN8: =IF(AM8="0天",0,IF(AM8="30天内",0,IF(AM8="31-90天",0.6,1))) -> 0 | AO8: Euro | AP8: =AK8*AN8 -> 0
A9: 202509 | B9: 45904 | C9: MIC德国仓 | D9: =D8 -> M » N2 - 1 | E9: =E8 -> YCD-EX:HUPPER TEK | F9: =F8 -> MI202508130012 | G9: =G8 -> DE2508031-G7-MIC | H9: =H8 -> 45889 | I9: =I8 -> B07BK8W5MF | K9: =K8 -> 金属储物柜71英寸银色 | M9: =M8 -> 188 | N9: =N8 -> 49 | O9: =O8 -> 14 | P9: =M9*N9*O9/1000000 -> 0.128968 | R9: =R8 -> 188 | S9: =S8 -> 49 | T9: =T8 -> 14 | U9: =R9*S9*T9/1000000 -> 0.128968 | AA9: =AA8 -> 21 | AB9: =AB8 -> 247 | AC9: =AC8 -> 247 | AD9: 0 | AE9: =AH8 -> 244 | AH9: =AE9+AF9-AG9 -> 244 | AI9: pcs | AJ9: =AH9*P9 -> 31.468192 | AK9: =AJ9 -> 31.468192 | AL9: =B9-H9+1 -> 16 | AM9: =IF(AL9<=0,"0天",IF(AL9<=30,"30天内",IF(AL9<=90,"31-90天","91天以上"))) -> 30天内 | AN9: =IF(AM9="0天",0,IF(AM9="30天内",0,IF(AM9="31-90天",0.6,1))) -> 0 | AO9: Euro | AP9: =AK9*AN9 -> 0
A10: 202509 | B10: 45905 | C10: MIC德国仓 | D10: =D9 -> M » N2 - 1 | E10: =E9 -> YCD-EX:HUPPER TEK | F10: =F9 -> MI202508130012 | G10: =G9 -> DE2508031-G7-MIC | H10: =H9 -> 45889 | I10: =I9 -> B07BK8W5MF | K10: =K9 -> 金属储物柜71英寸银色 | M10: =M9 -> 188 | N10: =N9 -> 49 | O10: =O9 -> 14 | P10: =M10*N10*O10/1000000 -> 0.128968 | R10: =R9 -> 188 | S10: =S9 -> 49 | T10: =T9 -> 14 | U10: =R10*S10*T10/1000000 -> 0.128968 | AA10: =AA9 -> 21 | AB10: =AB9 -> 247 | AC10: =AC9 -> 247 | AD10: 0 | AE10: =AH9 -> 244 | AH10: =AE10+AF10-AG10 -> 244 | AI10: pcs | AJ10: =AH10*P10 -> 31.468192 | AK10: =AJ10 -> 31.468192 | AL10: =B10-H10+1 -> 17 | AM10: =IF(AL10<=0,"0天",IF(AL10<=30,"30天内",IF(AL10<=90,"31-90天","91天以上"))) -> 30天内 | AN10: =IF(AM10="0天",0,IF(AM10="30天内",0,IF(AM10="31-90天",0.6,1))) -> 0 | AO10: Euro | AP10: =AK10*AN10 -> 0
A11: 202509 | B11: 45906 | C11: MIC德国仓 | D11: =D10 -> M » N2 - 1 | E11: =E10 -> YCD-EX:HUPPER TEK | F11: =F10 -> MI202508130012 | G11: =G10 -> DE2508031-G7-MIC | H11: =H10 -> 45889 | I11: =I10 -> B07BK8W5MF | K11: =K10 -> 金属储物柜71英寸银色 | M11: =M10 -> 188 | N11: =N10 -> 49 | O11: =O10 -> 14 | P11: =M11*N11*O11/1000000 -> 0.128968 | R11: =R10 -> 188 | S11: =S10 -> 49 | T11: =T10 -> 14 | U11: =R11*S11*T11/1000000 -> 0.128968 | AA11: =AA10 -> 21 | AB11: =AB10 -> 247 | AC11: =AC10 -> 247 | AD11: 0 | AE11: =AH10 -> 244 | AH11: =AE11+AF11-AG11 -> 244 | AI11: pcs | AJ11: =AH11*P11 -> 31.468192 | AK11: =AJ11 -> 31.468192 | AL11: =B11-H11+1 -> 18 | AM11: =IF(AL11<=0,"0天",IF(AL11<=30,"30天内",IF(AL11<=90,"31-90天","91天以上"))) -> 30天内 | AN11: =IF(AM11="0天",0,IF(AM11="30天内",0,IF(AM11="31-90天",0.6,1))) -> 0 | AO11: Euro | AP11: =AK11*AN11 -> 0
A12: 202509 | B12: 45907 | C12: MIC德国仓 | D12: =D11 -> M » N2 - 1 | E12: =E11 -> YCD-EX:HUPPER TEK | F12: =F11 -> MI202508130012 | G12: =G11 -> DE2508031-G7-MIC | H12: =H11 -> 45889 | I12: =I11 -> B07BK8W5MF | K12: =K11 -> 金属储物柜71英寸银色 | M12: =M11 -> 188 | N12: =N11 -> 49 | O12: =O11 -> 14 | P12: =M12*N12*O12/1000000 -> 0.128968 | R12: =R11 -> 188 | S12: =S11 -> 49 | T12: =T11 -> 14 | U12: =R12*S12*T12/1000000 -> 0.128968 | AA12: =AA11 -> 21 | AB12: =AB11 -> 247 | AC12: =AC11 -> 247 | AD12: 0 | AE12: =AH11 -> 244 | AH12: =AE12+AF12-AG12 -> 244 | AI12: pcs | AJ12: =AH12*P12 -> 31.468192 | AK12: =AJ12 -> 31.468192 | AL12: =B12-H12+1 -> 19 | AM12: =IF(AL12<=0,"0天",IF(AL12<=30,"30天内",IF(AL12<=90,"31-90天","91天以上"))) -> 30天内 | AN12: =IF(AM12="0天",0,IF(AM12="30天内",0,IF(AM12="31-90天",0.6,1))) -> 0 | AO12: Euro | AP12: =AK12*AN12 -> 0
A13: 202509 | B13: 45908 | C13: MIC德国仓 | D13: =D12 -> M » N2 - 1 | E13: =E12 -> YCD-EX:HUPPER TEK | F13: =F12 -> MI202508130012 | G13: =G12 -> DE2508031-G7-MIC | H13: =H12 -> 45889 | I13: =I12 -> B07BK8W5MF | K13: =K12 -> 金属储物柜71英寸银色 | M13: =M12 -> 188 | N13: =N12 -> 49 | O13: =O12 -> 14 | P13: =M13*N13*O13/1000000 -> 0.128968 | R13: =R12 -> 188 | S13: =S12 -> 49 | T13: =T12 -> 14 | U13: =R13*S13*T13/1000000 -> 0.128968 | AA13: =AA12 -> 21 | AB13: =AB12 -> 247 | AC13: =AC12 -> 247 | AD13: 0 | AE13: =AH12 -> 244 | AG13: 1 | AH13: =AE13+AF13-AG13 -> 243 | AI13: pcs | AJ13: =AH13*P13 -> 31.339224 | AK13: =AJ13 -> 31.339224 | AL13: =B13-H13+1 -> 20 | AM13: =IF(AL13<=0,"0天",IF(AL13<=30,"30天内",IF(AL13<=90,"31-90天","91天以上"))) -> 30天内 | AN13: =IF(AM13="0天",0,IF(AM13="30天内",0,IF(AM13="31-90天",0.6,1))) -> 0 | AO13: Euro | AP13: =AK13*AN13 -> 0
A14: 202509 | B14: 45909 | C14: MIC德国仓 | D14: =D13 -> M » N2 - 1 | E14: =E13 -> YCD-EX:HUPPER TEK | F14: =F13 -> MI202508130012 | G14: =G13 -> DE2508031-G7-MIC | H14: =H13 -> 45889 | I14: =I13 -> B07BK8W5MF | K14: =K13 -> 金属储物柜71英寸银色 | M14: =M13 -> 188 | N14: =N13 -> 49 | O14: =O13 -> 14 | P14: =M14*N14*O14/1000000 -> 0.128968 | R14: =R13 -> 188 | S14: =S13 -> 49 | T14: =T13 -> 14 | U14: =R14*S14*T14/1000000 -> 0.128968 | AA14: =AA13 -> 21 | AB14: =AB13 -> 247 | AC14: =AC13 -> 247 | AD14: 0 | AE14: =AH13 -> 243 | AG14: 3 | AH14: =AE14+AF14-AG14 -> 240 | AI14: pcs | AJ14: =AH14*P14 -> 30.95232 | AK14: =AJ14 -> 30.95232 | AL14: =B14-H14+1 -> 21 | AM14: =IF(AL14<=0,"0天",IF(AL14<=30,"30天内",IF(AL14<=90,"31-90天","91天以上"))) -> 30天内 | AN14: =IF(AM14="0天",0,IF(AM14="30天内",0,IF(AM14="31-90天",0.6,1))) -> 0 | AO14: Euro | AP14: =AK14*AN14 -> 0
A15: 202509 | B15: 45910 | C15: MIC德国仓 | D15: =D14 -> M » N2 - 1 | E15: =E14 -> YCD-EX:HUPPER TEK | F15: =F14 -> MI202508130012 | G15: =G14 -> DE2508031-G7-MIC | H15: =H14 -> 45889 | I15: =I14 -> B07BK8W5MF | K15: =K14 -> 金属储物柜71英寸银色 | M15: =M14 -> 188 | N15: =N14 -> 49 | O15: =O14 -> 14 | P15: =M15*N15*O15/1000000 -> 0.128968 | R15: =R14 -> 188 | S15: =S14 -> 49 | T15: =T14 -> 14 | U15: =R15*S15*T15/1000000 -> 0.128968 | AA15: =AA14 -> 21 | AB15: =AB14 -> 247 | AC15: =AC14 -> 247 | AD15: 0 | AE15: =AH14 -> 240 | AH15: =AE15+AF15-AG15 -> 240 | AI15: pcs | AJ15: =AH15*P15 -> 30.95232 | AK15: =AJ15 -> 30.95232 | AL15: =B15-H15+1 -> 22 | AM15: =IF(AL15<=0,"0天",IF(AL15<=30,"30天内",IF(AL15<=90,"31-90天","91天以上"))) -> 30天内 | AN15: =IF(AM15="0天",0,IF(AM15="30天内",0,IF(AM15="31-90天",0.6,1))) -> 0 | AO15: Euro | AP15: =AK15*AN15 -> 0
A16: 202509 | B16: 45911 | C16: MIC德国仓 | D16: =D15 -> M » N2 - 1 | E16: =E15 -> YCD-EX:HUPPER TEK | F16: =F15 -> MI202508130012 | G16: =G15 -> DE2508031-G7-MIC | H16: =H15 -> 45889 | I16: =I15 -> B07BK8W5MF | K16: =K15 -> 金属储物柜71英寸银色 | M16: =M15 -> 188 | N16: =N15 -> 49 | O16: =O15 -> 14 | P16: =M16*N16*O16/1000000 -> 0.128968 | R16: =R15 -> 188 | S16: =S15 -> 49 | T16: =T15 -> 14 | U16: =R16*S16*T16/1000000 -> 0.128968 | AA16: =AA15 -> 21 | AB16: =AB15 -> 247 | AC16: =AC15 -> 247 | AD16: 0 | AE16: =AH15 -> 240 | AH16: =AE16+AF16-AG16 -> 240 | AI16: pcs | AJ16: =AH16*P16 -> 30.95232 | AK16: =AJ16 -> 30.95232 | AL16: =B16-H16+1 -> 23 | AM16: =IF(AL16<=0,"0天",IF(AL16<=30,"30天内",IF(AL16<=90,"31-90天","91天以上"))) -> 30天内 | AN16: =IF(AM16="0天",0,IF(AM16="30天内",0,IF(AM16="31-90天",0.6,1))) -> 0 | AO16: Euro | AP16: =AK16*AN16 -> 0
A17: 202509 | B17: 45912 | C17: MIC德国仓 | D17: =D16 -> M » N2 - 1 | E17: =E16 -> YCD-EX:HUPPER TEK | F17: =F16 -> MI202508130012 | G17: =G16 -> DE2508031-G7-MIC | H17: =H16 -> 45889 | I17: =I16 -> B07BK8W5MF | K17: =K16 -> 金属储物柜71英寸银色 | M17: =M16 -> 188 | N17: =N16 -> 49 | O17: =O16 -> 14 | P17: =M17*N17*O17/1000000 -> 0.128968 | R17: =R16 -> 188 | S17: =S16 -> 49 | T17: =T16 -> 14 | U17: =R17*S17*T17/1000000 -> 0.128968 | AA17: =AA16 -> 21 | AB17: =AB16 -> 247 | AC17: =AC16 -> 247 | AD17: 0 | AE17: =AH16 -> 240 | AH17: =AE17+AF17-AG17 -> 240 | AI17: pcs | AJ17: =AH17*P17 -> 30.95232 | AK17: =AJ17 -> 30.95232 | AL17: =B17-H17+1 -> 24 | AM17: =IF(AL17<=0,"0天",IF(AL17<=30,"30天内",IF(AL17<=90,"31-90天","91天以上"))) -> 30天内 | AN17: =IF(AM17="0天",0,IF(AM17="30天内",0,IF(AM17="31-90天",0.6,1))) -> 0 | AO17: Euro | AP17: =AK17*AN17 -> 0
A18: 202509 | B18: 45913 | C18: MIC德国仓 | D18: =D17 -> M » N2 - 1 | E18: =E17 -> YCD-EX:HUPPER TEK | F18: =F17 -> MI202508130012 | G18: =G17 -> DE2508031-G7-MIC | H18: =H17 -> 45889 | I18: =I17 -> B07BK8W5MF | K18: =K17 -> 金属储物柜71英寸银色 | M18: =M17 -> 188 | N18: =N17 -> 49 | O18: =O17 -> 14 | P18: =M18*N18*O18/1000000 -> 0.128968 | R18: =R17 -> 188 | S18: =S17 -> 49 | T18: =T17 -> 14 | U18: =R18*S18*T18/1000000 -> 0.128968 | AA18: =AA17 -> 21 | AB18: =AB17 -> 247 | AC18: =AC17 -> 247 | AD18: 0 | AE18: =AH17 -> 240 | AH18: =AE18+AF18-AG18 -> 240 | AI18: pcs | AJ18: =AH18*P18 -> 30.95232 | AK18: =AJ18 -> 30.95232 | AL18: =B18-H18+1 -> 25 | AM18: =IF(AL18<=0,"0天",IF(AL18<=30,"30天内",IF(AL18<=90,"31-90天","91天以上"))) -> 30天内 | AN18: =IF(AM18="0天",0,IF(AM18="30天内",0,IF(AM18="31-90天",0.6,1))) -> 0 | AO18: Euro | AP18: =AK18*AN18 -> 0
A19: 202509 | B19: 45914 | C19: MIC德国仓 | D19: =D18 -> M » N2 - 1 | E19: =E18 -> YCD-EX:HUPPER TEK | F19: =F18 -> MI202508130012 | G19: =G18 -> DE2508031-G7-MIC | H19: =H18 -> 45889 | I19: =I18 -> B07BK8W5MF | K19: =K18 -> 金属储物柜71英寸银色 | M19: =M18 -> 188 | N19: =N18 -> 49 | O19: =O18 -> 14 | P19: =M19*N19*O19/1000000 -> 0.128968 | R19: =R18 -> 188 | S19: =S18 -> 49 | T19: =T18 -> 14 | U19: =R19*S19*T19/1000000 -> 0.128968 | AA19: =AA18 -> 21 | AB19: =AB18 -> 247 | AC19: =AC18 -> 247 | AD19: 0 | AE19: =AH18 -> 240 | AH19: =AE19+AF19-AG19 -> 240 | AI19: pcs | AJ19: =AH19*P19 -> 30.95232 | AK19: =AJ19 -> 30.95232 | AL19: =B19-H19+1 -> 26 | AM19: =IF(AL19<=0,"0天",IF(AL19<=30,"30天内",IF(AL19<=90,"31-90天","91天以上"))) -> 30天内 | AN19: =IF(AM19="0天",0,IF(AM19="30天内",0,IF(AM19="31-90天",0.6,1))) -> 0 | AO19: Euro | AP19: =AK19*AN19 -> 0
