Workbook

Sheet CostBill
A1: NO | B1: 单号 | C1: 参考号 | D1: 跟踪号 sumif金额 | E1: 状态 | F1: 核销状态 | G1: 业务类型 | H1: 运输方式 | I1: 费用类型 | J1: 仓库 | K1: 结算金额 | L1: 结算币种 | M1: 计费规则金额 | N1: 计费规则币种 | O1: 计费重 | P1: 计费时间 | Q1: 备注 | R1: 收件人国家
A2: 1 | B2: WTHTCL-1-20250131 | E2: 未核账 | G2: 仓租 | H2: () | I2: 仓储费 | J2: OCWSA [4A WS10 UK] | K2: 13.834 | L2: GBP | M2: 13.834 | N2: GBP | P2: 2025-01-31 00:00:00
A3: 2 | B3: HTCL-250131-0001 | C3: ST-PO-210-00705284649510773 | D3: OJ661564934GB | E3: 未核账 | G3: 包裹订单 | H3: RM_TR48(48可追踪包裹) | I3: 操作费 | J3: OCWSA [4A WS10 UK] | K3: 0.4 | L3: GBP | M3: 0.4 | N3: GBP | O3: 0.738 | P3: 2025-01-31 01:05:48 | R3: GB
A4: 3 | B4: HTCL-250131-0001 | C4: ST-PO-210-00705284649510773 | D4: OJ661564934GB | E4: 未核账 | G4: 包裹订单 | H4: RM_TR48(48可追踪包裹) | I4: 运输费 | J4: OCWSA [4A WS10 UK] | K4: 2.49 | L4: GBP | M4: 2.49 | N4: GBP | O4: 0.738 | P4: 2025-01-31 01:05:48 | R4: GB
A5: 4 | B5: WTHTCL-1-20250130 | E5: 未核账 | G5: 仓租 | H5: () | I5: 仓储费 | J5: OCWSA [4A WS10 UK] | K5: 13.845 | L5: GBP | M5: 13.845 | N5: GBP | P5: 2025-01-30 00:00:00
A6: 5 | B6: HTCL-250129-0009 | C6: shein-GSO1M621Y000T7D | D6: OJ660860184GB | E6: 未核账 | G6: 包裹订单 | H6: RM_TR48(48可追踪包裹) | I6: 仓储操作附加费按重量 | J6: OCWSA [4A WS10 UK] | K6: 0.07 | L6: GBP | M6: 0.07 | N6: GBP | O6: 1.646 | P6: 2025-01-29 16:57:16 | R6: GB
A7: 6 | B7: HTCL-250129-0009 | C7: shein-GSO1M621Y000T7D | D7: OJ660860184GB | E7: 未核账 | G7: 包裹订单 | H7: RM_TR48(48可追踪包裹) | I7: 操作费 | J7: OCWSA [4A WS10 UK] | K7: 0.4 | L7: GBP | M7: 0.4 | N7: GBP | O7: 1.646 | P7: 2025-01-29 16:57:16 | R7: GB
A8: 7 | B8: HTCL-250129-0009 | C8: shein-GSO1M621Y000T7D | D8: OJ660860184GB | E8: 未核账 | G8: 包裹订单 | H8: RM_TR48(48可追踪包裹) | I8: 运输费 | J8: OCWSA [4A WS10 UK] | K8: 2.49 | L8: GBP | M8: 2.49 | N8: GBP | O8: 1.646 | P8: 2025-01-29 16:57:16 | R8: GB
A9: 8 | B9: HTCL-250130-0003 | C9: ST-PO-210-11736884378150555 | D9: OJ661281116GB | E9: 未核账 | G9: 包裹订单 | H9: RM_TR48(48可追踪包裹) | I9: 仓储操作附加费按重量 | J9: OCWSA [4A WS10 UK] | K9: 0.07 | L9: GBP | M9: 0.07 | N9: GBP | O9: 1.362 | P9: 2025-01-30 11:17:05 | R9: GB
A10: 9 | B10: HTCL-250130-0003 | C10: ST-PO-210-11736884378150555 | D10: OJ661281116GB | E10: 未核账 | G10: 包裹订单 | H10: RM_TR48(48可追踪包裹) | I10: 操作费 | J10: OCWSA [4A WS10 UK] | K10: 0.4 | L10: GBP | M10: 0.4 | N10: GBP | O10: 1.362 | P10: 2025-01-30 11:17:05 | R10: GB
A11: 10 | B11: HTCL-250130-0003 | C11: ST-PO-210-11736884378150555 | D11: OJ661281116GB | E11: 未核账 | G11: 包裹订单 | H11: RM_TR48(48可追踪包裹) | I11: 运输费 | J11: OCWSA [4A WS10 UK] | K11: 2.49 | L11: GBP | M11: 2.49 | N11: GBP | O11: 1.362 | P11: 2025-01-30 11:17:05 | R11: GB
A12: 11 | B12: HTCL-250130-0004 | C12: ST-PO-210-11981967007271428 | D12: OJ661281120GB | E12: 未核账 | G12: 包裹订单 | H12: RM_TR48(48可追踪包裹) | I12: 仓储操作附加费按重量 | J12: OCWSA [4A WS10 UK] | K12: 0.07 | L12: GBP | M12: 0.07 | N12: GBP | O12: 1.362 | P12: 2025-01-30 11:17:06 | R12: GB
A13: 12 | B13: HTCL-250130-0004 | C13: ST-PO-210-11981967007271428 | D13: OJ661281120GB | E13: 未核账 | G13: 包裹订单 | H13: RM_TR48(48可追踪包裹) | I13: 操作费 | J13: OCWSA [4A WS10 UK] | K13: 0.4 | L13: GBP | M13: 0.4 | N13: GBP | O13: 1.362 | P13: 2025-01-30 11:17:06 | R13: GB
A14: 13 | B14: HTCL-250130-0004 | C14: ST-PO-210-11981967007271428 | D14: OJ661281120GB | E14: 未核账 | G14: 包裹订单 | H14: RM_TR48(48可追踪包裹) | I14: 运输费 | J14: OCWSA [4A WS10 UK] | K14: 2.49 | L14: GBP | M14: 2.49 | N14: GBP | O14: 1.362 | P14: 2025-01-30 11:17:06 | R14: GB
A15: 14 | B15: HTCL-250130-0002 | C15: ST-PO-210-12124682552872338 | D15: OJ661281102GB | E15: 未核账 | G15: 包裹订单 | H15: RM_TR48(48可追踪包裹) | I15: 仓储操作附加费按重量 | J15: OCWSA [4A WS10 UK] | K15: 0.07 | L15: GBP | M15: 0.07 | N15: GBP | O15: 1.362 | P15: 2025-01-30 11:17:04 | R15: GB
A16: 15 | B16: HTCL-250130-0002 | C16: ST-PO-210-12124682552872338 | D16: OJ661281102GB | E16: 未核账 | G16: 包裹订单 | H16: RM_TR48(48可追踪包裹) | I16: 操作费 | J16: OCWSA [4A WS10 UK] | K16: 0.4 | L16: GBP | M16: 0.4 | N16: GBP | O16: 1.362 | P16: 2025-01-30 11:17:04 | R16: GB
A17: 16 | B17: HTCL-250130-0002 | C17: ST-PO-210-12124682552872338 | D17: OJ661281102GB | E17: 未核账 | G17: 包裹订单 | H17: RM_TR48(48可追踪包裹) | I17: 运输费 | J17: OCWSA [4A WS10 UK] | K17: 2.49 | L17: GBP | M17: 2.49 | N17: GBP | O17: 1.362 | P17: 2025-01-30 11:17:04 | R17: GB
... A25: 24 | B25: HTCL-250130-0001 | C25: shein-GSO1MX38N00MB5H | D25: OJ661250365GB | E25: 未核账 | G25: 包裹订单 | H25: RM_TR48(48可追踪包裹) | I25: 运输费 | J25: OCWSA [4A WS10 UK] | K25: 2.86 | L25: GBP | M25: 2.86 | N25: GBP | O25: 3.292 | P25: 2025-01-30 10:49:08 | R25: GB
A26: 25 | B26: WTHTCL-1-20250129 | E26: 未核账 | G26: 仓租 | H26: () | I26: 仓储费 | J26: OCWSA [4A WS10 UK] | K26: 13.876 | L26: GBP | M26: 13.876 | N26: GBP | P26: 2025-01-29 00:00:00
A27: 26 | B27: HTCL-250126-0002 | C27: ST-PO-210-14994884818473662 | D27: OJ658907268GB | E27: 未核账 | G27: 包裹订单 | H27: RM_TR48(48可追踪包裹) | I27: 包材费用 | J27: OCWSA [4A WS10 UK] | K27: 1.5 | L27: GBP | M27: 1.5 | N27: GBP | O27: 1.869 | P27: 2025-01-26 13:27:55 | R27: GB
A28: 27 | B28: HTCL-250126-0002 | C28: ST-PO-210-14994884818473662 | D28: OJ658907268GB | E28: 未核账 | G28: 包裹订单 | H28: RM_TR48(48可追踪包裹) | I28: 仓储操作附加费按重量 | J28: OCWSA [4A WS10 UK] | K28: 0.07 | L28: GBP | M28: 0.07 | N28: GBP | O28: 1.869 | P28: 2025-01-26 13:27:55 | R28: GB
A29: 28 | B29: HTCL-250126-0002 | C29: ST-PO-210-14994884818473662 | D29: OJ658907268GB | E29: 未核账 | G29: 包裹订单 | H29: RM_TR48(48可追踪包裹) | I29: 操作费 | J29: OCWSA [4A WS10 UK] | K29: 0.4 | L29: GBP | M29: 0.4 | N29: GBP | O29: 1.869 | P29: 2025-01-26 13:27:55 | R29: GB
A30: 29 | B30: HTCL-250126-0002 | C30: ST-PO-210-14994884818473662 | D30: OJ658907268GB | E30: 未核账 | G30: 包裹订单 | H30: RM_TR48(48可追踪包裹) | I30: 运输费 | J30: OCWSA [4A WS10 UK] | K30: 2.49 | L30: GBP | M30: 2.49 | N30: GBP | O30: 1.869 | P30: 2025-01-26 13:27:55 | R30: GB
A31: 30 | B31: HTCL-250126-0004 | C31: ST-PO-210-14524761354790320 | D31: OJ658908630GB | E31: 未核账 | G31: 包裹订单 | H31: RM_TR48(48可追踪包裹) | I31: 包材费用 | J31: OCWSA [4A WS10 UK] | K31: 1.5 | L31: GBP | M31: 1.5 | N31: GBP | O31: 1.869 | P31: 2025-01-26 13:31:38 | R31: GB
A32: 31 | B32: HTCL-250126-0004 | C32: ST-PO-210-14524761354790320 | D32: OJ658908630GB | E32: 未核账 | G32: 包裹订单 | H32: RM_TR48(48可追踪包裹) | I32: 仓储操作附加费按重量 | J32: OCWSA [4A WS10 UK] | K32: 0.07 | L32: GBP | M32: 0.07 | N32: GBP | O32: 1.869 | P32: 2025-01-26 13:31:38 | R32: GB
A33: 32 | B33: HTCL-250126-0004 | C33: ST-PO-210-14524761354790320 | D33: OJ658908630GB | E33: 未核账 | G33: 包裹订单 | H33: RM_TR48(48可追踪包裹) | I33: 操作费 | J33: OCWSA [4A WS10 UK] | K33: 0.4 | L33: GBP | M33: 0.4 | N33: GBP | O33: 1.869 | P33: 2025-01-26 13:31:38 | R33: GB
A34: 33 | B34: HTCL-250126-0004 | C34: ST-PO-210-14524761354790320 | D34: OJ658908630GB | E34: 未核账 | G34: 包裹订单 | H34: RM_TR48(48可追踪包裹) | I34: 运输费 | J34: OCWSA [4A WS10 UK] | K34: 2.49 | L34: GBP | M34: 2.49 | N34: GBP | O34: 1.869 | P34: 2025-01-26 13:31:38 | R34: GB
A35: 34 | B35: HTCL-250129-0004 | C35: ST-PO-210-12222831002154091 | D35: OJ660804196GB | E35: 未核账 | G35: 包裹订单 | H35: RM_TR48(48可追踪包裹) | I35: 包材费用 | J35: OCWSA [4A WS10 UK] | K35: 0.8 | L35: GBP | M35: 0.8 | N35: GBP | O35: 1.476 | P35: 2025-01-29 14:51:30 | R35: GB
A36: 35 | B36: HTCL-250129-0004 | C36: ST-PO-210-12222831002154091 | D36: OJ660804196GB | E36: 未核账 | G36: 包裹订单 | H36: RM_TR48(48可追踪包裹) | I36: 仓储操作附加费按件数 | J36: OCWSA [4A WS10 UK] | K36: 0.3 | L36: GBP | M36: 0.3 | N36: GBP | O36: 1.476 | P36: 2025-01-29 14:51:30 | R36: GB
A37: 36 | B37: HTCL-250129-0004 | C37: ST-PO-210-12222831002154091 | D37: OJ660804196GB | E37: 未核账 | G37: 包裹订单 | H37: RM_TR48(48可追踪包裹) | I37: 仓储操作附加费按重量 | J37: OCWSA [4A WS10 UK] | K37: 0.07 | L37: GBP | M37: 0.07 | N37: GBP | O37: 1.476 | P37: 2025-01-29 14:51:30 | R37: GB
A38: 37 | B38: HTCL-250129-0004 | C38: ST-PO-210-12222831002154091 | D38: OJ660804196GB | E38: 未核账 | G38: 包裹订单 | H38: RM_TR48(48可追踪包裹) | I38: 操作费 | J38: OCWSA [4A WS10 UK] | K38: 0.4 | L38: GBP | M38: 0.4 | N38: GBP | O38: 1.476 | P38: 2025-01-29 14:51:30 | R38: GB
... A60: 59 | B60: HTCL-250128-0004 | C60: shein-GSO1M526A001BAL | D60: OJ660514790GB | E60: 未核账 | G60: 包裹订单 | H60: RM_TR48(48可追踪包裹) | I60: 运输费 | J60: OCWSA [4A WS10 UK] | K60: 2.49 | L60: GBP | M60: 2.49 | N60: GBP | O60: 1.646 | P60: 2025-01-28 23:31:34 | R60: GB
A61: 60 | B61: WTHTCL-1-20250128 | E61: 未核账 | G61: 仓租 | H61: () | I61: 仓储费 | J61: OCWSA [4A WS10 UK] | K61: 13.914 | L61: GBP | M61: 13.914 | N61: GBP | P61: 2025-01-28 00:00:00
A62: 61 | B62: HTCL-250128-0003 | C62: ST-PO-210-20604397563433285 | D62: OJ660375642GB | E62: 未核账 | G62: 包裹订单 | H62: RM_TR48(48可追踪包裹) | I62: 仓储操作附加费按重量 | J62: OCWSA [4A WS10 UK] | K62: 0.07 | L62: GBP | M62: 0.07 | N62: GBP | O62: 1.907 | P62: 2025-01-28 16:57:33 | R62: GB
A63: 62 | B63: HTCL-250128-0003 | C63: ST-PO-210-20604397563433285 | D63: OJ660375642GB | E63: 未核账 | G63: 包裹订单 | H63: RM_TR48(48可追踪包裹) | I63: 操作费 | J63: OCWSA [4A WS10 UK] | K63: 0.4 | L63: GBP | M63: 0.4 | N63: GBP | O63: 1.907 | P63: 2025-01-28 16:57:33 | R63: GB
A64: 63 | B64: HTCL-250128-0003 | C64: ST-PO-210-20604397563433285 | D64: OJ660375642GB | E64: 未核账 | G64: 包裹订单 | H64: RM_TR48(48可追踪包裹) | I64: 运输费 | J64: OCWSA [4A WS10 UK] | K64: 2.49 | L64: GBP | M64: 2.49 | N64: GBP | O64: 1.907 | P64: 2025-01-28 16:57:33 | R64: GB
A65: 64 | B65: HTCL-250128-0002 | C65: ST-PO-210-20010225536550648 | D65: OJ660375656GB | E65: 未核账 | G65: 包裹订单 | H65: RM_TR48(48可追踪包裹) | I65: 操作费 | J65: OCWSA [4A WS10 UK] | K65: 0.4 | L65: GBP | M65: 0.4 | N65: GBP | O65: 0.605 | P65: 2025-01-28 16:57:29 | R65: GB
A66: 65 | B66: HTCL-250128-0002 | C66: ST-PO-210-20010225536550648 | D66: OJ660375656GB | E66: 未核账 | G66: 包裹订单 | H66: RM_TR48(48可追踪包裹) | I66: 运输费 | J66: OCWSA [4A WS10 UK] | K66: 2.49 | L66: GBP | M66: 2.49 | N66: GBP | O66: 0.605 | P66: 2025-01-28 16:57:29 | R66: GB
A67: 66 | B67: HTCL-250125-0005 | C67: shein-GSO1M415W000P7V | D67: OJ658380604GB | E67: 未核账 | G67: 包裹订单 | H67: RM_TR48(48可追踪包裹) | I67: 操作费 | J67: OCWSA [4A WS10 UK] | K67: 0.4 | L67: GBP | M67: 0.4 | N67: GBP | O67: 0.151 | P67: 2025-01-25 14:27:29 | R67: GB
A68: 67 | B68: HTCL-250125-0005 | C68: shein-GSO1M415W000P7V | D68: OJ658380604GB | E68: 未核账 | G68: 包裹订单 | H68: RM_TR48(48可追踪包裹) | I68: 运输费 | J68: OCWSA [4A WS10 UK] | K68: 2.49 | L68: GBP | M68: 2.49 | N68: GBP | O68: 0.151 | P68: 2025-01-25 14:27:29 | R68: GB
...

Sheet CostBill 一件代发费用录入
A1: NO | B1: 单号 | C1: 参考号 | D1: 跟踪号 sumif金额 | E1: 计费规则金额 | F1: 金额汇总 | G1: 已删除重复项 | H1: 业务类型 | I1: 运输方式 | J1: 费用类型 | K1: 仓库 | L1: 结算金额 | M1: 结算币种 | N1: 计费重 | O1: 跟踪号 | P1: 计费规则币种 | Q1: 计费重 | R1: 计费重匹配 | S1: 计费时间 | T1: 备注 | U1: 收件人国家
A2: 2 | B2: HTCL-250131-0001 | C2: ST-PO-210-00705284649510773 | D2: OJ661564934GB | E2: 0.4 | F2: {=SUMIF(D:D,G2:G98,E:E)} -> 2.89 | G2: OJ661564934GB | H2: 包裹订单 | I2: RM_TR48(48可追踪包裹) | J2: 操作费 | K2: OCWSA [4A WS10 UK] | L2: 0.4 | M2: GBP | N2: 0.738 | O2: OJ661564934GB | P2: GBP | Q2: 0.738 | R2: 0.738 | S2: 2025-01-31 01:05:48 | U2: GB
A3: 3 | B3: HTCL-250131-0001 | C3: ST-PO-210-00705284649510773 | D3: OJ661564934GB | E3: 2.49 | F3: 2.96 | G3: OJ660860184GB | H3: 包裹订单 | I3: RM_TR48(48可追踪包裹) | J3: 运输费 | K3: OCWSA [4A WS10 UK] | L3: 2.49 | M3: GBP | N3: 0.738 | O3: OJ661564934GB | P3: GBP | Q3: 0.738 | R3: 1.646 | S3: 2025-01-31 01:05:48 | U3: GB
A4: 5 | B4: HTCL-250129-0009 | C4: shein-GSO1M621Y000T7D | D4: OJ660860184GB | E4: 0.07 | F4: 2.96 | G4: OJ661281116GB | H4: 包裹订单 | I4: RM_TR48(48可追踪包裹) | J4: 仓储操作附加费按重量 | K4: OCWSA [4A WS10 UK] | L4: 0.07 | M4: GBP | N4: 1.646 | O4: OJ660860184GB | P4: GBP | Q4: 1.646 | R4: 1.362 | S4: 2025-01-29 16:57:16 | U4: GB
A5: 6 | B5: HTCL-250129-0009 | C5: shein-GSO1M621Y000T7D | D5: OJ660860184GB | E5: 0.4 | F5: 2.96 | G5: OJ661281120GB | H5: 包裹订单 | I5: RM_TR48(48可追踪包裹) | J5: 操作费 | K5: OCWSA [4A WS10 UK] | L5: 0.4 | M5: GBP | N5: 1.646 | O5: OJ660860184GB | P5: GBP | Q5: 1.646 | R5: 1.362 | S5: 2025-01-29 16:57:16 | U5: GB
A6: 7 | B6: HTCL-250129-0009 | C6: shein-GSO1M621Y000T7D | D6: OJ660860184GB | E6: 2.49 | F6: 2.96 | G6: OJ661281102GB | H6: 包裹订单 | I6: RM_TR48(48可追踪包裹) | J6: 运输费 | K6: OCWSA [4A WS10 UK] | L6: 2.49 | M6: GBP | N6: 1.646 | O6: OJ660860184GB | P6: GBP | Q6: 1.646 | R6: 1.362 | S6: 2025-01-29 16:57:16 | U6: GB
A7: 8 | B7: HTCL-250130-0003 | C7: ST-PO-210-11736884378150555 | D7: OJ661281116GB | E7: 0.07 | F7: 2.96 | G7: OJ660888148GB | H7: 包裹订单 | I7: RM_TR48(48可追踪包裹) | J7: 仓储操作附加费按重量 | K7: OCWSA [4A WS10 UK] | L7: 0.07 | M7: GBP | N7: 1.362 | O7: OJ661281116GB | P7: GBP | Q7: 1.362 | R7: 1.362 | S7: 2025-01-30 11:17:05 | U7: GB
A8: 9 | B8: HTCL-250130-0003 | C8: ST-PO-210-11736884378150555 | D8: OJ661281116GB | E8: 0.4 | F8: 5.27 | G8: OJ661250365GB | H8: 包裹订单 | I8: RM_TR48(48可追踪包裹) | J8: 操作费 | K8: OCWSA [4A WS10 UK] | L8: 0.4 | M8: GBP | N8: 1.362 | O8: OJ661281116GB | P8: GBP | Q8: 1.362 | R8: 3.292 | S8: 2025-01-30 11:17:05 | U8: GB
A9: 10 | B9: HTCL-250130-0003 | C9: ST-PO-210-11736884378150555 | D9: OJ661281116GB | E9: 2.49 | F9: 4.46 | G9: OJ658907268GB | H9: 包裹订单 | I9: RM_TR48(48可追踪包裹) | J9: 运输费 | K9: OCWSA [4A WS10 UK] | L9: 2.49 | M9: GBP | N9: 1.362 | O9: OJ661281116GB | P9: GBP | Q9: 1.362 | R9: 1.869 | S9: 2025-01-30 11:17:05 | U9: GB
A10: 11 | B10: HTCL-250130-0004 | C10: ST-PO-210-11981967007271428 | D10: OJ661281120GB | E10: 0.07 | F10: 4.46 | G10: OJ658908630GB | H10: 包裹订单 | I10: RM_TR48(48可追踪包裹) | J10: 仓储操作附加费按重量 | K10: OCWSA [4A WS10 UK] | L10: 0.07 | M10: GBP | N10: 1.362 | O10: OJ661281120GB | P10: GBP | Q10: 1.362 | R10: 1.869 | S10: 2025-01-30 11:17:06 | U10: GB
A11: 12 | B11: HTCL-250130-0004 | C11: ST-PO-210-11981967007271428 | D11: OJ661281120GB | E11: 0.4 | F11: 4.06 | G11: OJ660804196GB | H11: 包裹订单 | I11: RM_TR48(48可追踪包裹) | J11: 操作费 | K11: OCWSA [4A WS10 UK] | L11: 0.4 | M11: GBP | N11: 1.362 | O11: OJ661281120GB | P11: GBP | Q11: 1.362 | R11: 1.476 | S11: 2025-01-30 11:17:06 | U11: GB
A12: 13 | B12: HTCL-250130-0004 | C12: ST-PO-210-11981967007271428 | D12: OJ661281120GB | E12: 2.49 | F12: 2.89 | G12: OJ660804165GB | H12: 包裹订单 | I12: RM_TR48(48可追踪包裹) | J12: 运输费 | K12: OCWSA [4A WS10 UK] | L12: 2.49 | M12: GBP | N12: 1.362 | O12: OJ661281120GB | P12: GBP | Q12: 1.362 | R12: 0.738 | S12: 2025-01-30 11:17:06 | U12: GB
A13: 14 | B13: HTCL-250130-0002 | C13: ST-PO-210-12124682552872338 | D13: OJ661281102GB | E13: 0.07 | F13: 2.89 | G13: OJ660804182GB | H13: 包裹订单 | I13: RM_TR48(48可追踪包裹) | J13: 仓储操作附加费按重量 | K13: OCWSA [4A WS10 UK] | L13: 0.07 | M13: GBP | N13: 1.362 | O13: OJ661281102GB | P13: GBP | Q13: 1.362 | R13: 0.738 | S13: 2025-01-30 11:17:04 | U13: GB
A14: 15 | B14: HTCL-250130-0002 | C14: ST-PO-210-12124682552872338 | D14: OJ661281102GB | E14: 0.4 | F14: 2.89 | G14: OJ660804205GB | H14: 包裹订单 | I14: RM_TR48(48可追踪包裹) | J14: 操作费 | K14: OCWSA [4A WS10 UK] | L14: 0.4 | M14: GBP | N14: 1.362 | O14: OJ661281102GB | P14: GBP | Q14: 1.362 | R14: 0.738 | S14: 2025-01-30 11:17:04 | U14: GB
... A98: 101 | B98: HTCL-250127-0003 | C98: shein-GSO1MT28100Q68U | D98: OJ659388330GB | E98: 0.4 | F98: 4.46 | G98: OJ590792088GB | H98: 包裹订单 | I98: RM_TR48(48可追踪包裹) | J98: 操作费 | K98: OCWSA [4A WS10 UK] | L98: 0.4 | M98: GBP | N98: 0.229 | O98: OJ659388330GB | P98: GBP | Q98: 0.229 | R98: 1.869 | S98: 2025-01-27 09:46:38 | U98: GB
A99: 102 | B99: HTCL-250127-0003 | C99: shein-GSO1MT28100Q68U | D99: OJ659388330GB | E99: 2.49 | H99: 包裹订单 | I99: RM_TR48(48可追踪包裹) | J99: 运输费 | K99: OCWSA [4A WS10 UK] | L99: 2.49 | M99: GBP | N99: 0.229 | O99: OJ659388330GB | P99: GBP | Q99: 0.229 | S99: 2025-01-27 09:46:38 | U99: GB
A100: 103 | B100: HTCL-250127-0001 | C100: 12-12628-77707 | D100: OJ659363341GB | E100: 1 | H100: 包裹订单 | I100: RM_TR48(48可追踪包裹) | J100: 包材费用 | K100: OCWSA [4A WS10 UK] | L100: 1 | M100: GBP | N100: 1.674 | O100: OJ659363341GB | P100: GBP | Q100: 1.674 | S100: 2025-01-27 09:00:47 | U100: GB
A101: 104 | B101: HTCL-250127-0001 | C101: 12-12628-77707 | D101: OJ659363341GB | E101: 0.07 | H101: 包裹订单 | I101: RM_TR48(48可追踪包裹) | J101: 仓储操作附加费按重量 | K101: OCWSA [4A WS10 UK] | L101: 0.07 | M101: GBP | N101: 1.674 | O101: OJ659363341GB | P101: GBP | Q101: 1.674 | S101: 2025-01-27 09:00:47 | U101: GB
A102: 105 | B102: HTCL-250127-0001 | C102: 12-12628-77707 | D102: OJ659363341GB | E102: 0.4 | H102: 包裹订单 | I102: RM_TR48(48可追踪包裹) | J102: 操作费 | K102: OCWSA [4A WS10 UK] | L102: 0.4 | M102: GBP | N102: 1.674 | O102: OJ659363341GB | P102: GBP | Q102: 1.674 | S102: 2025-01-27 09:00:47 | U102: GB
A103: 106 | B103: HTCL-250127-0001 | C103: 12-12628-77707 | D103: OJ659363341GB | E103: 2.49 | H103: 包裹订单 | I103: RM_TR48(48可追踪包裹) | J103: 运输费 | K103: OCWSA [4A WS10 UK] | L103: 2.49 | M103: GBP | N103: 1.674 | O103: OJ659363341GB | P103: GBP | Q103: 1.674 | S103: 2025-01-27 09:00:47 | U103: GB
A104: 107 | B104: HTCL-250126-0007 | C104: 11-12619-21055 | D104: OJ659041205GB | E104: 1 | H104: 包裹订单 | I104: RM_TR48(48可追踪包裹) | J104: 包材费用 | K104: OCWSA [4A WS10 UK] | L104: 1 | M104: GBP | N104: 0.034 | O104: OJ659041205GB | P104: GBP | Q104: 0.034 | S104: 2025-01-26 18:36:42 | U104: GB
A105: 108 | B105: HTCL-250126-0007 | C105: 11-12619-21055 | D105: OJ659041205GB | E105: 0.4 | H105: 包裹订单 | I105: RM_TR48(48可追踪包裹) | J105: 操作费 | K105: OCWSA [4A WS10 UK] | L105: 0.4 | M105: GBP | N105: 0.034 | O105: OJ659041205GB | P105: GBP | Q105: 0.034 | S105: 2025-01-26 18:36:42 | U105: GB
A106: 109 | B106: HTCL-250126-0007 | C106: 11-12619-21055 | D106: OJ659041205GB | E106: 2.49 | H106: 包裹订单 | I106: RM_TR48(48可追踪包裹) | J106: 运输费 | K106: OCWSA [4A WS10 UK] | L106: 2.49 | M106: GBP | N106: 0.034 | O106: OJ659041205GB | P106: GBP | Q106: 0.034 | S106: 2025-01-26 18:36:42 | U106: GB
A107: 110 | B107: HTCL-250126-0001 | C107: shein-GSO1M407F000FCN | D107: OJ658652395GB | E107: 1 | H107: 包裹订单 | I107: RM_TR48(48可追踪包裹) | J107: 包材费用 | K107: OCWSA [4A WS10 UK] | L107: 1 | M107: GBP | N107: 0.034 | O107: OJ658652395GB | P107: GBP | Q107: 0.034 | S107: 2025-01-26 01:03:38 | U107: GB
A108: 111 | B108: HTCL-250126-0001 | C108: shein-GSO1M407F000FCN | D108: OJ658652395GB | E108: 0.4 | H108: 包裹订单 | I108: RM_TR48(48可追踪包裹) | J108: 操作费 | K108: OCWSA [4A WS10 UK] | L108: 0.4 | M108: GBP | N108: 0.034 | O108: OJ658652395GB | P108: GBP | Q108: 0.034 | S108: 2025-01-26 01:03:38 | U108: GB
A109: 112 | B109: HTCL-250126-0001 | C109: shein-GSO1M407F000FCN | D109: OJ658652395GB | E109: 2.49 | H109: 包裹订单 | I109: RM_TR48(48可追踪包裹) | J109: 运输费 | K109: OCWSA [4A WS10 UK] | L109: 2.49 | M109: GBP | N109: 0.034 | O109: OJ658652395GB | P109: GBP | Q109: 0.034 | S109: 2025-01-26 01:03:38 | U109: GB
A110: 113 | B110: HTCL-250125-0007 | C110: shein-GSO1M403R000KW8 | D110: OJ658517523GB | E110: 0.4 | H110: 包裹订单 | I110: RM_TR48(48可追踪包裹) | J110: 操作费 | K110: OCWSA [4A WS10 UK] | L110: 0.4 | M110: GBP | N110: 0.034 | O110: OJ658517523GB | P110: GBP | Q110: 0.034 | S110: 2025-01-25 19:33:16 | U110: GB
... A122: 126 | B122: HTCL-250126-0005 | C122: ST-PO-210-03800412434472834 | D122: OJ658914096GB | E122: 2.49 | H122: 包裹订单 | I122: RM_TR48(48可追踪包裹) | J122: 运输费 | K122: OCWSA [4A WS10 UK] | L122: 2.49 | M122: GBP | N122: 1.476 | O122: OJ658914096GB | P122: GBP | Q122: 1.476 | S122: 2025-01-26 13:48:22 | U122: GB
A123: 130 | B123: HTCL-250124-0007 | D123: 4338445140 | E123: 0.98 | H123: 包裹订单 | I123: DPD_GB(DPD 英国) | J123: 仓储操作附加费按重量 | K123: OCWSA [4A WS10 UK] | L123: 0.98 | M123: GBP | N123: 14.528 | O123: 4338445140 | P123: GBP | Q123: 14.528 | S123: 2025-01-24 21:57:45 | U123: GB
A124: 131 | B124: HTCL-250124-0007 | D124: 4338445140 | E124: 0.4 | H124: 包裹订单 | I124: DPD_GB(DPD 英国) | J124: 操作费 | K124: OCWSA [4A WS10 UK] | L124: 0.4 | M124: GBP | N124: 14.528 | O124: 4338445140 | P124: GBP | Q124: 14.528 | S124: 2025-01-24 21:57:45 | U124: GB
A125: 132 | B125: HTCL-250124-0007 | D125: 4338445140 | E125: 5.55 | H125: 包裹订单 | I125: DPD_GB(DPD 英国) | J125: 运输费 | K125: OCWSA [4A WS10 UK] | L125: 5.55 | M125: GBP | N125: 14.528 | O125: 4338445140 | P125: GBP | Q125: 14.528 | S125: 2025-01-24 21:57:45 | U125: GB
A126: 133 | B126: HTCL-250124-0006 | C126: shein-GSO1M335800M8PQ | D126: OJ657923817GB | E126: 0.07 | H126: 包裹订单 | I126: RM_TR48(48可追踪包裹) | J126: 仓储操作附加费按重量 | K126: OCWSA [4A WS10 UK] | L126: 0.07 | M126: GBP | N126: 1.646 | O126: OJ657923817GB | P126: GBP | Q126: 1.646 | S126: 2025-01-24 20:18:43 | U126: GB
A127: 134 | B127: HTCL-250124-0006 | C127: shein-GSO1M335800M8PQ | D127: OJ657923817GB | E127: 0.4 | H127: 包裹订单 | I127: RM_TR48(48可追踪包裹) | J127: 操作费 | K127: OCWSA [4A WS10 UK] | L127: 0.4 | M127: GBP | N127: 1.646 | O127: OJ657923817GB | P127: GBP | Q127: 1.646 | S127: 2025-01-24 20:18:43 | U127: GB
A128: 135 | B128: HTCL-250124-0006 | C128: shein-GSO1M335800M8PQ | D128: OJ657923817GB | E128: 2.49 | H128: 包裹订单 | I128: RM_TR48(48可追踪包裹) | J128: 运输费 | K128: OCWSA [4A WS10 UK] | L128: 2.49 | M128: GBP | N128: 1.646 | O128: OJ657923817GB | P128: GBP | Q128: 1.646 | S128: 2025-01-24 20:18:43 | U128: GB
A129: 136 | B129: HTCL-250124-0001 | C129: 14-12611-79079 | D129: OJ657472587GB | E129: 0.8 | H129: 包裹订单 | I129: RM_TR48(48可追踪包裹) | J129: 包材费用 | K129: OCWSA [4A WS10 UK] | L129: 0.8 | M129: GBP | N129: 0.118 | O129: OJ657472587GB | P129: GBP | Q129: 0.118 | S129: 2025-01-24 09:22:30 | U129: GB
A130: 137 | B130: HTCL-250124-0001 | C130: 14-12611-79079 | D130: OJ657472587GB | E130: 0.4 | H130: 包裹订单 | I130: RM_TR48(48可追踪包裹) | J130: 操作费 | K130: OCWSA [4A WS10 UK] | L130: 0.4 | M130: GBP | N130: 0.118 | O130: OJ657472587GB | P130: GBP | Q130: 0.118 | S130: 2025-01-24 09:22:30 | U130: GB
A131: 138 | B131: HTCL-250124-0001 | C131: 14-12611-79079 | D131: OJ657472587GB | E131: 2.49 | H131: 包裹订单 | I131: RM_TR48(48可追踪包裹) | J131: 运输费 | K131: OCWSA [4A WS10 UK] | L131: 2.49 | M131: GBP | N131: 0.118 | O131: OJ657472587GB | P131: GBP | Q131: 0.118 | S131: 2025-01-24 09:22:30 | U131: GB
A132: 139 | B132: HTCL-250124-0003 | C132: ST-PO-210-18130479030311356 | D132: OJ657472613GB | E132: 0.8 | H132: 包裹订单 | I132: RM_TR48(48可追踪包裹) | J132: 包材费用 | K132: OCWSA [4A WS10 UK] | L132: 0.8 | M132: GBP | N132: 0.738 | O132: OJ657472613GB | P132: GBP | Q132: 0.738 | S132: 2025-01-24 09:22:38 | U132: GB
A133: 140 | B133: HTCL-250124-0003 | C133: ST-PO-210-18130479030311356 | D133: OJ657472613GB | E133: 0.4 | H133: 包裹订单 | I133: RM_TR48(48可追踪包裹) | J133: 操作费 | K133: OCWSA [4A WS10 UK] | L133: 0.4 | M133: GBP | N133: 0.738 | O133: OJ657472613GB | P133: GBP | Q133: 0.738 | S133: 2025-01-24 09:22:38 | U133: GB
A134: 141 | B134: HTCL-250124-0003 | C134: ST-PO-210-18130479030311356 | D134: OJ657472613GB | E134: 2.49 | H134: 包裹订单 | I134: RM_TR48(48可追踪包裹) | J134: 运输费 | K134: OCWSA [4A WS10 UK] | L134: 2.49 | M134: GBP | N134: 0.738 | O134: OJ657472613GB | P134: GBP | Q134: 0.738 | S134: 2025-01-24 09:22:38 | U134: GB
...

Sheet vlookup重量
A1: 已删除重复项
A2: OJ661564934GB | B2: =VLOOKUP(A2,'CostBill 一件代发费用录入'!O:Q,0,FALSE) -> #VALUE! | C2: =VLOOKUP(A2,'CostBill 一件代发费用录入'!D:S,16,0) -> 2025-01-31 01:05:48
A3: OJ660860184GB | B3: =VLOOKUP(A3,'CostBill 一件代发费用录入'!O:Q,4,0) -> #REF! | C3: =VLOOKUP(A3,'CostBill 一件代发费用录入'!D:S,16,0) -> 2025-01-29 16:57:16
A4: OJ661281116GB | B4: =VLOOKUP(A4,'CostBill 一件代发费用录入'!O:Q,4,0) -> #REF! | C4: =VLOOKUP(A4,'CostBill 一件代发费用录入'!D:S,16,0) -> 2025-01-30 11:17:05
A5: OJ661281120GB | B5: =VLOOKUP(A5,'CostBill 一件代发费用录入'!O:Q,4,0) -> #REF! | C5: =VLOOKUP(A5,'CostBill 一件代发费用录入'!D:S,16,0) -> 2025-01-30 11:17:06
A6: OJ661281102GB | B6: =VLOOKUP(A6,'CostBill 一件代发费用录入'!O:Q,4,0) -> #REF! | C6: =VLOOKUP(A6,'CostBill 一件代发费用录入'!D:S,16,0) -> 2025-01-30 11:17:04
A7: OJ660888148GB | B7: =VLOOKUP(A7,'CostBill 一件代发费用录入'!O:Q,4,0) -> #REF! | C7: =VLOOKUP(A7,'CostBill 一件代发费用录入'!D:S,16,0) -> 2025-01-29 17:57:21
A8: OJ661250365GB | B8: =VLOOKUP(A8,'CostBill 一件代发费用录入'!O:Q,4,0) -> #REF! | C8: =VLOOKUP(A8,'CostBill 一件代发费用录入'!D:S,16,0) -> 2025-01-30 10:49:08
A9: OJ658907268GB | B9: =VLOOKUP(A9,'CostBill 一件代发费用录入'!O:Q,4,0) -> #REF! | C9: =VLOOKUP(A9,'CostBill 一件代发费用录入'!D:S,16,0) -> 2025-01-26 13:27:55
A10: OJ658908630GB | B10: =VLOOKUP(A10,'CostBill 一件代发费用录入'!O:Q,4,0) -> #REF! | C10: =VLOOKUP(A10,'CostBill 一件代发费用录入'!D:S,16,0) -> 2025-01-26 13:31:38
A11: OJ660804196GB | B11: =VLOOKUP(A11,'CostBill 一件代发费用录入'!O:Q,4,0) -> #REF! | C11: =VLOOKUP(A11,'CostBill 一件代发费用录入'!D:S,16,0) -> 2025-01-29 14:51:30
A12: OJ660804165GB | B12: =VLOOKUP(A12,'CostBill 一件代发费用录入'!O:Q,4,0) -> #REF! | C12: =VLOOKUP(A12,'CostBill 一件代发费用录入'!D:S,16,0) -> 2025-01-29 14:52:13
A13: OJ660804182GB | B13: =VLOOKUP(A13,'CostBill 一件代发费用录入'!O:Q,4,0) -> #REF! | C13: =VLOOKUP(A13,'CostBill 一件代发费用录入'!D:S,16,0) -> 2025-01-29 14:51:56
A14: OJ660804205GB | B14: =VLOOKUP(A14,'CostBill 一件代发费用录入'!O:Q,4,0) -> #REF! | C14: =VLOOKUP(A14,'CostBill 一件代发费用录入'!D:S,16,0) -> 2025-01-29 14:52:00
... A98: OJ590792088GB | B98: =VLOOKUP(A98,'CostBill 一件代发费用录入'!O:Q,4,0) -> #REF! | C98: =VLOOKUP(A98,'CostBill 一件代发费用录入'!D:S,16,0) -> 2025-01-02 08:54:04

Sheet Sheet1
A1: 跟踪号 | G1: OJ743957005GB | H1: 1.646
A2: OJ743957005GB | B2: =SUMIF([1]CostBill!$D:$M,A2,[1]CostBill!$M:$M) -> 2.96 | C2: 45716 | D2: =VLOOKUP(A2,G:H,2,0) -> 1.646 | G2: OJ743957005GB | H2: 1.646
A3: OJ743956999GB | B3: =SUMIF([1]CostBill!$D:$M,A3,[1]CostBill!$M:$M) -> 2.89 | C3: 45716 | D3: =VLOOKUP(A3,G:H,2,0) -> 0.605 | G3: OJ743957005GB | H3: 1.646
A4: OJ743968201GB | B4: =SUMIF([1]CostBill!$D:$M,A4,[1]CostBill!$M:$M) -> 2.89 | C4: 45716 | D4: =VLOOKUP(A4,G:H,2,0) -> 0.605 | G4: OJ743956999GB | H4: 0.605
A5: OJ729364261GB | B5: =SUMIF([1]CostBill!$D:$M,A5,[1]CostBill!$M:$M) -> 2.96 | C5: 45715 | D5: =VLOOKUP(A5,G:H,2,0) -> 1.869 | G5: OJ743956999GB | H5: 0.605
A6: OJ729370409GB | B6: =SUMIF([1]CostBill!$D:$M,A6,[1]CostBill!$M:$M) -> 2.89 | C6: 45715 | D6: =VLOOKUP(A6,G:H,2,0) -> 0.605 | G6: OJ743968201GB | H6: 0.605
A7: OJ729353003GB | B7: =SUMIF([1]CostBill!$D:$M,A7,[1]CostBill!$M:$M) -> 2.96 | C7: 45715 | D7: =VLOOKUP(A7,G:H,2,0) -> 1.674 | G7: OJ743968201GB | H7: 0.605
A8: OJ729352569GB | B8: =SUMIF([1]CostBill!$D:$M,A8,[1]CostBill!$M:$M) -> 3.4 | C8: 45715 | D8: =VLOOKUP(A8,G:H,2,0) -> 2.050 | G8: OJ729364261GB | H8: 1.869
A9: OJ729352586GB | B9: =SUMIF([1]CostBill!$D:$M,A9,[1]CostBill!$M:$M) -> 2.96 | C9: 45715 | D9: =VLOOKUP(A9,G:H,2,0) -> 1.348 | G9: OJ729364261GB | H9: 1.869
A10: OJ728599124GB | B10: =SUMIF([1]CostBill!$D:$M,A10,[1]CostBill!$M:$M) -> 2.89 | C10: 45714 | D10: =VLOOKUP(A10,G:H,2,0) -> 0.358 | G10: OJ729364261GB | H10: 1.869
A11: OJ728504118GB | B11: =SUMIF([1]CostBill!$D:$M,A11,[1]CostBill!$M:$M) -> 2.89 | C11: 45714 | D11: =VLOOKUP(A11,G:H,2,0) -> 0.568 | G11: OJ729370409GB | H11: 0.605
A12: OJ727633408GB | B12: =SUMIF([1]CostBill!$D:$M,A12,[1]CostBill!$M:$M) -> 2.96 | C12: 45713 | D12: =VLOOKUP(A12,G:H,2,0) -> 1.646 | G12: OJ729370409GB | H12: 0.605
A13: OJ727651503GB | B13: =SUMIF([1]CostBill!$D:$M,A13,[1]CostBill!$M:$M) -> 2.96 | C13: 45713 | D13: =VLOOKUP(A13,G:H,2,0) -> 1.827 | G13: OJ729353003GB | H13: 1.674
... A143: OJ663664657GB | B143: =SUMIF([1]CostBill!$D:$M,A143,[1]CostBill!$M:$M) -> 4.19 | C143: 45691 | D143: =VLOOKUP(A143,G:H,2,0) -> 0.148 | G143: OJ723730466GB | H143: 1.139
G144: OJ723730466GB | H144: 1.139
G145: OJ723730466GB | H145: 1.139
G146: OJ723731577GB | H146: 1.139
G147: OJ723731577GB | H147: 1.139
G148: OJ723731577GB | H148: 1.139
G149: OJ722949290GB | H149: 1.139
G150: OJ722949290GB | H150: 1.139
G151: OJ722949290GB | H151: 1.139
G152: OJ722950409GB | H152: 1.139
G153: OJ722950409GB | H153: 1.139
G154: OJ722950409GB | H154: 1.139
G155: OJ722951625GB | H155: 1.139
... G453: OJ663664657GB | H453: 0.148
