Workbook

Sheet first load不准确
A1: Item Key | B1: SKU | C1: Description | D1: Expiry Date | E1: Batch Ref. | F1: Qty | G1: Pallet | H1: Location | I1: comment | J1: Pallet Total | K1: Units Per Carton | L1: Total Cartons
A2: B01A7QZ9ZM | B2: X000N8HM4L | C2: Silicone utensil set | F2: 72 | G2: PLT286590 | H2: H1465A | I2: 1st load | J2: 1 | K2: 12 | L2: =F2/K2 -> 6
A3: B075K9FPQT | B3: X000OXVBEH | C3: truck | F3: 64 | G3: PLT286568 | H3: H1471A | I3: 1st load | J3: 1 | K3: 8 | L3: =F3/K3 -> 8
A4: B07DPF53MT | B4: X000TDXL0T | C4: Pizza steel | F4: 114 | G4: PLT306402 | H4: H1334A | I4: 1st load | J4: 1 | K4: 3 | L4: =F4/K4 -> 38
A5: B08PVF9NWP | B5: X000WGHKHX | C5: 24 cupcakes | F5: 3 | G5: PLT286588 | H5: H1342A | I5: 1st load | J5: 1 | K5: 30 | L5: 1
A6: B01IP5VT2O | B6: X000N8IVQJ | C6: Premium pizza cutter | F6: 612 | G6: PLT306414 | H6: H1343A | I6: 1st load | J6: 1 | K6: 36 | L6: =F6/K6 -> 17
A7: B07FXG4JVG | C7: HOBART DECANTER | F7: 36 | G7: PLT693476 | H7: H1372A | I7: 1st load | J7: 1 | K7: 3 | L7: =F7/K7 -> 12
A8: B01M74A279 | C8: Pre-Seasoned 12 Inch (30cm) Cast Iron Skillet Fry Pan. | D8: 28-Feb-2024 | E8: 21BP177 | F8: 2144 | G8: PLT509018 | H8: H1384A | I8: 1st load | J8: 18 | K8: 4 | L8: =F8/K8 -> 536
A9: B07881WCQY | C9: TWIST DECANTER SET | F9: 162 | G9: PLT664561 | H9: H1274A | I9: 1st load | J9: 3 | K9: 3 | L9: =F9/K9 -> 54
A10: B07V32FG4Q | C10: Dutch Oven 5.2 litre | D10: 28-Feb-2024 | E10: 21BP177 | F10: 1750 | G10: PLT439320 | H10: H1381A | I10: 1st load | J10: 25 | K10: 2 | L10: =F10/K10 -> 875
A11: B08R6SKCVN | B11: X000WKNCNP | C11: icecream scoop | F11: 1584 | G11: PLT286576 | H11: H1346A | I11: 1st load | J11: 2 | K11: 48 | L11: =F11/K11 -> 33
A12: B095W2MLPF | C12: Canvas Baby Swing CREAM | F12: 192 | G12: PLT663931 | H12: H1370A | I12: 1st load | J12: 2 | K12: 6 | L12: =F12/K12 -> 32
F13: =SUM(F2:F12) -> 6733 | J13: =SUM(J2:J12) -> 56 | L13: =SUM(L2:L12) -> 1612

Sheet 托盘清单
A1: Item Key | B1: SKU | C1: Description | D1: Expiry Date | E1: Batch Ref. | F1: Qty | G1: Pallet | H1: Location | I1: comment | J1: Pallet Total | K1: Units Per Carton | L1: Total Cartons
A2: B07V32FG4Q | C2: Dutch Oven 5.2 litre | D2: 28-Feb-2024 | E2: 21BP177 | F2: 72 | G2: PLT508857 | H2: H1363A | I2: 1st load | J2: 1 | K2: 2 | L2: =F2/K2 -> 36
A3: B08R6SKCVN | B3: X000WKNCNP | C3: icecream scoop | F3: 528 | G3: PLT286570 | H3: H1431A | I3: 1st load | J3: 1 | K3: 48 | L3: =F3/K3 -> 11
A4: B01A7QZ9ZM | B4: X000N8HM4L | C4: Silicone utensil set | F4: 72 | G4: PLT286590 | H4: H1465A | I4: 1st load | J4: 1 | K4: 12 | L4: =F4/K4 -> 6
A5: B01M74A279 | C5: Pre-Seasoned 12 Inch (30cm) Cast Iron Skillet Fry Pan. | D5: 28-Feb-2024 | E5: 21BP177 | F5: 128 | G5: PLT509005 | H5: H1468A | I5: 1st load | J5: 1 | K5: 4 | L5: =F5/K5 -> 32
A6: B075K9FPQT | B6: X000OXVBEH | C6: truck | F6: 64 | G6: PLT286568 | H6: H1471A | I6: 1st load | J6: 1 | K6: 8 | L6: =F6/K6 -> 8
A7: B01M74A279 | C7: Pre-Seasoned 12 Inch (30cm) Cast Iron Skillet Fry Pan. | D7: 28-Feb-2024 | E7: 21BP177 | F7: 128 | G7: PLT508962 | H7: H1472A | I7: 1st load | J7: 1 | K7: 4 | L7: =F7/K7 -> 32
A8: B07V32FG4Q | C8: Dutch Oven 5.2 litre | D8: 24-Feb-2024 | E8: 21BP177 | F8: 66 | G8: PLT509078 | H8: H1479A | I8: 1st load | J8: 1 | K8: 2 | L8: =F8/K8 -> 33
A9: B07V32FG4Q | C9: Dutch Oven 5.2 litre | D9: 29-Feb-2024 | E9: 21BP177 | F9: 66 | G9: PLT508932 | H9: H1481A | I9: 1st load | J9: 1 | K9: 2 | L9: =F9/K9 -> 33
A10: B07V32FG4Q | C10: Dutch Oven 5.2 litre | D10: 28-Feb-2024 | E10: 21BP177 | F10: 72 | G10: PLT509007 | H10: H1483A | I10: 1st load | J10: 1 | K10: 2 | L10: =F10/K10 -> 36
A11: B07V32FG4Q | C11: Dutch Oven 5.2 litre | D11: 28-Feb-2024 | E11: 21BP177 | F11: 72 | G11: PLT509008 | H11: SH1384A | I11: 1st load | J11: 1 | K11: 2 | L11: =F11/K11 -> 36
A12: B01M74A279 | C12: Pre-Seasoned 12 Inch (30cm) Cast Iron Skillet Fry Pan. | D12: 29-Feb-2024 | E12: 21BP177 | F12: 96 | G12: PLT500537 | H12: H0302F | I12: 1st load | J12: 1 | K12: 4 | L12: =F12/K12 -> 24
A13: B07V32FG4Q | C13: Dutch Oven 5.2 litre | D13: 29-Feb-2024 | E13: 21BP177 | F13: 66 | G13: PLT500528 | H13: H0304F | I13: 1st load | J13: 1 | K13: 2 | L13: =F13/K13 -> 33
A14: B07881WCQY | C14: TWIST DECANTER SET | F14: 54 | G14: PLT664573 | H14: H0308C | I14: 1st load | J14: 1 | K14: 3 | L14: =F14/K14 -> 18
A15: B01M74A279 | C15: Pre-Seasoned 12 Inch (30cm) Cast Iron Skillet Fry Pan. | D15: 28-Feb-2024 | E15: 21BP177 | F15: 128 | G15: PLT509010 | H15: H0313D | I15: 1st load | J15: 1 | K15: 4 | L15: =F15/K15 -> 32
A16: B01M74A279 | C16: Pre-Seasoned 12 Inch (30cm) Cast Iron Skillet Fry Pan. | D16: 29-Feb-2024 | E16: 21BP177 | F16: 96 | G16: PLT500539 | H16: H0314E | I16: 1st load | J16: 1 | K16: 4 | L16: =F16/K16 -> 24
A17: B07V32FG4Q | C17: Dutch Oven 5.2 litre | D17: 28-Feb-2024 | E17: 21BP177 | F17: 72 | G17: PLT508849 | H17: H0320E | I17: 1st load | J17: 1 | K17: 2 | L17: =F17/K17 -> 36
A18: B07881WCQY | C18: TWIST DECANTER SET | F18: 54 | G18: PLT664533 | H18: H0324C | I18: 1st load | J18: 1 | K18: 3 | L18: =F18/K18 -> 18
A19: B07V32FG4Q | C19: Dutch Oven 5.2 litre | D19: 28-Feb-2024 | E19: 21BP177 | F19: 72 | G19: PLT509006 | H19: H0340F | I19: 1st load | J19: 1 | K19: 2 | L19: =F19/K19 -> 36
A20: B01M74A279 | C20: Pre-Seasoned 12 Inch (30cm) Cast Iron Skillet Fry Pan. | D20: 29-Feb-2024 | E20: 21BP177 | F20: 96 | G20: PLT508984 | H20: H0347D | I20: 1st load | J20: 1 | K20: 4 | L20: =F20/K20 -> 24
A21: B07V32FG4Q | C21: Dutch Oven 5.2 litre | D21: 28-Feb-2024 | E21: 21BP177 | F21: 72 | G21: PLT508850 | H21: H0349F | I21: 1st load | J21: 1 | K21: 2 | L21: =F21/K21 -> 36
A22: B07V32FG4Q | C22: Dutch Oven 5.2 litre | D22: 28-Feb-2024 | E22: 21BP177 | F22: 72 | G22: PLT508860 | H22: H0405G | I22: 1st load | J22: 1 | K22: 2 | L22: =F22/K22 -> 36
A23: B07V32FG4Q | C23: Dutch Oven 5.2 litre | D23: 28-Feb-2024 | E23: 21BP177 | F23: 72 | G23: PLT508865 | H23: H0409G | I23: 1st load | J23: 1 | K23: 2 | L23: =F23/K23 -> 36
A24: B01M74A279 | C24: Pre-Seasoned 12 Inch (30cm) Cast Iron Skillet Fry Pan. | D24: 28-Feb-2024 | E24: 21BP177 | F24: 128 | G24: PLT508967 | H24: H0411G | I24: 1st load | J24: 1 | K24: 4 | L24: =F24/K24 -> 32
A25: B01M74A279 | C25: Pre-Seasoned 12 Inch (30cm) Cast Iron Skillet Fry Pan. | D25: 28-Feb-2024 | E25: 21BP177 | F25: 128 | G25: PLT508837 | H25: H0417G | I25: 1st load | J25: 1 | K25: 4 | L25: =F25/K25 -> 32
A26: B07V32FG4Q | C26: Dutch Oven 5.2 litre | D26: 24-Feb-2024 | E26: 21BP177 | F26: 72 | G26: PLT509048 | H26: H0419G | I26: 1st load | J26: 1 | K26: 2 | L26: =F26/K26 -> 36
A27: B07V32FG4Q | C27: Dutch Oven 5.2 litre | D27: 28-Feb-2024 | E27: 21BP177 | F27: 72 | G27: PLT077925 | H27: H0423G | I27: 1st load | J27: 1 | K27: 2 | L27: =F27/K27 -> 36
A28: B01M74A279 | C28: Pre-Seasoned 12 Inch (30cm) Cast Iron Skillet Fry Pan. | D28: 28-Feb-2024 | E28: 21BP177 | F28: 128 | G28: PLT834013 | H28: H0425G | I28: 1st load | J28: 1 | K28: 4 | L28: =F28/K28 -> 32
A29: B07V32FG4Q | C29: Dutch Oven 5.2 litre | D29: 28-Feb-2024 | E29: 21BP177 | F29: 72 | G29: PLT834014 | H29: H0427G | I29: 1st load | J29: 1 | K29: 2 | L29: =F29/K29 -> 36
A30: B07V32FG4Q | C30: Dutch Oven 5.2 litre | D30: 28-Feb-2024 | E30: 21BP177 | F30: 72 | G30: PLT508864 | H30: H0429G | I30: 1st load | J30: 1 | K30: 2 | L30: =F30/K30 -> 36
A31: B01M74A279 | C31: Pre-Seasoned 12 Inch (30cm) Cast Iron Skillet Fry Pan. | D31: 28-Feb-2024 | E31: 21BP177 | F31: 128 | G31: PLT509013 | H31: H0431G | I31: 1st load | J31: 1 | K31: 4 | L31: =F31/K31 -> 32
A32: B095W2MLPF | C32: Canvas Baby Swing CREAM | F32: 96 | G32: PLT290982 | H32: H0918A | I32: 1st load | J32: 1 | K32: 6 | L32: =F32/K32 -> 16
A33: B01M74A279 | C33: Pre-Seasoned 12 Inch (30cm) Cast Iron Skillet Fry Pan. | D33: 29-Feb-2024 | E33: 21BP177 | F33: 96 | G33: PLT508929 | H33: H1264A | I33: 1st load | J33: 1 | K33: 4 | L33: =F33/K33 -> 24
A34: B07V32FG4Q | C34: Dutch Oven 5.2 litre | D34: 24-Feb-2024 | E34: 21BP177 | F34: 66 | G34: PLT509073 | H34: H1266A | I34: 1st load | J34: 1 | K34: 2 | L34: =F34/K34 -> 33
A35: B07V32FG4Q | C35: Dutch Oven 5.2 litre | D35: 24-Feb-2024 | E35: 21BP177 | F35: 64 | G35: PLT509105 | H35: H1267A | I35: 1st load | J35: 1 | K35: 2 | L35: =F35/K35 -> 32
A36: B07V32FG4Q | C36: Dutch Oven 5.2 litre | D36: 28-Feb-2024 | E36: 21BP177 | F36: 72 | G36: PLT508871 | H36: H1268A | I36: 1st load | J36: 1 | K36: 2 | L36: =F36/K36 -> 36
A37: B07881WCQY | C37: TWIST DECANTER SET | F37: 54 | G37: PLT664561 | H37: H1274A | I37: 1st load | J37: 1 | K37: 3 | L37: =F37/K37 -> 18
A38: B07V32FG4Q | C38: Dutch Oven 5.2 litre | D38: 28-Feb-2024 | E38: 21BP177 | F38: 72 | G38: PLT508848 | H38: H1276A | I38: 1st load | J38: 1 | K38: 2 | L38: =F38/K38 -> 36
A39: B07V32FG4Q | C39: Dutch Oven 5.2 litre | D39: 29-Feb-2024 | E39: 21BP177 | F39: 66 | G39: PLT508920 | H39: H1277A | I39: 1st load | J39: 1 | K39: 2 | L39: =F39/K39 -> 33
A40: B07V32FG4Q | C40: Dutch Oven 5.2 litre | D40: 29-Feb-2024 | E40: 21BP177 | F40: 66 | G40: PLT508931 | H40: H1284A | I40: 1st load | J40: 1 | K40: 2 | L40: =F40/K40 -> 33
...

Sheet first load
A1: ASIN | B1: FN SKU | C1: Discrp | D1: Item Name | E1: Quantity | F1: per ctn | G1: total carton
A2: B07T2XNN7C | B2: X000RV2Y1P | C2: =VLOOKUP(A2,[1]澳洲!$A$2:$D$36,4,FALSE) -> Launceston Whiskey Glasses 2pk | D2: =VLOOKUP(A2,[1]澳洲!$A$2:$E$36,5,FALSE) -> 朗塞斯顿威士忌杯 2 件装 | E2: 10 | F2: 10 | G2: =E2/F2 -> 1
A3: B081HZBM5Z | B3: X000V2PDO5 | C3: =VLOOKUP(A3,[1]澳洲!$A$2:$D$36,4,FALSE) -> Dough Scraper and Pastry Mat Set | D3: =VLOOKUP(A3,[1]澳洲!$A$2:$E$36,5,FALSE) -> 面团刮刀和糕点垫套装 | E3: 325 | F3: 36 | G3: =E3/F3 -> 9.0277778
A4: B082M3SLJ7 | B4: X000TEKLUB | C4: =VLOOKUP(A4,[1]澳洲!$A$2:$D$36,4,FALSE) -> Basketball Bag Backpack | D4: =VLOOKUP(A4,[1]澳洲!$A$2:$E$36,5,FALSE) -> 篮球包背包 | E4: 2 | F4: 20 | G4: =E4/F4 -> 0.1
A5: B01A7QZ9ZM | B5: X000N8HM4L | C5: =VLOOKUP(A5,[1]澳洲!$A$2:$D$36,4,FALSE) -> Silicone Kitchen Utensils 5 Pieces | D5: =VLOOKUP(A5,[1]澳洲!$A$2:$E$36,5,FALSE) -> 硅胶厨房用具5件套 | E5: 72 | F5: 12 | G5: =E5/F5 -> 6
A6: B07DPF53MT | B6: X000TDXL0T | C6: =VLOOKUP(A6,[1]澳洲!$A$2:$D$36,4,FALSE) -> Steel Pizza Stone for Baking | D6: =VLOOKUP(A6,[1]澳洲!$A$2:$E$36,5,FALSE) -> 烘焙用钢披萨石 | E6: 0 | F6: 3 | G6: =E6/F6 -> 0
A7: B07RVDKZC2 | B7: X000U6KVA3 | C7: =VLOOKUP(A7,[1]澳洲!$A$2:$D$36,4,FALSE) -> 3 Tiered Checkered Cupcake Stand | D7: =VLOOKUP(A7,[1]澳洲!$A$2:$E$36,5,FALSE) -> 3 层格子蛋糕架 | E7: 80 | F7: 8 | G7: =E7/F7 -> 10
A8: B08PVF9NWP | B8: X000WGHKHX | C8: =VLOOKUP(A8,[1]澳洲!$A$2:$D$36,4,FALSE) -> Silicone Cupcake Moulds 24 Pack | D8: =VLOOKUP(A8,[1]澳洲!$A$2:$E$36,5,FALSE) -> 硅胶纸杯蛋糕模具 24 件装 | E8: 3 | F8: 30 | G8: =E8/F8 -> 0.1
A9: B01IP5VT2O | B9: X000N8IVQJ | C9: =VLOOKUP(A9,[1]澳洲!$A$2:$D$36,4,FALSE) -> Premium Pizza Cutter Oscillating Blade | D9: =VLOOKUP(A9,[1]澳洲!$A$2:$E$36,5,FALSE) -> 优质披萨切割机摆动刀片 | E9: 612 | F9: 36 | G9: =E9/F9 -> 17
A10: B08R6SKCVN | B10: X000WKNCNP | C10: =VLOOKUP(A10,[1]澳洲!$A$2:$D$36,4,FALSE) -> Heavy Duty Icecream Scoop | D10: =VLOOKUP(A10,[1]澳洲!$A$2:$E$36,5,FALSE) -> 重型冰淇淋勺 | E10: 1056 | F10: 48 | G10: =E10/F10 -> 22
A11: B095W2MLPF | B11: B095W2MLPF | C11: =VLOOKUP(A11,[1]澳洲!$A$2:$D$36,4,FALSE) -> Canvas and Wood Swinging Chair Cream | D11: =VLOOKUP(A11,[1]澳洲!$A$2:$E$36,5,FALSE) -> 帆布和木质秋千椅奶油色 | E11: 192 | F11: 6 | G11: =E11/F11 -> 32
A12: B07V32FG4Q | C12: =VLOOKUP(A12,[1]澳洲!$A$2:$D$36,4,FALSE) -> Pre-Seasoned Cast Iron Double Dutch Oven | D12: =VLOOKUP(A12,[1]澳洲!$A$2:$E$36,5,FALSE) -> 预调味铸铁双层荷兰烤箱 | E12: 1612 | F12: 2 | G12: =E12/F12 -> 806
A13: B01M74A279 | C13: =VLOOKUP(A13,[1]澳洲!$A$2:$D$36,4,FALSE) -> Pre-Seasoned Cast Iron Skillet 12.5" | D13: =VLOOKUP(A13,[1]澳洲!$A$2:$E$36,5,FALSE) -> 预调味铸铁煎锅 12.5" | E13: 2272 | F13: 4 | G13: =E13/F13 -> 568
A14: B07FXG4JVG | C14: =VLOOKUP(A14,[1]澳洲!$A$2:$D$36,4,FALSE) -> Whisky Decanter and 4 Whiskey Glasses Hobart | D14: =VLOOKUP(A14,[1]澳洲!$A$2:$E$36,5,FALSE) -> 霍巴特威士忌醒酒器和 4 个威士忌杯 | E14: 36 | F14: 3 | G14: =E14/F14 -> 12
A15: B07881WCQY | C15: =VLOOKUP(A15,[1]澳洲!$A$2:$D$36,4,FALSE) -> Whisky Decanter and 4 Whiskey Glasses Tasman | D15: =VLOOKUP(A15,[1]澳洲!$A$2:$E$36,5,FALSE) -> 威士忌醒酒器和 4 个塔斯曼威士忌杯 | E15: 165 | F15: 3 | G15: =E15/F15 -> 55
E16: =SUM(E2:E15) -> 6437
F20: 54托

Sheet Nutrilock
A1: Id | B1: Facility | C1: Snap Shot Date | D1: Customer | E1: Sku | F1: Sku Description | G1: Qty | H1: FitStatus | I1: Batch | J1: Expiry date | K1: Location | L1: Length | M1: Width | N1: Height | O1: Pallet Space Calculation | P1: Pallet Counted Bill | Q1: Standard Pallet - (upto 1.4m) | R1: Standard Pallet - (upto 1.8m) | S1: Standard Pallet - (upto 2.2m) | T1: Pick Pallet Bill | U1: Pick Flow Rack Bill | V1: Pick Shelf Bill | W1: DG Flag | X1: Refrigerated | Y1: Bill Type
A2: 81434269 | B2: WH7 | C2: 2025-01-07 | D2: NUTRILOCK | E2: B01M74A279 | F2: Pre-Seasoned 12 Inch (30cm) Cast Iron Skillet Fry Pan. | G2: 100 | H2: sale | I2: 21BP177 | J2: 2024-02-28 | K2: H0762D | L2: 310 | M2: 430 | N2: 310 | O2: Sku | P2: 1 | Q2: 1 | R2: 0 | S2: 0 | T2: 0 | U2: 0 | V2: 0 | W2: N | X2: N | Y2: Pallet Racking
A3: 81434267 | B3: WH7 | C3: 2025-01-07 | D3: NUTRILOCK | E3: B01M74A279 | F3: Pre-Seasoned 12 Inch (30cm) Cast Iron Skillet Fry Pan. | G3: 128 | H3: sale | I3: 21BP177 | J3: 2024-02-28 | K3: H0467G | L3: 310 | M3: 430 | N3: 310 | O3: Sku | P3: 1 | Q3: 1 | R3: 0 | S3: 0 | T3: 0 | U3: 0 | V3: 0 | W3: N | X3: N | Y3: Pallet Racking
A4: 81434268 | B4: WH7 | C4: 2025-01-07 | D4: NUTRILOCK | E4: B01M74A279 | F4: Pre-Seasoned 12 Inch (30cm) Cast Iron Skillet Fry Pan. | G4: 128 | H4: sale | I4: 21BP177 | J4: 2024-02-28 | K4: H0469G | L4: 310 | M4: 430 | N4: 310 | O4: Sku | P4: 1 | Q4: 1 | R4: 0 | S4: 0 | T4: 0 | U4: 0 | V4: 0 | W4: N | X4: N | Y4: Pallet Racking
A5: 81434259 | B5: WH7 | C5: 2025-01-07 | D5: NUTRILOCK | E5: B01M74A279 | F5: Pre-Seasoned 12 Inch (30cm) Cast Iron Skillet Fry Pan. | G5: 128 | H5: sale | I5: 21BP177 | J5: 2024-02-29 | K5: SH1284C | L5: 310 | M5: 430 | N5: 310 | O5: Sku | P5: 1 | Q5: 1 | R5: 0 | S5: 0 | T5: 0 | U5: 0 | V5: 0 | W5: N | X5: N | Y5: Pallet Racking
A6: 81434261 | B6: WH7 | C6: 2025-01-07 | D6: NUTRILOCK | E6: B01M74A279 | F6: Pre-Seasoned 12 Inch (30cm) Cast Iron Skillet Fry Pan. | G6: 76 | H6: sale | I6: 21BP177 | J6: 2024-02-24 | K6: H1279B | L6: 310 | M6: 430 | N6: 310 | O6: Sku | P6: 1 | Q6: 1 | R6: 0 | S6: 0 | T6: 0 | U6: 0 | V6: 0 | W6: N | X6: N | Y6: Pallet Racking
A7: 81434260 | B7: WH7 | C7: 2025-01-07 | D7: NUTRILOCK | E7: B01M74A279 | F7: Pre-Seasoned 12 Inch (30cm) Cast Iron Skillet Fry Pan. | G7: 95 | H7: sale | I7: 21BP177 | J7: 2024-02-29 | K7: SH984D | L7: 310 | M7: 430 | N7: 310 | O7: Sku | P7: 1 | Q7: 1 | R7: 0 | S7: 0 | T7: 0 | U7: 0 | V7: 0 | W7: N | X7: N | Y7: Pallet Racking
A8: 81434270 | B8: WH7 | C8: 2025-01-07 | D8: NUTRILOCK | E8: B01M74A279 | F8: Pre-Seasoned 12 Inch (30cm) Cast Iron Skillet Fry Pan. | G8: 96 | H8: sale | I8: 21BP177 | J8: 2024-02-24 | K8: H0772B | L8: 310 | M8: 430 | N8: 310 | O8: Sku | P8: 1 | Q8: 1 | R8: 0 | S8: 0 | T8: 0 | U8: 0 | V8: 0 | W8: N | X8: N | Y8: Pallet Racking
A9: 81434262 | B9: WH7 | C9: 2025-01-07 | D9: NUTRILOCK | E9: B01M74A279 | F9: Pre-Seasoned 12 Inch (30cm) Cast Iron Skillet Fry Pan. | G9: 96 | H9: sale | I9: 21BP177 | J9: 2024-02-24 | K9: H1281B | L9: 310 | M9: 430 | N9: 310 | O9: Sku | P9: 1 | Q9: 1 | R9: 0 | S9: 0 | T9: 0 | U9: 0 | V9: 0 | W9: N | X9: N | Y9: Pallet Racking
A10: 81434257 | B10: WH7 | C10: 2025-01-07 | D10: NUTRILOCK | E10: B01M74A279 | F10: Pre-Seasoned 12 Inch (30cm) Cast Iron Skillet Fry Pan. | G10: 96 | H10: sale | I10: 21BP177 | J10: 2024-02-24 | K10: K1363G | L10: 310 | M10: 430 | N10: 310 | O10: Sku | P10: 1 | Q10: 1 | R10: 0 | S10: 0 | T10: 0 | U10: 0 | V10: 0 | W10: N | X10: N | Y10: Pallet Racking
A11: 81434271 | B11: WH7 | C11: 2025-01-07 | D11: NUTRILOCK | E11: B01M74A279 | F11: Pre-Seasoned 12 Inch (30cm) Cast Iron Skillet Fry Pan. | G11: 96 | H11: sale | I11: 21BP177 | J11: 2024-02-29 | K11: H0879D | L11: 310 | M11: 430 | N11: 310 | O11: Sku | P11: 1 | Q11: 1 | R11: 0 | S11: 0 | T11: 0 | U11: 0 | V11: 0 | W11: N | X11: N | Y11: Pallet Racking
A12: 81434272 | B12: WH7 | C12: 2025-01-07 | D12: NUTRILOCK | E12: B01M74A279 | F12: Pre-Seasoned 12 Inch (30cm) Cast Iron Skillet Fry Pan. | G12: 96 | H12: sale | I12: 21BP177 | J12: 2024-02-29 | K12: H1268C | L12: 310 | M12: 430 | N12: 310 | O12: Sku | P12: 1 | Q12: 1 | R12: 0 | S12: 0 | T12: 0 | U12: 0 | V12: 0 | W12: N | X12: N | Y12: Pallet Racking
A13: 81434263 | B13: WH7 | C13: 2025-01-07 | D13: NUTRILOCK | E13: B01M74A279 | F13: Pre-Seasoned 12 Inch (30cm) Cast Iron Skillet Fry Pan. | G13: 96 | H13: sale | I13: 21BP177 | J13: 2024-02-29 | K13: H1282B | L13: 310 | M13: 430 | N13: 310 | O13: Sku | P13: 1 | Q13: 1 | R13: 0 | S13: 0 | T13: 0 | U13: 0 | V13: 0 | W13: N | X13: N | Y13: Pallet Racking
... A18: 81434258 | B18: WH7 | C18: 2025-01-07 | D18: NUTRILOCK | E18: B01M74A279 | F18: Pre-Seasoned 12 Inch (30cm) Cast Iron Skillet Fry Pan. | G18: 96 | H18: sale | I18: 21BP177 | J18: 2024-02-29 | K18: R4O-22-D1 | L18: 310 | M18: 430 | N18: 310 | O18: Sku | P18: 1 | Q18: 1 | R18: 0 | S18: 0 | T18: 0 | U18: 0 | V18: 0 | W18: N | X18: N | Y18: Pallet Racking
A19: 81434246 | B19: WH7 | C19: 2025-01-07 | D19: NUTRILOCK | E19: B07881WCQY | F19: TWIST DECANTER SET | G19: 42 | H19: sale | K19: K1333F | L19: 352 | M19: 374 | N19: 352 | O19: Sku | P19: 1 | Q19: 1 | R19: 0 | S19: 0 | T19: 0 | U19: 0 | V19: 0 | W19: N | X19: N | Y19: Pallet Racking
A20: 81434247 | B20: WH7 | C20: 2025-01-07 | D20: NUTRILOCK | E20: B07881WCQY | F20: TWIST DECANTER SET | G20: 54 | H20: sale | K20: K1345C | L20: 352 | M20: 374 | N20: 352 | O20: Sku | P20: 1 | Q20: 1 | R20: 0 | S20: 0 | T20: 0 | U20: 0 | V20: 0 | W20: N | X20: N | Y20: Pallet Racking
A21: 81434245 | B21: WH7 | C21: 2025-01-07 | D21: NUTRILOCK | E21: B07881WCQY | F21: TWIST DECANTER SET | G21: 6 | H21: sale | K21: H1376B | L21: 352 | M21: 374 | N21: 352 | O21: Sku | P21: 1 | Q21: 1 | R21: 0 | S21: 0 | T21: 0 | U21: 0 | V21: 0 | W21: N | X21: N | Y21: Pallet Racking
A22: 81434249 | B22: WH7 | C22: 2025-01-07 | D22: NUTRILOCK | E22: B07FXG4JVG | F22: HOBART DECANTER | G22: 12 | H22: sale | K22: H1372B | L22: 355 | M22: 375 | N22: 355 | O22: Sku | P22: 0 | Q22: 0 | R22: 0 | S22: 0 | T22: 0 | U22: 0 | V22: 0 | W22: N | X22: N
A23: 81434250 | B23: WH7 | C23: 2025-01-07 | D23: NUTRILOCK | E23: B07FXG4JVG | F23: HOBART DECANTER | G23: 18 | H23: sale | K23: H1372B | L23: 355 | M23: 375 | N23: 355 | O23: Sku | P23: 0 | Q23: 0 | R23: 0 | S23: 0 | T23: 0 | U23: 0 | V23: 0 | W23: N | X23: N
A24: 81434252 | B24: WH7 | C24: 2025-01-07 | D24: NUTRILOCK | E24: B07FXG4JVG | F24: HOBART DECANTER | G24: 27 | H24: sale | K24: H1583D | L24: 355 | M24: 375 | N24: 355 | O24: Sku | P24: 1 | Q24: 1 | R24: 0 | S24: 0 | T24: 0 | U24: 0 | V24: 0 | W24: N | X24: N | Y24: Pallet Racking
A25: 81434255 | B25: WH7 | C25: 2025-01-07 | D25: NUTRILOCK | E25: B07FXG4JVG | F25: HOBART DECANTER | G25: 30 | H25: sale | K25: H1073D | L25: 355 | M25: 375 | N25: 355 | O25: Sku | P25: 1 | Q25: 1 | R25: 0 | S25: 0 | T25: 0 | U25: 0 | V25: 0 | W25: N | X25: N | Y25: Pallet Racking
A26: 81434253 | B26: WH7 | C26: 2025-01-07 | D26: NUTRILOCK | E26: B07FXG4JVG | F26: HOBART DECANTER | G26: 54 | H26: sale | K26: H0769C | L26: 355 | M26: 375 | N26: 355 | O26: Sku | P26: 1 | Q26: 1 | R26: 0 | S26: 0 | T26: 0 | U26: 0 | V26: 0 | W26: N | X26: N | Y26: Pallet Racking
A27: 81434254 | B27: WH7 | C27: 2025-01-07 | D27: NUTRILOCK | E27: B07FXG4JVG | F27: HOBART DECANTER | G27: 54 | H27: sale | K27: H1072E | L27: 355 | M27: 375 | N27: 355 | O27: Sku | P27: 1 | Q27: 1 | R27: 0 | S27: 0 | T27: 0 | U27: 0 | V27: 0 | W27: N | X27: N | Y27: Pallet Racking
A28: 81434248 | B28: WH7 | C28: 2025-01-07 | D28: NUTRILOCK | E28: B07FXG4JVG | F28: HOBART DECANTER | G28: 6 | H28: sale | K28: H1372B | L28: 355 | M28: 375 | N28: 355 | O28: Sku | P28: 1 | Q28: 1 | R28: 0 | S28: 0 | T28: 0 | U28: 0 | V28: 0 | W28: N | X28: N | Y28: Pallet Racking
A29: 81434251 | B29: WH7 | C29: 2025-01-07 | D29: NUTRILOCK | E29: B07FXG4JVG | F29: HOBART DECANTER | G29: 6 | H29: sale | K29: H1378B | L29: 355 | M29: 375 | N29: 355 | O29: Sku | P29: 1 | Q29: 1 | R29: 0 | S29: 0 | T29: 0 | U29: 0 | V29: 0 | W29: N | X29: N | Y29: Pallet Racking
A30: 81434306 | B30: WH7 | C30: 2025-01-07 | D30: NUTRILOCK | E30: B07V32FG4Q | F30: Dutch Oven 5.2 litre | G30: 32 | H30: sale | I30: 21BP177 | J30: 2024-02-28 | K30: H0749C | L30: 150 | M30: 285 | N30: 150 | O30: Sku | P30: 1 | Q30: 1 | R30: 0 | S30: 0 | T30: 0 | U30: 0 | V30: 0 | W30: N | X30: N | Y30: Pallet Racking
A31: 81434295 | B31: WH7 | C31: 2025-01-07 | D31: NUTRILOCK | E31: B07V32FG4Q | F31: Dutch Oven 5.2 litre | G31: 42 | H31: sale | I31: 21BP177 | J31: 2024-02-28 | K31: H1075D | L31: 150 | M31: 285 | N31: 150 | O31: Sku | P31: 1 | Q31: 1 | R31: 0 | S31: 0 | T31: 0 | U31: 0 | V31: 0 | W31: N | X31: N | Y31: Pallet Racking
A32: 81434277 | B32: WH7 | C32: 2025-01-07 | D32: NUTRILOCK | E32: B07V32FG4Q | F32: Dutch Oven 5.2 litre | G32: 42 | H32: sale | I32: 21BP177 | J32: 2024-02-29 | K32: SH1385B | L32: 150 | M32: 285 | N32: 150 | O32: Sku | P32: 1 | Q32: 1 | R32: 0 | S32: 0 | T32: 0 | U32: 0 | V32: 0 | W32: N | X32: N | Y32: Pallet Racking
A33: 81434276 | B33: WH7 | C33: 2025-01-07 | D33: NUTRILOCK | E33: B07V32FG4Q | F33: Dutch Oven 5.2 litre | G33: 44 | H33: sale | I33: 21BP177 | J33: 2024-02-24 | K33: SH1384D | L33: 150 | M33: 285 | N33: 150 | O33: Sku | P33: 1 | Q33: 1 | R33: 0 | S33: 0 | T33: 0 | U33: 0 | V33: 0 | W33: N | X33: N | Y33: Pallet Racking
A34: 81434310 | B34: WH7 | C34: 2025-01-07 | D34: NUTRILOCK | E34: B07V32FG4Q | F34: Dutch Oven 5.2 litre | G34: 66 | H34: sale | I34: 21BP177 | J34: 2024-02-24 | K34: H0465E | L34: 150 | M34: 285 | N34: 150 | O34: Sku | P34: 1 | Q34: 1 | R34: 0 | S34: 0 | T34: 0 | U34: 0 | V34: 0 | W34: N | X34: N | Y34: Pallet Racking
A35: 81434314 | B35: WH7 | C35: 2025-01-07 | D35: NUTRILOCK | E35: B07V32FG4Q | F35: Dutch Oven 5.2 litre | G35: 66 | H35: sale | I35: 21BP177 | J35: 2024-02-24 | K35: H0663F | L35: 150 | M35: 285 | N35: 150 | O35: Sku | P35: 1 | Q35: 1 | R35: 0 | S35: 0 | T35: 0 | U35: 0 | V35: 0 | W35: N | X35: N | Y35: Pallet Racking
A36: 81434301 | B36: WH7 | C36: 2025-01-07 | D36: NUTRILOCK | E36: B07V32FG4Q | F36: Dutch Oven 5.2 litre | G36: 66 | H36: sale | I36: 21BP177 | J36: 2024-02-24 | K36: H0771C | L36: 150 | M36: 285 | N36: 150 | O36: Sku | P36: 1 | Q36: 1 | R36: 0 | S36: 0 | T36: 0 | U36: 0 | V36: 0 | W36: N | X36: N | Y36: Pallet Racking
A37: 81434294 | B37: WH7 | C37: 2025-01-07 | D37: NUTRILOCK | E37: B07V32FG4Q | F37: Dutch Oven 5.2 litre | G37: 66 | H37: sale | I37: 21BP177 | J37: 2024-02-24 | K37: H1072D | L37: 150 | M37: 285 | N37: 150 | O37: Sku | P37: 1 | Q37: 1 | R37: 0 | S37: 0 | T37: 0 | U37: 0 | V37: 0 | W37: N | X37: N | Y37: Pallet Racking
A38: 81434285 | B38: WH7 | C38: 2025-01-07 | D38: NUTRILOCK | E38: B07V32FG4Q | F38: Dutch Oven 5.2 litre | G38: 66 | H38: sale | I38: 21BP177 | J38: 2024-02-24 | K38: H1079D | L38: 150 | M38: 285 | N38: 150 | O38: Sku | P38: 1 | Q38: 1 | R38: 0 | S38: 0 | T38: 0 | U38: 0 | V38: 0 | W38: N | X38: N | Y38: Pallet Racking
A39: 81434289 | B39: WH7 | C39: 2025-01-07 | D39: NUTRILOCK | E39: B07V32FG4Q | F39: Dutch Oven 5.2 litre | G39: 66 | H39: sale | I39: 21BP177 | J39: 2024-02-24 | K39: H1277B | L39: 150 | M39: 285 | N39: 150 | O39: Sku | P39: 1 | Q39: 1 | R39: 0 | S39: 0 | T39: 0 | U39: 0 | V39: 0 | W39: N | X39: N | Y39: Pallet Racking
A40: 81434280 | B40: WH7 | C40: 2025-01-07 | D40: NUTRILOCK | E40: B07V32FG4Q | F40: Dutch Oven 5.2 litre | G40: 66 | H40: sale | I40: 21BP177 | J40: 2024-02-24 | K40: H1369A | L40: 150 | M40: 285 | N40: 150 | O40: Sku | P40: 1 | Q40: 1 | R40: 0 | S40: 0 | T40: 0 | U40: 0 | V40: 0 | W40: N | X40: N | Y40: Pallet Racking
A41: 81434282 | B41: WH7 | C41: 2025-01-07 | D41: NUTRILOCK | E41: B07V32FG4Q | F41: Dutch Oven 5.2 litre | G41: 66 | H41: sale | I41: 21BP177 | J41: 2024-02-24 | K41: H1382B | L41: 150 | M41: 285 | N41: 150 | O41: Sku | P41: 1 | Q41: 1 | R41: 0 | S41: 0 | T41: 0 | U41: 0 | V41: 0 | W41: N | X41: N | Y41: Pallet Racking
... A76: 81434278 | B76: WH7 | C76: 2025-01-07 | D76: NUTRILOCK | E76: B07V32FG4Q | F76: Dutch Oven 5.2 litre | G76: 72 | H76: sale | I76: 21BP177 | J76: 2024-02-28 | K76: SH301C | L76: 150 | M76: 285 | N76: 150 | O76: Sku | P76: 1 | Q76: 1 | R76: 0 | S76: 0 | T76: 0 | U76: 0 | V76: 0 | W76: N | X76: N | Y76: Pallet Racking
G77: =SUM(G2:G76) -> 5116
A78: Applied filters: Customer is not NULL Facility is not Customer is NUTRILOCK SnapShotDateAsText is greater than or equal to 2025-01-07 and is less than or equal to 2025-01-07

Sheet Thrasio
A1: Id | B1: Facility | C1: Snap Shot Date | D1: Customer | E1: Sku | F1: Sku Description | G1: Qty | H1: FitStatus | I1: Batch | J1: Expiry date | K1: Location | L1: Length | M1: Width | N1: Height | O1: Pallet Space Calculation | P1: Pallet Counted Bill | Q1: Standard Pallet - (upto 1.4m) | R1: Standard Pallet - (upto 1.8m) | S1: Standard Pallet - (upto 2.2m) | T1: Pick Pallet Bill | U1: Pick Flow Rack Bill | V1: Pick Shelf Bill | W1: DG Flag | X1: Refrigerated | Y1: Bill Type
A2: 81463855 | B2: WH2 | C2: 2025-01-07 | D2: THRASIO | E2: B07QQFWF6B | F2: aluminium Twin Tray Set | G2: 144 | H2: sale | K2: H1240E | L2: 345 | M2: 465 | N2: 345 | O2: Sku | P2: 1 | Q2: 1 | R2: 0 | S2: 0 | T2: 0 | U2: 0 | V2: 0 | W2: N | X2: N | Y2: Pallet Racking
A3: 81463856 | B3: WH2 | C3: 2025-01-07 | D3: THRASIO | E3: B07QQFWF6B | F3: aluminium Twin Tray Set | G3: 144 | H3: sale | K3: H1262D | L3: 345 | M3: 465 | N3: 345 | O3: Sku | P3: 1 | Q3: 1 | R3: 0 | S3: 0 | T3: 0 | U3: 0 | V3: 0 | W3: N | X3: N | Y3: Pallet Racking
A4: 81463857 | B4: WH2 | C4: 2025-01-07 | D4: THRASIO | E4: B07QQFWF6B | F4: aluminium Twin Tray Set | G4: 144 | H4: sale | K4: H1264D | L4: 345 | M4: 465 | N4: 345 | O4: Sku | P4: 1 | Q4: 1 | R4: 0 | S4: 0 | T4: 0 | U4: 0 | V4: 0 | W4: N | X4: N | Y4: Pallet Racking
A5: 81463854 | B5: WH2 | C5: 2025-01-07 | D5: THRASIO | E5: B07QQFWF6B | F5: aluminium Twin Tray Set | G5: 6 | H5: sale | K5: H1266C | L5: 345 | M5: 465 | N5: 345 | O5: Sku | P5: 1 | Q5: 1 | R5: 0 | S5: 0 | T5: 0 | U5: 0 | V5: 0 | W5: N | X5: N | Y5: Pallet Racking
A6: 81463898 | B6: WH2 | C6: 2025-01-07 | D6: THRASIO | E6: B095W2MLPF | F6: Canvas Baby Swing CREAM | G6: 18 | H6: sale | K6: H1383B | L6: 405 | M6: 455 | N6: 405 | O6: Sku | P6: 1 | Q6: 1 | R6: 0 | S6: 0 | T6: 0 | U6: 0 | V6: 0 | W6: N | X6: N | Y6: Pallet Racking
A7: 81463899 | B7: WH2 | C7: 2025-01-07 | D7: THRASIO | E7: B095W2MLPF | F7: Canvas Baby Swing CREAM | G7: 96 | H7: sale | K7: K1349D | L7: 405 | M7: 455 | N7: 405 | O7: Sku | P7: 1 | Q7: 1 | R7: 0 | S7: 0 | T7: 0 | U7: 0 | V7: 0 | W7: N | X7: N | Y7: Pallet Racking
A8: 81463927 | B8: WH2 | C8: 2025-01-07 | D8: THRASIO | E8: HOLD PALLETS | F8: HOLD PALLETS | G8: 1 | H8: sale | K8: H0449G | L8: 10 | M8: 10 | N8: 10 | O8: Sku | P8: 1 | Q8: 1 | R8: 0 | S8: 0 | T8: 0 | U8: 0 | V8: 0 | W8: N | X8: N | Y8: Pallet Racking
A9: 81463928 | B9: WH2 | C9: 2025-01-07 | D9: THRASIO | E9: HOLD PALLETS | F9: HOLD PALLETS | G9: 1 | H9: sale | K9: H0454G | L9: 10 | M9: 10 | N9: 10 | O9: Sku | P9: 1 | Q9: 1 | R9: 0 | S9: 0 | T9: 0 | U9: 0 | V9: 0 | W9: N | X9: N | Y9: Pallet Racking
A10: 81463929 | B10: WH2 | C10: 2025-01-07 | D10: THRASIO | E10: HOLD PALLETS | F10: HOLD PALLETS | G10: 1 | H10: sale | K10: H1384B | L10: 10 | M10: 10 | N10: 10 | O10: Sku | P10: 1 | Q10: 1 | R10: 0 | S10: 0 | T10: 0 | U10: 0 | V10: 0 | W10: N | X10: N | Y10: Pallet Racking
A11: 81463930 | B11: WH2 | C11: 2025-01-07 | D11: THRASIO | E11: HOLD PALLETS | F11: HOLD PALLETS | G11: 1 | H11: sale | K11: H1446A | L11: 10 | M11: 10 | N11: 10 | O11: Sku | P11: 1 | Q11: 1 | R11: 0 | S11: 0 | T11: 0 | U11: 0 | V11: 0 | W11: N | X11: N | Y11: Pallet Racking
A12: 81463921 | B12: WH2 | C12: 2025-01-07 | D12: THRASIO | E12: HOLD PALLETS | F12: HOLD PALLETS | G12: 1 | H12: sale | K12: H1447A | L12: 10 | M12: 10 | N12: 10 | O12: Sku | P12: 1 | Q12: 1 | R12: 0 | S12: 0 | T12: 0 | U12: 0 | V12: 0 | W12: N | X12: N | Y12: Pallet Racking
A13: 81463922 | B13: WH2 | C13: 2025-01-07 | D13: THRASIO | E13: HOLD PALLETS | F13: HOLD PALLETS | G13: 1 | H13: sale | K13: H1448A | L13: 10 | M13: 10 | N13: 10 | O13: Sku | P13: 1 | Q13: 1 | R13: 0 | S13: 0 | T13: 0 | U13: 0 | V13: 0 | W13: N | X13: N | Y13: Pallet Racking
... A82: 81463888 | B82: WH2 | C82: 2025-01-07 | D82: THRASIO | E82: X000WKNCNP | F82: icecream scoop | G82: 528 | H82: sale | K82: H1431A | L82: 430 | M82: 430 | N82: 430 | O82: Sku | P82: 1 | Q82: 1 | R82: 0 | S82: 0 | T82: 0 | U82: 0 | V82: 0 | W82: N | X82: N | Y82: Pallet Racking
G83: =SUM(G2:G82) -> 14543
A84: Applied filters: Customer is not NULL Facility is not Customer is THRASIO SnapShotDateAsText is greater than or equal to 2025-01-07 and is less than or equal to 2025-01-07

Sheet Nutrilock数量
A1: Sku | B1: Qty | C1: Pallet Counted Bill
A2: B01M74A279 | B2: 100 | C2: 1 | G2: Qty | H2: Pallet
A3: B01M74A279 | B3: 128 | C3: 1 | F3: B01M74A279 | G3: 1711 | H3: 17
A4: B01M74A279 | B4: 128 | C4: 1 | F4: B07881WCQY | G4: 102 | H4: 3
A5: B01M74A279 | B5: 128 | C5: 1 | F5: B07FXG4JVG | G5: 207 | H5: 6
A6: B01M74A279 | B6: 76 | C6: 1 | F6: B07V32FG4Q | G6: 3096 | H6: 47
A7: B01M74A279 | B7: 95 | C7: 1 | G7: =SUM(G3:G6) -> 5116 | H7: =SUM(H3:H6) -> 73
A8: B01M74A279 | B8: 96 | C8: 1
A9: B01M74A279 | B9: 96 | C9: 1
A10: B01M74A279 | B10: 96 | C10: 1
A11: B01M74A279 | B11: 96 | C11: 1
A12: B01M74A279 | B12: 96 | C12: 1
A13: B01M74A279 | B13: 96 | C13: 1
A14: B01M74A279 | B14: 96 | C14: 1
A15: B01M74A279 | B15: 96 | C15: 1
A16: B01M74A279 | B16: 96 | C16: 1
A17: B01M74A279 | B17: 96 | C17: 1
A18: B01M74A279 | B18: 96 | C18: 1
A19: B07881WCQY | B19: 42 | C19: 1
... A76: B07V32FG4Q | B76: 72 | C76: 1

Sheet Thrasio数量
A1: Sku | B1: Qty | C1: Pallet Counted Bill | E1: Thrasio库存 | J1: total | M1: ASIN | N1: Quantity | O1: First load已提货 | P1: 库存 | Q1: Total | R1: Difference quantity差异
A2: B07QQFWF6B | B2: 144 | C2: 1 | F2: ASIN | G2: Qty | H2: Pallet Counted Bill | M2: B07V32FG4Q | N2: 4852 | O2: 1612 | P2: 3096 | Q2: =O2+P2 -> 4708 | R2: =Q2-N2 -> -144
A3: B07QQFWF6B | B3: 144 | C3: 1 | E3: B07QQFWF6B | F3: B07QQFWF6B | G3: 438 | H3: 4 | J3: =G3 -> 438 | M3: B01M74A279 | N3: 3983 | O3: 2272 | P3: 1711 | Q3: =O3+P3 -> 3983 | R3: =Q3-N3 -> 0
A4: B07QQFWF6B | B4: 144 | C4: 1 | E4: B095W2MLPF | F4: B095W2MLPF | G4: 114 | H4: 2 | J4: =G4 -> 114 | M4: B07DPF53MT | N4: 1362 | O4: 0 | P4: =384+978 -> 1362 | Q4: =O4+P4 -> 1362 | R4: =Q4-N4 -> 0
A5: B07QQFWF6B | B5: 6 | C5: 1 | E5: HOLD PALLETS | F5: HOLD PALLETS | G5: 28 | H5: 28 | J5: =G5 -> 28 | M5: B01IP5VT2O | N5: 3060 | O5: 612 | P5: 2448 | Q5: =O5+P5 -> 3060 | R5: =Q5-N5 -> 0
A6: B095W2MLPF | B6: 18 | C6: 1 | E6: X000N8E30H | F6: B01FGTFBHG | G6: 468 | H6: 2 | J6: =G6 -> 468 | M6: B07QQFWF6B | N6: 438 | P6: 438 | Q6: =O6+P6 -> 438 | R6: =Q6-N6 -> 0
A7: B095W2MLPF | B7: 96 | C7: 1 | E7: X000N8FRST | F7: B01JRNNUU2 | G7: 216 | H7: 1 | J7: =G7 -> 216 | M7: B07GSJKTVM | N7: 600 | P7: 600 | Q7: =O7+P7 -> 600 | R7: =Q7-N7 -> 0
A8: HOLD PALLETS | B8: 1 | C8: 1 | E8: X000N8FSDD | F8: B01A7PYVS4 | G8: 252 | H8: 1 | J8: =G8 -> 252 | M8: B07881WCQY | N8: 411 | O8: 165 | P8: 246 | Q8: =O8+P8 -> 411 | R8: =Q8-N8 -> 0
A9: HOLD PALLETS | B9: 1 | C9: 1 | E9: X000N8FSMJ | F9: B0722QMHF2 | G9: 24 | H9: 1 | J9: =G9 -> 24 | M9: B08R6SKCVN | N9: 1584 | O9: 1056 | P9: 528 | Q9: =O9+P9 -> 1584 | R9: =Q9-N9 -> 0
A10: HOLD PALLETS | B10: 1 | C10: 1 | E10: X000N8FVHB | F10: B06WWQGWPW | G10: 72 | H10: 1 | J10: =G10 -> 72 | M10: B095W2MLPF | N10: 306 | O10: 192 | P10: 114 | Q10: =O10+P10 -> 306 | R10: =Q10-N10 -> 0
A11: HOLD PALLETS | B11: 1 | C11: 1 | E11: X000N8GL4D | F11: B00WS5JK10 | G11: 1363 | H11: 2 | J11: =G11 -> 1363 | M11: B07RVDKZC2 | N11: 760 | O11: 80 | P11: 680 | Q11: =O11+P11 -> 760 | R11: =Q11-N11 -> 0
A12: HOLD PALLETS | B12: 1 | C12: 1 | E12: X000N8GLMP | F12: B07353TRJP | G12: 24 | H12: 1 | J12: =G12 -> 24 | M12: B081HZBM5Z | N12: 757 | O12: 325 | P12: 432 | Q12: =O12+P12 -> 757 | R12: =Q12-N12 -> 0
A13: HOLD PALLETS | B13: 1 | C13: 1 | E13: X000N8HHA5 | F13: B01FGT2VJW | G13: 768 | H13: 1 | J13: =G13 -> 768 | M13: B01A7Q7XSI | N13: 1264 | P13: 1264 | Q13: =O13+P13 -> 1264 | R13: =Q13-N13 -> 0
A14: HOLD PALLETS | B14: 1 | C14: 1 | E14: X000N8HHE1 | F14: B01A7Q7XSI | G14: 1264 | H14: 4 | J14: =G14 -> 1264 | M14: B01FGT2VJW | N14: 768 | P14: 768 | Q14: =O14+P14 -> 768 | R14: =Q14-N14 -> 0
A15: HOLD PALLETS | B15: 1 | C15: 1 | E15: X000N8HHHD | F15: B07358FG4G | G15: 7 | H15: 1 | J15: =G15 -> 7 | M15: B00WS5JK10 | N15: 1363 | P15: 1363 | Q15: =O15+P15 -> 1363 | R15: =Q15-N15 -> 0
A16: HOLD PALLETS | B16: 1 | C16: 1 | E16: X000N8IP1P | F16: B06Y5F3NGY | G16: 162 | H16: 2 | J16: =G16 -> 162 | M16: B08HJQCKJB | N16: 1320 | P16: 1320 | Q16: =O16+P16 -> 1320 | R16: =Q16-N16 -> 0
A17: HOLD PALLETS | B17: 1 | C17: 1 | E17: X000N8IVQJ | F17: B01IP5VT2O | G17: 2448 | H17: 2 | J17: =G17 -> 2448 | M17: B07FXG4JVG | N17: 243 | O17: 36 | P17: 207 | Q17: =O17+P17 -> 243 | R17: =Q17-N17 -> 0
A18: HOLD PALLETS | B18: 1 | C18: 1 | E18: X000NLOVEH | F18: B07881WCQY | G18: 144 | H18: 5 | I18: 102 | J18: =G18+I18 -> 246 | M18: B01FGTFBHG | N18: 468 | P18: 468 | Q18: =O18+P18 -> 468 | R18: =Q18-N18 -> 0
A19: HOLD PALLETS | B19: 1 | C19: 1 | E19: X000OUBZRD | F19: B075SQSHSH | G19: 1632 | H19: 3 | J19: =G19 -> 1632 | M19: B075SQSHSH | N19: 1632 | P19: 1632 | Q19: =O19+P19 -> 1632 | R19: =Q19-N19 -> 0
A20: HOLD PALLETS | B20: 1 | C20: 1 | E20: X000OXVBEH | F20: B075K9FPQT | G20: 64 | H20: 1 | J20: =G20 -> 64 | M20: B08HJS7RR8 | N20: 513 | P20: 513 | Q20: =O20+P20 -> 513 | R20: =Q20-N20 -> 0
A21: HOLD PALLETS | B21: 1 | C21: 1 | E21: X000RV2Y1P | F21: B07T2XNN7C | G21: 130 | H21: 1 | J21: =G21 -> 130 | M21: B01JRNNUU2 | N21: 216 | P21: 216 | Q21: =O21+P21 -> 216 | R21: =Q21-N21 -> 0
A22: HOLD PALLETS | B22: 1 | C22: 1 | E22: X000T6DFC5 | F22: B07GSJKTVM | G22: 600 | H22: 3 | J22: =G22 -> 600 | M22: B06Y5F3NGY | N22: 162 | P22: 162 | Q22: =O22+P22 -> 162 | R22: =Q22-N22 -> 0
A23: HOLD PALLETS | B23: 1 | C23: 1 | E23: X000TDXL0T | F23: B07DPF53MT | G23: =384+978 -> 1362 | H23: 4 | J23: =G23 -> 1362 | M23: B08NP6N2S4 | N23: 432 | P23: 432 | Q23: =O23+P23 -> 432 | R23: =Q23-N23 -> 0
A24: HOLD PALLETS | B24: 1 | C24: 1 | E24: X000U6KVA3 | F24: B07RVDKZC2 | G24: 680 | H24: 4 | J24: =G24 -> 680 | M24: B01A7PYVS4 | N24: 252 | P24: 252 | Q24: =O24+P24 -> 252 | R24: =Q24-N24 -> 0
A25: HOLD PALLETS | B25: 1 | C25: 1 | E25: X000V2PDO5 | F25: B081HZBM5Z | G25: 432 | H25: 1 | J25: =G25 -> 432 | M25: B07T2XNN7C | N25: 140 | O25: 10 | P25: 130 | Q25: =O25+P25 -> 140 | R25: =Q25-N25 -> 0
A26: HOLD PALLETS | B26: 1 | C26: 1 | E26: X000V2QAUB | F26: B07YWDJGH4 | G26: 24 | H26: 1 | J26: =G26 -> 24 | M26: B01A7QZ9ZM | N26: 72 | O26: 72 | P26: 0 | Q26: =O26+P26 -> 72 | R26: =Q26-N26 -> 0
A27: HOLD PALLETS | B27: 1 | C27: 1 | E27: X000VHA8BD | F27: B07Z4NF7ZZ | G27: 12 | H27: 1 | J27: =G27 -> 12 | M27: B075K9FPQT | N27: 64 | P27: 64 | Q27: =O27+P27 -> 64 | R27: =Q27-N27 -> 0
A28: HOLD PALLETS | B28: 1 | C28: 1 | E28: X000VOAO0V | F28: B08HJQCKJB | G28: 1320 | H28: 3 | J28: =G28 -> 1320 | M28: B06WWQGWPW | N28: 72 | P28: 72 | Q28: =O28+P28 -> 72 | R28: =Q28-N28 -> 0
A29: HOLD PALLETS | B29: 1 | C29: 1 | E29: X000VOBH7Z | F29: B08HJS7RR8 | G29: 513 | H29: 2 | J29: =G29 -> 513 | M29: B07Z4NF7ZZ | N29: 12 | P29: 12 | Q29: =O29+P29 -> 12 | R29: =Q29-N29 -> 0
A30: HOLD PALLETS | B30: 1 | C30: 1 | E30: X000WA4BRL | F30: B08NP6N2S4 | G30: 432 | H30: 1 | J30: =G30 -> 432 | M30: B07YWDJGH4 | N30: 24 | P30: 24 | Q30: =O30+P30 -> 24 | R30: =Q30-N30 -> 0
A31: HOLD PALLETS | B31: 1 | C31: 1 | E31: X000WKNCNP | F31: B08R6SKCVN | G31: 528 | H31: 1 | J31: =G31 -> 528 | M31: B07353TRJP | N31: 24 | P31: 24 | Q31: =O31+P31 -> 24 | R31: =Q31-N31 -> 0
A32: HOLD PALLETS | B32: 1 | C32: 1 | G32: =SUM(G3:G31) -> 15521 | M32: B0722QMHF2 | N32: 24 | P32: 24 | Q32: =O32+P32 -> 24 | R32: =Q32-N32 -> 0
A33: HOLD PALLETS | B33: 1 | C33: 1 | E33: Nutrilock库存 | M33: B082M3SLJ7 | N33: 2 | O33: 2 | P33: 0 | Q33: =O33+P33 -> 2 | R33: =Q33-N33 -> 0
A34: HOLD PALLETS | B34: 1 | C34: 1 | E34: B01M74A279 | F34: B01M74A279 | G34: 1711 | H34: 17 | J34: 1711 | M34: B07358FG4G | N34: 7 | P34: 7 | Q34: =O34+P34 -> 7 | R34: =Q34-N34 -> 0
A35: HOLD PALLETS | B35: 1 | C35: 1 | E35: B07881WCQY | F35: B07881WCQY | G35: 0 | H35: 0 | J35: 0 | M35: B08PVF9NWP | N35: 3 | O35: 3 | P35: 0 | Q35: =O35+P35 -> 3 | R35: =Q35-N35 -> 0
A36: X000N8E30H | B36: 228 | C36: 1 | E36: B07FXG4JVG | F36: B07FXG4JVG | G36: 207 | H36: 6 | J36: 207 | N36: =SUM(N2:N35) -> 27190 | O36: =SUM(O2:O35) -> 6437 | P36: =SUM(P2:P35) -> 20609 | Q36: =SUM(Q2:Q35) -> 27046 | R36: =SUM(R2:R35) -> -144
A37: X000N8E30H | B37: 240 | C37: 1 | E37: B07V32FG4Q | F37: B07V32FG4Q | G37: 3096 | H37: 47 | J37: 3096 | M37: HOLD PALLETS | P37: 28
A38: X000N8FRST | B38: 216 | C38: 1
A39: X000N8FSDD | B39: 252 | C39: 1
A40: X000N8FSMJ | B40: 24 | C40: 1
...

Sheet Nutrilock Tfr
A1: Item Key | B1: Item Name | C1: Quantity
A2: B07V32FG4Q | B2: Dutch Oven 5.2 litre | C2: -72
A3: B07V32FG4Q | B3: Dutch Oven 5.2 litre | C3: -72
A4: B07V32FG4Q | B4: Dutch Oven 5.2 litre | C4: -72
A5: B01M74A279 | B5: Pre-Seasoned 12 Inch (30cm) Cast Iron Skillet Fry Pan. | C5: -128
A6: B01M74A279 | B6: Pre-Seasoned 12 Inch (30cm) Cast Iron Skillet Fry Pan. | C6: -128
A7: B07V32FG4Q | B7: Dutch Oven 5.2 litre | C7: -66
A8: B07V32FG4Q | B8: Dutch Oven 5.2 litre | C8: -66 | K8: Item Name | L8: Quantity
A9: B07V32FG4Q | B9: Dutch Oven 5.2 litre | C9: -72 | J9: B07V32FG4Q | L9: -1612
A10: B01M74A279 | B10: Pre-Seasoned 12 Inch (30cm) Cast Iron Skillet Fry Pan. | C10: -128 | J10: B01M74A279 | L10: -2272
A11: B07V32FG4Q | B11: Dutch Oven 5.2 litre | C11: -72 | J11: B07FXG4JVG | L11: -36
A12: B07V32FG4Q | B12: Dutch Oven 5.2 litre | C12: -72 | J12: B07881WCQY | L12: -162
A13: B07V32FG4Q | B13: Dutch Oven 5.2 litre | C13: -72
A14: B01M74A279 | B14: Pre-Seasoned 12 Inch (30cm) Cast Iron Skillet Fry Pan. | C14: -128
A15: B01M74A279 | B15: Pre-Seasoned 12 Inch (30cm) Cast Iron Skillet Fry Pan. | C15: -128
A16: B01M74A279 | B16: Pre-Seasoned 12 Inch (30cm) Cast Iron Skillet Fry Pan. | C16: -128
A17: B07V32FG4Q | B17: Dutch Oven 5.2 litre | C17: -72
A18: B01M74A279 | B18: Pre-Seasoned 12 Inch (30cm) Cast Iron Skillet Fry Pan. | C18: -128
A19: B07FXG4JVG | B19: HOBART DECANTER | C19: -36
A20: B07V32FG4Q | B20: Dutch Oven 5.2 litre | C20: -72
A21: B01M74A279 | B21: Pre-Seasoned 12 Inch (30cm) Cast Iron Skillet Fry Pan. | C21: -128
A22: B01M74A279 | B22: Pre-Seasoned 12 Inch (30cm) Cast Iron Skillet Fry Pan. | C22: -128
A23: B01M74A279 | B23: Pre-Seasoned 12 Inch (30cm) Cast Iron Skillet Fry Pan. | C23: -96
A24: B07V32FG4Q | B24: Dutch Oven 5.2 litre | C24: -72
... A49: B07V32FG4Q | B49: Dutch Oven 5.2 litre | C49: -66
C50: =SUM(C2:C49) -> -4082

Sheet Thrasio Tfr
A1: ASIN | B1: Item Key | C1: Item Name | D1: Quantity
B2: X000NLOVEH | C2: Van Daemon Twist Decanter 5 Set | D2: -3 | F2: ASIN | H2: Item Name | I2: Quantity
B3: X000RV2Y1P | C3: Launceston Whiskey Glass Set | D3: -10 | F3: B07881WCQY | G3: X000NLOVEH | I3: -3
B4: X000V2PDO5 | C4: Mat with dough scraper set | D4: -325 | F4: B07T2XNN7C | G4: X000RV2Y1P | I4: -10
B5: X000TEKLUB | C5: basketball bag | D5: -2 | F5: B081HZBM5Z | G5: X000V2PDO5 | I5: -325
B6: X000N8HM4L | C6: Silicone utensil set | D6: -72 | F6: B082M3SLJ7 | G6: X000TEKLUB | I6: -2
B7: X000TDXL0T | C7: Pizza steel | D7: -144 | F7: B01A7QZ9ZM | G7: X000N8HM4L | I7: -72
B8: X000TDXL0T | C8: Pizza steel | D8: -144 | F8: B07DPF53MT | G8: X000TDXL0T | I8: -978
B9: X000TDXL0T | C9: Pizza steel | D9: -114 | F9: B07RVDKZC2 | G9: X000U6KVA3 | I9: -80
B10: X000TDXL0T | C10: Pizza steel | D10: -144 | F10: B08PVF9NWP | G10: X000WGHKHX | I10: -3
B11: X000TDXL0T | C11: Pizza steel | D11: -144 | F11: B01IP5VT2O | G11: X000N8IVQJ | I11: -612
B12: X000TDXL0T | C12: Pizza steel | D12: -144 | F12: B08R6SKCVN | G12: X000WKNCNP | I12: -1056
B13: X000TDXL0T | C13: Pizza steel | D13: -144 | F13: B095W2MLPF | G13: B095W2MLPF | I13: -192
B14: X000U6KVA3 | C14: cake stand | D14: -80
B15: X000WGHKHX | C15: 24 cupcakes | D15: -3
B16: X000N8IVQJ | C16: Premium pizza cutter | D16: -612
B17: X000WKNCNP | C17: icecream scoop | D17: -1056
B18: B095W2MLPF | C18: Canvas Baby Swing CREAM | D18: -96
B19: B095W2MLPF | C19: Canvas Baby Swing CREAM | D19: -96
